Workbook

Sheet v0
B1: 块个数 | C1: 单块运行cycle | D1: 流水延迟 | E1: CB CR 块 | F1: 420 | G1: 422 | H1: 模式
A2: 8x8 | B2: 64 | C2: 8 | D2: 6 | E2: 64*2 | F2: 4x4 | G2: 4x8 | H2: FME+ MMVPx1
A3: 16x16 | B3: 16 | C3: 24 | D3: 6 | E3: 16*2 | F3: 8x8 | G3: 8x16 | H3: FME+ MMVPx2
A4: 32x32 | B4: 4 | C4: 78 | D4: 6 | E4: 8*2 | F4: 16x16 | G4: 16x32 | H4: FME+ MMVPx2
A5: 64x64 | B5: 1 | C5: 284 | D5: 6 | E5: 2 | F5: 32x32 | G5: 32x64 | H5: FME+ MMVPx1
A7: 性能需求420：64x64 | B7: 3200
A8: 插值性能估计
A9: Y | B9: 块个数 | C9: 单块运行cycle | D9: 模式个数 | E9: 总计 | G9: Y | H9: y size | I9: 块个数 | J9: 单块运行cycle | K9: 模式个数 | L9: 小计 | M9: 总计 | O9: Y | P9: y size | Q9: 块个数 | R9: 单块运行cycle | S9: 模式个数 | T9: 小计 | U9: 总计
A10: 8x8 | B10: 64 | C10: 8 | D10: 2 | E10: =B10*C10*D10 -> 1024 | G10: 16pixel | H10: 8x8 1F1M | I10: 64 | J10: 8 | K10: 2 | L10: 1024 | M10: 2440 | O10: 16pixel | P10: 8x8 1F3M | Q10: 64 | R10: 8 | S10: 4 | T10: =Q10*R10*S10 -> 2048 | U10: 2784
A11: 16x16 | B11: 16 | C11: 23 | D11: 3 | E11: =B11*C11*D11 -> 1104 | H11: 16x16 1F2M | I11: 16 | J11: 23 | K11: 3 | L11: 1104 | P11: 16x16 2M | Q11: 16 | R11: 23 | S11: 2 | T11: =Q11*R11*S11 -> 736
A12: 32x32 | B12: 4 | C12: 78 | D12: 3 | E12: =B12*C12*D12 -> 936 | H12: 32x32 1F | I12: 4 | J12: 78 | K12: 1 | L12: 312 | O12: 16pixel | P12: 16x16 1F1M | Q12: 16 | R12: 23 | S12: 2 | T12: =Q12*R12*S12 -> 736 | U12: 2608
A13: 64x64(切成4个32x32) | B13: 4 | C13: 78 | D13: 2 | E13: =B13*C13*D13 -> 624 | G13: 8pixel | H13: 32x32 2M | I13: 4 | J13: 156 | K13: 2 | L13: 1248 | M13: 2496 | P13: 32x32 1F3M | Q13: 4 | R13: 78 | S13: 4 | T13: =Q13*R13*S13 -> 1248
E14: 3688 | H14: 64x64 1F1M(切成4个32x32) | I14: 4 | J14: 156 | K14: 2 | L14: 1248 | P14: 64x64 1F1M(切成4个32x32) | Q14: 4 | R14: 78 | S14: 2 | T14: =Q14*R14*S14 -> 624
A16: U(420) | B16: 块个数 | C16: 单块运行cycle(8 pixel) | D16: 模式个数 | G16: UV | H16: uv size | I16: 块个数 | J16: 单块运行cycle | K16: 模式个数 | L16: 小计 | M16: 总计 （U+V） | O16: Y | P16: y size | Q16: 块个数 | R16: 单块运行cycle | S16: 模式个数 | T16: 小计 | U16: 总计
A17: 4x4 (Y8x8) | B17: 64 | C17: 4 | D17: 4 | E17: =B17*C17*D17 -> 1024 | G17: 8pixel | H17: 4x4 | I17: 64 | J17: 4 | K17: 2 | L17: 512 | M17: 2384 | O17: 16pixel | P17: 8x8 1F1M | Q17: 64 | R17: 8 | S17: 2 | T17: =Q17*R17*S17 -> 1024 | U17: 2496
A18: 8x8 (Y16x16) | B18: 16 | C18: 11 | D18: 4 | E18: =B18*C18*D18 -> 704 | H18: 8x8 | I18: 16 | J18: 11 | K18: 3 | L18: 528 | P18: 16x16 1F3M | Q18: 16 | R18: 23 | S18: 4 | T18: =Q18*R18*S18 -> 1472
A19: 16x16 (Y32x32) | B19: 4 | C19: 38 | D19: 4 | E19: =B19*C19*D19 -> 608 | H19: 16x16 F | I19: 4 | J19: 38 | K19: 1 | L19: 152 | T19: =Q19*R19*S19 -> 0
A20: 32x32 (Y64x64) | B20: 1 | C20: 140 | D20: 2 | E20: =B20*C20*D20 -> 280 | G20: 4pixel | H20: 16x16 M | I20: 4 | J20: 76 | K20: 2 | L20: 608 | M20: 2336 | O20: 16pixel | P20: 32x32 1F3M | Q20: 4 | R20: 78 | S20: 4 | T20: =Q20*R20*S20 -> 1248 | U20: 2496
E21: 1800 | H21: 32x32(4x32x8) | I21: 1 | J21: 280 | K21: 2 | L21: 560 | P21: 64x64 1F3M(切成4个32x32) | Q21: 4 | R21: 78 | S21: 4 | T21: =Q21*R21*S21 -> 1248
A23: 块输出到TQITQ 时间
A24: Y | B24: 块个数 | C24: 单块输出时间 | D24: 模式个数 | E24: 总计 | G24: TQITQ输入通道 | H24: Y 耗时 | I24: UV 耗时 | J24: MRG总耗时 | K24: Intra 耗时 | L24: TQITQ 输入耗时 | O24: UV | P24: uv size | Q24: 块个数 | R24: 单块运行cycle | S24: 模式个数 | T24: 小计 | U24: 总计 （U420）
A25: 8x8 | B25: 64 | C25: 4 | D25: 2 | E25: =B25*C25*D25 -> 512 | G25: 8x8 | H25: 512 | I25: 256 | J25: 768 | K25: 768 | L25: 768 | M25: MRG & intra 独立 | O25: 16pixel | P25: 4x4 1F3M | Q25: 64 | R25: 4 | S25: 4 | T25: =Q25*R25*S25 -> 1024 | U25: =T25+T26 -> 1376
A26: 16x16 | B26: 16 | C26: 16 | D26: 2 | E26: =B26*C26*D26 -> 512 | G26: 16x16 | H26: 512 | I26: 256 | J26: 768 | K26: 768 | L26: 1536 | M26: MRG & intra 共享 | P26: 8x8 2M | Q26: 16 | R26: 11 | S26: 2 | T26: =Q26*R26*S26 -> 352
A27: 32x32 | B27: 4 | C27: 64 | D27: 2 | E27: =B27*C27*D27 -> 512 | G27: 32x32 | H27: 1024 | I27: 256 | J27: 1280 | K27: 512 | L27: 1792 | O27: 16pixel | P27: 8x8 1F1M | Q27: 16 | R27: 11 | S27: 2 | T27: =Q27*R27*S27 -> 352 | U27: =T27+T28+T29 -> 1240
A28: 64x64(切成4个32x32) | B28: 4 | C28: 64 | D28: 2 | E28: =B28*C28*D28 -> 512 | G28: 4x4 | H28: 0 | I28: 512 | J28: 512 | K28: 0 | L28: 512 | M28: 待定 | P28: 16x16 1F3M | Q28: 4 | R28: 38 | S28: 4 | T28: =Q28*R28*S28 -> 608
E29: 2048 | P29: 32x32 1F1M(切成4个32x32) | Q29: 1 | R29: 140 | S29: 2 | T29: =Q29*R29*S29 -> 280
A31: U(420) | B31: 块个数 | C31: 单块输出时间 | D31: 模式个数
A32: 4x4 (Y8x8) | B32: 64 | C32: 2 | D32: 2 | E32: =B32*C32*D32 -> 256
A33: 8x8 (Y16x16) | B33: 16 | C33: 4 | D33: 2 | E33: =B33*C33*D33 -> 128
A34: 16x16 (Y32x32) | B34: 4 | C34: 16 | D34: 2 | E34: =B34*C34*D34 -> 128
A35: 32x32 (Y64x64) | B35: 1 | C35: 64 | D35: 2 | E35: =B35*C35*D35 -> 128
E36: 640
A38: PMF output to TQITQ 占用时间
A39: 通道4 | B39: 块数 | C39: 输出时间 | D39: 模式个数 | E39: 时间
A40: uv4x4 | B40: 128 | C40: 1 | D40: 4 | E40: =B40*C40*D40 -> 512
A41: y8x8(切成4个4x4) | B41: 256 | C41: 1 | D41: 4 | E41: =B41*C41*D41 -> 1024
A42: 总计 | E42: =SUM(E40:E41) -> 1536
A44: 通道8
A45: Y8x8 | B45: 64 | C45: 4 | D45: 4 | E45: =B45*C45*D45 -> 1024
A46: UV8x8 | B46: 32 | C46: 4 | D46: 2 | E46: =B46*C46*D46 -> 256
...

Sheet struct
A2: vctrl2pmf_info | B2: codec | C2: 2 | D2: 0=264; 1=265; 2=266;
B3: csamp | C3: 2 | D3: 0/1/2/3 = 400/420/422/.440
B4: pred_mode | C4: 1 | D4: 0=P; 1=B;
B5: bit_depth | C5: 1 | D5: 0=8bit; 1=10bit;
B6: sdw_req_x | C6: 7 | D6: 搜索窗起始点
B7: sdw_req_y | C7: 7
B8: qp | C8: [4:0][6:0] | D8: 4个32x32 块 和1个 64x64 块（32以下共用）
A9: pmf2mvp_req | B9: blk_size | C9: 2 | D9: 8/16/32/64
B10: blk_idx | C10: 6 | D10: z-scan
B11: depend | C11: 1 | D11: 0：反馈 N-2 的两个cand; 1 ： 反馈N-1 的一个
B12: merge | C12: 1 | D12: 0: amvp ; 1:merge
A14: mvp2pmf_ack | B14: blk_size | C14: 2 | D14: 8/16/32/64
B15: blk_idx | C15: 6 | D15: z-scan
B16: cand_idx | C16: 1 | D16: 0：反馈 N-2 的两个cand; 1 ： 反馈N-1 的一个
B17: merge_idx | C17: [2:0][2:0] | D17: 实时的3个 mmvp 对应的merge idx (cand_idx =0 时，反馈的N-2的用于提前PK; cand_idx =1时反馈的 N-1 的用于最终PK和输出
B18: l1_predflag | C18: 1
B19: l0_predflag | C19: 1
B20: l1_refidx | C20: 3 | D20: 可能可以缩减
B21: l0_refidx | C21: 3 | D21: 可能可以缩减
B22: l1_mvy | C22: 16 | D22: 可能可以缩减
B23: l1_mvx | C23: 16 | D23: 可能可以缩减
B24: l0_mvy | C24: 16 | D24: 可能可以缩减
B25: l0_mvx | C25: 16 | D25: 可能可以缩减
A28: pmf2sel_pk | B28: blk_x | C28: 4 | D28: 4x4
B29: blk_y | C29: 4 | D29: 4x4
B30: size | C30: 2 | D30: 8/16/32/64
B31: comp | C31: 2 | D31: Y/U/V
B32: blk_mode | C32: 3 | D32: 0/1/2/3 = FME/M0/M1/M2
B33: cost | C33: COST_WIDTH
B34: tu_mode | C34: 1 | D34: for H265 8x8 ：0=4x4；1 = 8x8; for H264 16x16: 0=4x4；1 = 8x8;
B35: transform_skip | C35: 1
B36: l1_predflag | C36: 1
B37: l0_predflag | C37: 1
B38: l1_refidx | C38: 3
B39: l0_refidx | C39: 3
B40: l1_mvdy | C40: 16
B41: l1_mvdx | C41: 16
B42: l0_mvdy | C42: 16
B43: l0_mvdx | C43: 16
B44: merge_idx | C44: 3
...

Sheet interface
A1: 接口
A3: 类型 | B3: name | C3: direction | D3: width | E3: note
A4: normal | B4: clk | C4: in | D4: 1
B5: aresetn | C5: in | D5: 1
A7: vctrl | B7: vctrl2pmf_ctu_start | C7: in | D7: 1 | E7: start must wait for end=1;
B8: pmf2vctrl_ctu_end | C8: out | D8: 1
B9: vctrl2pmf_info | C9: in | D9: vctrl2pmf_info_t
A10: mvp | B10: pmf2mvp_mmvp_req | C10: out | D10: 1
B11: pmf2mvp_mmvp_req_info | C11: out | D11: pmf2mvp_req_t
B12: pmf2mvp_mmvp_ack | C12: in | D12: 1
B13: mvp2pmf_mmvp_ack_info | C13: in | D13: 2x mvp2pmf_ack
B14: pmf2mvp_amvp_req | C14: out | D14: 1
B15: pmf2mvp_amvp_req_info | C15: out | D15: pmf2mvp_req_t
B16: mvp2pmf_amvp_ack | C16: in | D16: 1
B17: mvp2pmf_amvp_ack_info | C17: in | D17: 2x mvp2pmf_ack
B18: pmf2mvp_pk_valid | C18: out | D18: 1
B19: pmf2mvp_pk | C19: out | D19: pmf2mvp_pk_t | E19: H264 only, 反馈inter 8x8 pk 结果。
A20: SEL | B20: pmf2sel_pk_valid | C20: out | D20: 1
B21: pmf2sel_pk | C21: out | D21: 1x pmf2sel_pk_t
B22: pmf2sel_pred_valid | C22: out | D22: 5 | E22: 0/1/2/3/4-》 4/8/16/32/64(blk size)
B23: pmf2sel_pred_ready | C23: in | D23: 5
B24: pmf2sel_pred | C24: out | D24: 5x pmf2sel_pred_t
A25: TQITQ | B25: pmf2tqitq_res_valid | C25: out | D25: 5 | E25: 0/1/2/3/4-》 4/4/8/16/32
B26: pmf2tqitq_res_ready | C26: in | D26: 5
B27: pmf2tqitq_res | C27: out | D27: 5x pmf2tqitq_res_t
B28: tqitq2pmf_bd_valid | C28: in | D28: 5 | E28: 0/1/2/3/4-》 4/4/8/16/32
B29: tqitq2pmf_bd | C29: in | D29: 5x tqitq2pmf_bd
A30: FME | B30: fme2pmf_fmv_valid | C30: in | D30: 4 | E30: 0,1,2,3-》 8/16/32/64
B31: pmf2fme_fmv_ready | C31: out | D31: 4
B32: fme2pmf_fmv | C32: in | D32: 4x fme2pmf_fmv
A33: REF_RAM | B33: ref_pixel_y_csn | C33: out | D33: [1:0][1:0][3:0]
B34: ref_pixel_y_wen | C34: out | D34: [1:0][1:0][3:0]
B35: ref_pixel_y_addr | C35: out | D35: [1:0][1:0][3:0][7:0]
B36: ref_pixel_y_wdata | C36: out | D36: [1:0][1:0][3:0][15:0][9:0]
B37: ref_pixel_y_rdata | C37: in | D37: [1:0][1:0][3:0][15:0][9:0]
B38: ref_pixel_uv_csn | C38: out | D38: [1:0][1:0][3:0]
B39: ref_pixel_uv_wen | C39: out | D39: [1:0][1:0][3:0]
B40: ref_pixel_uv_addr | C40: out | D40: [1:0][1:0][3:0][7:0]
B41: ref_pixel_uv_wdata | C41: out | D41: [1:0][1:0][3:0][7:0][9:0]
B42: ref_pixel_uv_rdata | C42: in | D42: [1:0][1:0][3:0][7:0][9:0]
...

Sheet job
A1: codec | B1: color | C1: cu_size | D1: mode | E1: tu_size | F1: SAD | G1: RDO | H1: TS | I1: CU_SKIP | J1: comment
A2: H265 | B2: Y | C2: 8x8 | D2: M0 | E2: 4x4 | F2: 0 | G2: 4 | H2: 4 | I2: 0 | J2: 需要在pmf中先做TS PK, 再做4个bit/dist 的累加
D3: M0 | E3: 8x8 | F3: 0 | G3: 1 | H3: 0 | I3: 1
D4: M1 | E4: 4x4 | F4: 0 | G4: 4 | H4: 4 | I4: 0 | J4: 需要在pmf中先做TS PK, 再做4个bit/dist 的累加
D5: M1 | E5: 8x8 | F5: 0 | G5: 1 | H5: 0 | I5: 1
D6: M2 | E6: 4x4 | F6: 0 | G6: 4 | H6: 4 | I6: 0 | J6: 需要在pmf中先做TS PK, 再做4个bit/dist 的累加
D7: M2 | E7: 8x8 | F7: 0 | G7: 1 | H7: 0 | I7: 1
D8: F | E8: 4x4 | F8: 0 | G8: 4 | H8: 4 | I8: 0 | J8: 需要在pmf中先做TS PK, 再做4个bit/dist 的累加
D9: F | E9: 8x8 | F9: 0 | G9: 1 | H9: 0 | I9: 1
C10: 16x16 | D10: M0 | E10: 16x16 | F10: 1 | G10: 1 | H10: 0 | I10: 0
D11: M1 | E11: 16x16
D12: M2 | E12: 16x16
D13: F | E13: 16x16 | F13: 0 | G13: 1 | H13: 0 | I13: 1
C14: 32X32 | D14: M0 | E14: 32x32 | F14: 1 | G14: 1 | H14: 0 | I14: 0
C15: 32X32 | D15: M1 | E15: 32x32
C16: 32X32 | D16: M2 | E16: 32x32
C17: 32X32 | D17: F | E17: 32x32 | F17: 0 | G17: 1 | H17: 0 | I17: 1
C18: 64x64 | D18: M0 | E18: 32x32 | F18: 0 | G18: 4 | H18: 0 | I18: 0 | J18: 需要在pmf中做4个bit/dist 的累加
D19: F | E19: 32x32 | F19: 0 | G19: 4 | H19: 0 | I19: 1 | J19: 需要在pmf中做4个bit/dist 的累加
B20: UV | C20: 4x4 | D20: M0 | E20: 4x4 | F20: 0 | G20: 1 | H20: 1 | I20: 0
C21: 4x4 | D21: M1 | E21: 4x4 | F21: 0 | G21: 1 | H21: 1 | I21: 0
C22: 4x4 | D22: M2 | E22: 4x4 | F22: 0 | G22: 1 | H22: 1 | I22: 0
C23: 4x4 | D23: F | E23: 4x4 | F23: 0 | G23: 1 | H23: 1 | I23: 0
C24: 8x8 | D24: M0 | E24: 8x8 | F24: 1 | G24: 1 | H24: 0 | I24: 0
C25: 8x8 | D25: M1 | E25: 8x8
C26: 8x8 | D26: M2 | E26: 8x8
C27: 8x8 | D27: F | E27: 8x8 | F27: 0 | G27: 1 | H27: 0 | I27: 1
C28: 16x16 | D28: M0 | E28: 16x16 | F28: 1 | G28: 1 | H28: 0 | I28: 0
C29: 16x16 | D29: M1 | E29: 16x16
C30: 16x16 | D30: M2 | E30: 16x16
C31: 16x16 | D31: F | E31: 16x16 | F31: 0 | G31: 1 | H31: 0 | I31: 1
C32: 32x32 | D32: M0 | E32: 16x16 | F32: 0 | G32: 4 | H32: 0 | I32: 0 | J32: 需要在pmf中做4个bit/dist 的累加
C33: 32x32 | D33: F | E33: 16x16 | F33: 0 | G33: 4 | H33: 0 | I33: 1 | J33: 需要在pmf中做4个bit/dist 的累加
A34: H264 | B34: Y | C34: 8x8 | D34: M0 | E34: 4x4 | F34: 0 | G34: 1 | H34: 0 | I34: 0 | J34: TQITQ 算出cu 的结果
C35: 8x8 | D35: F | E35: 4x4 | F35: 0 | G35: 1 | H35: 0 | I35: 1 | J35: TQITQ 算出cu 的结果
C36: 16x16 | D36: M0 | E36: 4x4 | F36: 0 | G36: 1 | H36: 0 | I36: 0 | J36: TQITQ 算出cu 的结果
C37: 16x17 | D37: M1 | E37: 8x8 | F37: 0 | G37: 1 | H37: 0 | I37: 0 | J37: TQITQ 算出cu 的结果
C38: 16x16 | D38: F | E38: 4x4 | F38: 0 | G38: 1 | H38: 0 | I38: 0 | J38: TQITQ 算出cu 的结果
C39: 16x17 | D39: F | E39: 8x8 | F39: 0 | G39: 1 | H39: 0 | I39: 1 | J39: TQITQ 算出cu 的结果
B40: UV | C40: 4x4 | D40: M0 | E40: 4x4 | F40: 0 | G40: 1 | H40: 0 | I40: 0 | J40: TQITQ 算出cu 的结果
...

Sheet output format
A1: H265 | AC1: H264
A2: Y | H2: 4x4 channel | O2: UV | AC2: Y | AN2: UV
A3: 8x8 | C3: 8x2 -0 | H3: 4x4 -0 | J3: 1 | O3: 4x4 | Q3: 4x4 U | AC3: 8x8 | AE3: 凑4笔输出 4x4 channel
AE4: 4x4 -0 | AG4: 1 | AN4: 4x4 -0
C5: 1
Q6: 4x4 V
C7: 2 | H7: 2 | J7: 3
AE8: 2 | AG8: 3
A12: Y | O12: UV
A13: 16x16 | C13: 16x1 -0 | O13: 8x8 | Q13: U 8x1 -0 | V13: V 8x1 -0 | AC13: 16x16 | AE13: 8x8 channel | AN13: 4x4 channel | AX13: UV
C14: 1 | Q14: 1 | V14: 1 | AE14: 0 | AI14: 2 | AN14: 0 | AP14: 1 | AR14: 8 | AT14: 9 | AX14: 8x8 | AY14: 4x4 -0 | BA14: 1
Q15: 2 | V15: 2
Q16: 3 | V16: 3 | AN16: 2 | AP16: 3 | AR16: 10 | AT16: 11
AE18: 1 | AI18: 3 | AN18: 4 | AP18: 5 | AR18: 12 | AT18: 13 | AY18: 2 | BA18: 3
C20: 15 | Q20: 15 | V20: 15 | AN20: 6 | AP20: 7 | AR20: 14 | AT20: 15
A22: Y | O22: UV
A23: 32x32 | C23: 原始插值顺序 | O23: 16x16 | Q23: 原始插值顺序
C24: 16x1 -0 | G24: 16x1 -32 | Q24: 8x1 -0 | U24: 8x1 -16
C25: 1 | Q25: 1
C26: 2 | Q26: 2
C27: 3 | Q27: 3
C31: 31 | G31: 63 | Q31: 15 | U31: 31
C33: 重组输出顺序 | Q33: 重组输出顺序
C34: 16x1 -0 | G34: 16x1 -1 | Q34: 16x1 -0
C35: 2 | G35: 3 | Q35: 1
C41: 62 | G41: 63 | Q41: 15
A46: Y | O46: UV
A47: 64x64 | C47: 以4个独立的 32x32 计算 | O47: 32x32 | Q47: 以4个独立的16x16 计算
D51: 0 | H51: 1 | P51: 0 | T51: 1
D58: 2 | H58: 3 | P58: 2 | T58: 3

Sheet 264PMF Y c0 round0
A1: tile | B1: 264PMF c0 round0 | I1: =v0!K75 -> H264 | J1: =v0!L75 -> 0 | K1: =v0!M75 -> 0 | L1: =v0!N75 -> 0 | M1: =v0!O75 -> 0 | N1: =v0!P75 -> 0 | O1: =v0!Q75 -> 0 | P1: =v0!R75 -> 0
A2: x | B2: CYCLE | I2: =v0!K76 -> inter pk in | J2: =v0!L76 -> inter pk work | K2: =v0!M76 -> inter pk out | L2: =v0!N76 -> 0 | M2: =v0!O76 -> 0 | N2: =v0!P76 -> tqitq16x16 input | O2: =v0!Q76 -> tqitq work | P2: =v0!R76 -> tqitq out
A3: y | B3: MODE | I3: =v0!K77 -> 1 | J3: =v0!L77 -> 1 | K3: =v0!M77 -> 3 | L3: =v0!N77 -> 0 | M3: =v0!O77 -> 0 | N3: =v0!P77 -> 0 | O3: =v0!Q77 -> 0 | P3: =v0!R77 -> 0
A4: mode | B4: pipe begin | C4: input begin | D4: input end | E4: output begin | F4: output end | I4: =v0!K78 -> sel pk in | J4: =v0!L78 -> sel pk work | K4: =v0!M78 -> sel pk out | L4: =v0!N78 -> 0 | M4: =v0!O78 -> 0 | N4: =v0!P78 -> tqitq8x8 input | O4: =v0!Q78 -> tqitq work | P4: =v0!R78 -> tqitq out
A5: PMF_8M4_0 | B5: 0 | C5: =B5+I$11 -> 2 | D5: =C5+J$11 -> 15 | E5: =D5+K$11 -> 23 | F5: =E5+L$11 -> 27 | I5: =v0!K79 -> 0 | J5: =v0!L79 -> 0 | K5: =v0!M79 -> 0 | L5: =v0!N79 -> 0 | M5: =v0!O79 -> 0 | N5: =v0!P79 -> 0 | O5: =v0!Q79 -> 12 | P5: =v0!R79 -> 0
A6: PMF_8F4_0 | B6: =D5-2 -> 13 | C6: =B6+I$11 -> 15 | D6: =C6+J$11 -> 28 | E6: =D6+K$11 -> 36 | F6: =E6+L$11 -> 40 | I6: =v0!K80 -> Yread latancy | J6: =v0!L80 -> 32x32 input cc | K6: =v0!M80 -> 32x32 work cc | L6: =v0!N80 -> 32x32 output cc | M6: =v0!O80 -> 0 | N6: =v0!P80 -> tqitq4x4 input | O6: =v0!Q80 -> tqitq work | P6: =v0!R80 -> tqitq out
A7: TQITQ_F4 | C7: =F6 -> 40 | D7: =C7+N$5 -> 40 | E7: =D7+O$5 -> 52 | F7: =E7+P$5 -> 52 | I7: =v0!K81 -> 0 | J7: =v0!L81 -> 0 | K7: =v0!M81 -> 0 | L7: =v0!N81 -> 0 | M7: =v0!O81 -> 0 | O7: =v0!Q81 -> 12 | P7: =v0!R81 -> 0
A8: INTER_PK8 | C8: =F7 -> 52 | D8: =C8+I$3 -> 53 | E8: =D8+J$3 -> 54 | F8: =E8+K$3 -> 57 | I8: =v0!K82 -> Yread latancy | J8: =v0!L82 -> 16x16 input cc | K8: =v0!M82 -> 16x16 work cc | L8: =v0!N82 -> 16x16 output cc | M8: =v0!O82 -> 0 | N8: =v0!P82 -> chroma | O8: =v0!Q82 -> 0 | P8: =v0!R82 -> 0
A9: PMF_8M4_1 | B9: =F8 -> 57 | C9: =B9+I$11 -> 59 | D9: =C9+J$11 -> 72 | E9: =D9+K$11 -> 80 | F9: =E9+L$11 -> 84 | I9: =v0!K83 -> 2 | J9: =v0!L83 -> 44 | K9: =v0!M83 -> -22 | L9: 24 | M9: =v0!O83 -> 0 | N9: =v0!P83 -> tqitq16x16 input | O9: =v0!Q83 -> tqitq work | P9: =v0!R83 -> tqitq out
A10: TQITQ_M4 | C10: =F9 -> 84 | D10: =C10+N$5 -> 84 | E10: =D10+O$5 -> 96 | F10: =E10+P$5 -> 96 | I10: =v0!K84 -> Yread latancy | J10: =v0!L84 -> 8x8 input cc | K10: =v0!M84 -> 8x8 work cc | L10: =v0!N84 -> 8x8 output cc | M10: =v0!O84 -> 0 | N10: =v0!P84 -> 0 | O10: =v0!Q84 -> 0 | P10: =v0!R84 -> 0
A11: INTER_PK8 | C11: =F10 -> 96 | D11: =C11+I$3 -> 97 | E11: =D11+J$3 -> 98 | F11: =E11+K$3 -> 101 | I11: =v0!K85 -> 2 | J11: =v0!L85 -> 13 | K11: =v0!M85 -> 8 | L11: =v0!N85 -> 4 | M11: =v0!O85 -> 0 | N11: =v0!P85 -> tqitq8x8 input | O11: =v0!Q85 -> tqitq work | P11: =v0!R85 -> tqitq out
A12: PMF_8M4_2 | B12: =F11 -> 101 | C12: =B12+I$11 -> 103 | D12: =C12+J$11 -> 116 | E12: =D12+K$11 -> 124 | F12: =E12+L$11 -> 128 | I12: =v0!K86 -> Yread latancy | J12: =v0!L86 -> 4x4 input cc | K12: =v0!M86 -> 4x4 work cc | L12: =v0!N86 -> 4x4 output cc | M12: =v0!O86 -> 0 | N12: =v0!P86 -> 0 | O12: =v0!Q86 -> 0 | P12: =v0!R86 -> 0
A13: TQITQ_M4 | C13: =F12 -> 128 | D13: =C13+N$5 -> 128 | E13: =D13+O$5 -> 140 | F13: =E13+P$5 -> 140 | I13: =v0!K87 -> 0 | J13: =v0!L87 -> 0 | K13: =v0!M87 -> 0 | L13: =v0!N87 -> 0 | M13: =v0!O87 -> 0 | N13: =v0!P87 -> tqitq4x4 input | O13: =v0!Q87 -> tqitq work | P13: =v0!R87 -> tqitq out
A14: INTER_PK8 | C14: =F13 -> 140 | D14: =C14+I$3 -> 141 | E14: =D14+J$3 -> 142 | F14: =E14+K$3 -> 145 | I14: =v0!K88 -> UVread latancy | J14: =v0!L88 -> 16x16 input cc | K14: =v0!M88 -> 16x16 work cc | L14: =v0!N88 -> 16x16 output cc | M14: =v0!O88 -> 0 | N14: =v0!P88 -> 0 | O14: =v0!Q88 -> 12 | P14: =v0!R88 -> 1
A15: PMF_8M4_3 | B15: =F14 -> 145 | C15: =B15+I$11 -> 147 | D15: =C15+J$11 -> 160 | E15: =D15+K$11 -> 168 | F15: =E15+L$11 -> 172 | I15: =v0!K89 -> 0 | J15: =v0!L89 -> 0 | K15: =v0!M89 -> 0 | L15: =v0!N89 -> 0 | M15: =v0!O89 -> 0 | N15: =v0!P89 -> 0 | O15: =v0!Q89 -> 0 | P15: =v0!R89 -> 0
A16: TQITQ_M4 | C16: =F15 -> 172 | D16: =C16+N$5 -> 172 | E16: =D16+O$5 -> 184 | F16: =E16+P$5 -> 184 | I16: =v0!K90 -> UVread latancy | J16: =v0!L90 -> 8x8 input cc | K16: =v0!M90 -> 8x8 work cc | L16: =v0!N90 -> 8x8 output cc | M16: =v0!O90 -> 0 | N16: =v0!P90 -> 0 | O16: =v0!Q90 -> 0 | P16: =v0!R90 -> 0
A17: INTER_PK8 | C17: =F16 -> 184 | D17: =C17+I$3 -> 185 | E17: =D17+J$3 -> 186 | F17: =E17+K$3 -> 189 | I17: =v0!K91 -> 2 | J17: =v0!L91 -> 26 | K17: =v0!M91 -> -8 | L17: =v0!N91 -> 8 | M17: =v0!O91 -> 0 | N17: =v0!P91 -> 0 | O17: =v0!Q91 -> 0 | P17: =v0!R91 -> 0
A18: PMF_8F4_1 | B18: =B9-J$11 -> 44 | C18: =B18+I$11 -> 46 | D18: =C18+J$11 -> 59 | E18: =D18+K$11 -> 67 | F18: =E18+L$11 -> 71 | I18: =v0!K92 -> UVread latancy | J18: =v0!L92 -> 4x4 input cc | K18: =v0!M92 -> 4x4 work cc | L18: =v0!N92 -> 4x4 output cc | M18: =v0!O92 -> 0 | N18: =v0!P92 -> 0 | O18: =v0!Q92 -> 0 | P18: =v0!R92 -> 0
A19: PMF_8F4_2 | B19: =B12-J$11 -> 88 | C19: =B19+I$11 -> 90 | D19: =C19+J$11 -> 103 | E19: =D19+K$11 -> 111 | F19: =E19+L$11 -> 115 | I19: =v0!K93 -> 2 | J19: =v0!L93 -> 6 | K19: =v0!M93 -> 8 | L19: =v0!N93 -> 2 | M19: =v0!O93 -> 0 | N19: =v0!P93 -> 0 | O19: =v0!Q93 -> 0 | P19: =v0!R93 -> 0
A20: PMF_8F4_3 | B20: =B15-J$11 -> 132 | C20: =B20+I$11 -> 134 | D20: =C20+J$11 -> 147 | E20: =D20+K$11 -> 155 | F20: =E20+L$11 -> 159 | I20: =v0!K94 -> 0 | J20: =v0!L94 -> 0 | K20: =v0!M94 -> 0 | L20: =v0!N94 -> 0 | M20: =v0!O94 -> 0 | N20: =v0!P94 -> 0 | O20: =v0!Q94 -> 0 | P20: =v0!R94 -> 0
I21: =v0!K95 -> 0 | J21: =v0!L95 -> 0 | K21: =v0!M95 -> 0 | L21: =v0!N95 -> 0 | M21: =v0!O95 -> 0 | N21: =v0!P95 -> 0 | O21: =v0!Q95 -> 0 | P21: =v0!R95 -> 0
I22: =v0!K96 -> 0 | J22: =v0!L96 -> 0 | K22: =v0!M96 -> 0 | L22: =v0!N96 -> 0 | M22: =v0!O96 -> 0 | N22: =v0!P96 -> 0 | O22: =v0!Q96 -> 0 | P22: =v0!R96 -> 0
I23: =v0!K97 -> 0 | J23: =v0!L97 -> 0 | K23: =v0!M97 -> 0 | L23: =v0!N97 -> 0 | M23: =v0!O97 -> 0 | N23: =v0!P97 -> 0 | O23: =v0!Q97 -> 0 | P23: =v0!R97 -> 0
I24: =v0!K98 -> 0 | J24: =v0!L98 -> 0 | K24: =v0!M98 -> 0 | L24: =v0!N98 -> 0 | M24: =v0!O98 -> 0 | N24: =v0!P98 -> 0 | O24: =v0!Q98 -> 0 | P24: =v0!R98 -> 0
I25: =v0!K99 -> 0 | J25: =v0!L99 -> 0 | K25: =v0!M99 -> 0 | L25: =v0!N99 -> 0 | M25: =v0!O99 -> 0 | N25: =v0!P99 -> 0 | O25: =v0!Q99 -> 0 | P25: =v0!R99 -> 0
I26: =v0!K100 -> 0 | J26: =v0!L100 -> 0 | K26: =v0!M100 -> 0 | L26: =v0!N100 -> 0 | M26: =v0!O100 -> 0 | N26: =v0!P100 -> 0 | O26: =v0!Q100 -> 0 | P26: =v0!R100 -> 0

Sheet 264PMF Y c1 round0
A1: tile | B1: 264PMF c1 round0 | I1: =v0!K75 -> H264 | J1: =v0!L75 -> 0 | K1: =v0!M75 -> 0 | L1: =v0!N75 -> 0 | M1: =v0!O75 -> 0 | N1: =v0!P75 -> 0 | O1: =v0!Q75 -> 0 | P1: =v0!R75 -> 0
A2: x | B2: CYCLE | I2: =v0!K76 -> inter pk in | J2: =v0!L76 -> inter pk work | K2: =v0!M76 -> inter pk out | L2: =v0!N76 -> 0 | M2: =v0!O76 -> 0 | N2: =v0!P76 -> tqitq16x16 input | O2: =v0!Q76 -> tqitq work | P2: =v0!R76 -> tqitq out
A3: y | B3: MODE | I3: =v0!K77 -> 1 | J3: =v0!L77 -> 1 | K3: =v0!M77 -> 3 | L3: =v0!N77 -> 0 | M3: =v0!O77 -> 0 | N3: =v0!P77 -> 0 | O3: =v0!Q77 -> 0 | P3: =v0!R77 -> 0
A4: mode | B4: pipe begin | C4: input begin | D4: input end | E4: output begin | F4: output end | I4: =v0!K78 -> sel pk in | J4: =v0!L78 -> sel pk work | K4: =v0!M78 -> sel pk out | L4: =v0!N78 -> 0 | M4: =v0!O78 -> 0 | N4: =v0!P78 -> tqitq8x8 input | O4: =v0!Q78 -> tqitq work | P4: =v0!R78 -> tqitq out
A5: PMF_M16 | B5: 14 | C5: =B5+I9 -> 16 | D5: =C5+J9 -> 60 | E5: =D5+K9+2 -> 40 | I5: =v0!K79 -> 0 | J5: =v0!L79 -> 0 | K5: =v0!M79 -> 0 | L5: =v0!N79 -> 0 | M5: =v0!O79 -> 0 | N5: =v0!P79 -> 0 | O5: =v0!Q79 -> 12 | P5: =v0!R79 -> 0
A6: PMF_F16 | B6: =D5-2+6 -> 64 | C6: =B6+I9 -> 66 | D6: =C6+J9 -> 110 | E6: =D6+K9 -> 88 | I6: =v0!K80 -> Yread latancy | J6: =v0!L80 -> 32x32 input cc | K6: =v0!M80 -> 32x32 work cc | L6: =v0!N80 -> 32x32 output cc | M6: =v0!O80 -> 0 | N6: =v0!P80 -> tqitq4x4 input | O6: =v0!Q80 -> tqitq work | P6: =v0!R80 -> tqitq out
A7: PMF_16M8_0 | E7: =E5 -> 40 | F7: =E7+L$11 -> 44 | I7: =v0!K81 -> 0 | J7: =v0!L81 -> 0 | K7: =v0!M81 -> 0 | L7: =v0!N81 -> 0 | M7: =v0!O81 -> 0 | N7: =v0!P81 -> 0 | O7: =v0!Q81 -> 12 | P7: =v0!R81 -> 0
A8: PMF_16M8_1 | E8: =F7 -> 44 | F8: =E8+L$11 -> 48 | I8: =v0!K82 -> Yread latancy | J8: =v0!L82 -> 16x16 input cc | K8: =v0!M82 -> 16x16 work cc | L8: =v0!N82 -> 16x16 output cc | M8: =v0!O82 -> 0 | N8: =v0!P82 -> chroma | O8: =v0!Q82 -> 0 | P8: =v0!R82 -> 0
A9: PMF_16M8_2 | E9: =F8 -> 48 | F9: =E9+L$11 -> 52 | I9: =v0!K83 -> 2 | J9: =v0!L83 -> 44 | K9: =v0!M83 -> -22 | L9: =v0!N83 -> 32 | M9: =v0!O83 -> 0 | N9: =v0!P83 -> tqitq16x16 input | O9: =v0!Q83 -> tqitq work | P9: =v0!R83 -> tqitq out
A10: PMF_16M8_3 | E10: =F9 -> 52 | F10: =E10+L$11+4 -> 60 | I10: =v0!K84 -> Yread latancy | J10: =v0!L84 -> 8x8 input cc | K10: =v0!M84 -> 8x8 work cc | L10: =v0!N84 -> 8x8 output cc | M10: =v0!O84 -> 0 | N10: =v0!P84 -> 0 | O10: =v0!Q84 -> 0 | P10: =v0!R84 -> 0
A11: PMF_16F8_0 | E11: =E6 -> 88 | F11: =E11+L$11 -> 92 | I11: =v0!K85 -> 2 | J11: =v0!L85 -> 13 | K11: =v0!M85 -> 8 | L11: =v0!N85 -> 4 | M11: =v0!O85 -> 0 | N11: =v0!P85 -> tqitq8x8 input | O11: =v0!Q85 -> tqitq work | P11: =v0!R85 -> tqitq out
A12: PMF_16F8_1 | E12: =F11 -> 92 | F12: =E12+L$11 -> 96 | I12: =v0!K86 -> Yread latancy | J12: =v0!L86 -> 4x4 input cc | K12: =v0!M86 -> 4x4 work cc | L12: =v0!N86 -> 4x4 output cc | M12: =v0!O86 -> 0 | N12: =v0!P86 -> 0 | O12: =v0!Q86 -> 0 | P12: =v0!R86 -> 0
A13: PMF_16F8_2 | E13: =F12 -> 96 | F13: =E13+L$11 -> 100 | I13: =v0!K87 -> 0 | J13: =v0!L87 -> 0 | K13: =v0!M87 -> 0 | L13: =v0!N87 -> 0 | M13: =v0!O87 -> 0 | N13: =v0!P87 -> tqitq4x4 input | O13: =v0!Q87 -> tqitq work | P13: =v0!R87 -> tqitq out
A14: PMF_16F8_3 | E14: =F13 -> 100 | F14: =E14+L$11+4 -> 108 | I14: =v0!K88 -> UVread latancy | J14: =v0!L88 -> 16x16 input cc | K14: =v0!M88 -> 16x16 work cc | L14: =v0!N88 -> 16x16 output cc | M14: =v0!O88 -> 0 | N14: =v0!P88 -> 0 | O14: =v0!Q88 -> 12 | P14: =v0!R88 -> 1
A15: PMF_16M4_0 | E15: =E7+1 -> 41 | F15: =F7+1 -> 45 | I15: =v0!K89 -> 0 | J15: =v0!L89 -> 0 | K15: =v0!M89 -> 0 | L15: =v0!N89 -> 0 | M15: =v0!O89 -> 0 | N15: =v0!P89 -> 0 | O15: =v0!Q89 -> 0 | P15: =v0!R89 -> 0
A16: PMF_16M4_1 | E16: =E8+1 -> 45 | F16: =F8+1 -> 49 | I16: =v0!K90 -> UVread latancy | J16: =v0!L90 -> 8x8 input cc | K16: =v0!M90 -> 8x8 work cc | L16: =v0!N90 -> 8x8 output cc | M16: =v0!O90 -> 0 | N16: =v0!P90 -> 0 | O16: =v0!Q90 -> 0 | P16: =v0!R90 -> 0
A17: PMF_16M4_2 | E17: =E9+1 -> 49 | F17: =F9+1 -> 53 | I17: =v0!K91 -> 2 | J17: =v0!L91 -> 26 | K17: =v0!M91 -> -8 | L17: =v0!N91 -> 8 | M17: =v0!O91 -> 0 | N17: =v0!P91 -> 0 | O17: =v0!Q91 -> 0 | P17: =v0!R91 -> 0
A18: PMF_16M4_3 | E18: =E10+1 -> 53 | F18: =F10+1 -> 61 | I18: =v0!K92 -> UVread latancy | J18: =v0!L92 -> 4x4 input cc | K18: =v0!M92 -> 4x4 work cc | L18: =v0!N92 -> 4x4 output cc | M18: =v0!O92 -> 0 | N18: =v0!P92 -> 0 | O18: =v0!Q92 -> 0 | P18: =v0!R92 -> 0
A19: PMF_16F4_0 | E19: =E11+1 -> 89 | F19: =F11+1 -> 93 | I19: =v0!K93 -> 2 | J19: =v0!L93 -> 6 | K19: =v0!M93 -> 8 | L19: =v0!N93 -> 2 | M19: =v0!O93 -> 0 | N19: =v0!P93 -> 0 | O19: =v0!Q93 -> 0 | P19: =v0!R93 -> 0
A20: PMF_16F4_1 | E20: =E12+1 -> 93 | F20: =F12+1 -> 97 | I20: =v0!K94 -> 0 | J20: =v0!L94 -> 0 | K20: =v0!M94 -> 0 | L20: =v0!N94 -> 0 | M20: =v0!O94 -> 0 | N20: =v0!P94 -> 0 | O20: =v0!Q94 -> 0 | P20: =v0!R94 -> 0
A21: PMF_16F4_2 | E21: =E13+1 -> 97 | F21: =F13+1 -> 101 | I21: =v0!K95 -> 0 | J21: =v0!L95 -> 0 | K21: =v0!M95 -> 0 | L21: =v0!N95 -> 0 | M21: =v0!O95 -> 0 | N21: =v0!P95 -> 0 | O21: =v0!Q95 -> 0 | P21: =v0!R95 -> 0
A22: PMF_16F4_3 | E22: =E14+1 -> 101 | F22: =F14+1 -> 109 | I22: =v0!K96 -> 0 | J22: =v0!L96 -> 0 | K22: =v0!M96 -> 0 | L22: =v0!N96 -> 0 | M22: =v0!O96 -> 0 | N22: =v0!P96 -> 0 | O22: =v0!Q96 -> 0 | P22: =v0!R96 -> 0
I23: =v0!K97 -> 0 | J23: =v0!L97 -> 0 | K23: =v0!M97 -> 0 | L23: =v0!N97 -> 0 | M23: =v0!O97 -> 0 | N23: =v0!P97 -> 0 | O23: =v0!Q97 -> 0 | P23: =v0!R97 -> 0
I24: =v0!K98 -> 0 | J24: =v0!L98 -> 0 | K24: =v0!M98 -> 0 | L24: =v0!N98 -> 0 | M24: =v0!O98 -> 0 | N24: =v0!P98 -> 0 | O24: =v0!Q98 -> 0 | P24: =v0!R98 -> 0
I25: =v0!K99 -> 0 | J25: =v0!L99 -> 0 | K25: =v0!M99 -> 0 | L25: =v0!N99 -> 0 | M25: =v0!O99 -> 0 | N25: =v0!P99 -> 0 | O25: =v0!Q99 -> 0 | P25: =v0!R99 -> 0
I26: =v0!K100 -> 0 | J26: =v0!L100 -> 0 | K26: =v0!M100 -> 0 | L26: =v0!N100 -> 0 | M26: =v0!O100 -> 0 | N26: =v0!P100 -> 0 | O26: =v0!Q100 -> 0 | P26: =v0!R100 -> 0

Sheet 264PMF UV c0 round0
A1: tile | B1: 264PMF UV c0 round0 | I1: =v0!K75 -> H264 | J1: =v0!L75 -> 0 | K1: =v0!M75 -> 0 | L1: =v0!N75 -> 0 | M1: =v0!O75 -> 0 | N1: =v0!P75 -> 0 | O1: =v0!Q75 -> 0 | P1: =v0!R75 -> 0
A2: x | B2: CYCLE | I2: =v0!K76 -> inter pk in | J2: =v0!L76 -> inter pk work | K2: =v0!M76 -> inter pk out | L2: =v0!N76 -> 0 | M2: =v0!O76 -> 0 | N2: =v0!P76 -> tqitq16x16 input | O2: =v0!Q76 -> tqitq work | P2: =v0!R76 -> tqitq out
A3: y | B3: MODE | I3: =v0!K77 -> 1 | J3: =v0!L77 -> 1 | K3: =v0!M77 -> 3 | L3: =v0!N77 -> 0 | M3: =v0!O77 -> 0 | N3: =v0!P77 -> 0 | O3: =v0!Q77 -> 0 | P3: =v0!R77 -> 0
A4: mode | B4: pipe begin | C4: input begin | D4: input end | E4: output begin | F4: output end | I4: =v0!K78 -> sel pk in | J4: =v0!L78 -> sel pk work | K4: =v0!M78 -> sel pk out | L4: =v0!N78 -> 0 | M4: =v0!O78 -> 0 | N4: =v0!P78 -> tqitq8x8 input | O4: =v0!Q78 -> tqitq work | P4: =v0!R78 -> tqitq out
A5: PMF_M4_0 | B5: 0 | C5: =B5+I$19 -> 2 | D5: =C5+J$19 -> 8 | E5: =D5+K$19 -> 16 | F5: =E5+L$19 -> 18 | I5: =v0!K79 -> 0 | J5: =v0!L79 -> 0 | K5: =v0!M79 -> 0 | L5: =v0!N79 -> 0 | M5: =v0!O79 -> 0 | N5: =v0!P79 -> 0 | O5: =v0!Q79 -> 12 | P5: =v0!R79 -> 0
A6: PMF_F4_0 | B6: =D5-2 -> 6 | C6: =B6+I$19 -> 8 | D6: =C6+J$19 -> 14 | E6: =D6+K$19 -> 22 | F6: =E6+L$19 -> 24 | I6: =v0!K80 -> Yread latancy | J6: =v0!L80 -> 32x32 input cc | K6: =v0!M80 -> 32x32 work cc | L6: =v0!N80 -> 32x32 output cc | M6: =v0!O80 -> 0 | N6: =v0!P80 -> tqitq4x4 input | O6: =v0!Q80 -> tqitq work | P6: =v0!R80 -> tqitq out
A7: TQITQ_F4 | C7: =F6 -> 24 | D7: =C7+N$14 -> 24 | E7: =D7+O$14 -> 36 | F7: =E7+P$14 -> 37 | I7: =v0!K81 -> 0 | J7: =v0!L81 -> 0 | K7: =v0!M81 -> 0 | L7: =v0!N81 -> 0 | M7: =v0!O81 -> 0 | N7: 0 | O7: =v0!Q81 -> 12 | P7: =v0!R81 -> 0
A8: INTER_PK4 | C8: =F7 -> 37 | D8: =C8+I$3 -> 38 | E8: =D8+J$3 -> 39 | F8: =E8+K$3 -> 42 | I8: =v0!K82 -> Yread latancy | J8: =v0!L82 -> 16x16 input cc | K8: =v0!M82 -> 16x16 work cc | L8: =v0!N82 -> 16x16 output cc | M8: =v0!O82 -> 0 | N8: =v0!P82 -> chroma | O8: =v0!Q82 -> 0 | P8: =v0!R82 -> 0
A9: SEL_PK4 | C9: =F8 -> 42 | D9: =C9+I$5 -> 42 | E9: =D9+J$5 -> 42 | F9: =E9+K$5 -> 42 | I9: =v0!K83 -> 2 | J9: =v0!L83 -> 44 | K9: =v0!M83 -> -22 | L9: 24 | M9: =v0!O83 -> 0 | N9: =v0!P83 -> tqitq16x16 input | O9: =v0!Q83 -> tqitq work | P9: =v0!R83 -> tqitq out
A10: PMF_M4_1 | B10: ='264PMF Y c0 round0'!B9 -> 57 | C10: =B10+I$19 -> 59 | D10: =C10+J$19 -> 65 | E10: =D10+K$19 -> 73 | F10: =E10+L$19 -> 75 | I10: =v0!K84 -> Yread latancy | J10: =v0!L84 -> 8x8 input cc | K10: =v0!M84 -> 8x8 work cc | L10: =v0!N84 -> 8x8 output cc | M10: =v0!O84 -> 0 | N10: =v0!P84 -> 0 | O10: =v0!Q84 -> 0 | P10: =v0!R84 -> 0
A11: TQITQ_M4 | C11: =F10 -> 75 | D11: =C11+N$14 -> 75 | E11: =D11+O$14 -> 87 | F11: =E11+P$14 -> 88 | I11: =v0!K85 -> 2 | J11: =v0!L85 -> 13 | K11: =v0!M85 -> 8 | L11: =v0!N85 -> 4 | M11: =v0!O85 -> 0 | N11: =v0!P85 -> tqitq8x8 input | O11: =v0!Q85 -> tqitq work | P11: =v0!R85 -> tqitq out
A12: INTER_PK4 | C12: =F11 -> 88 | D12: =C12+I$3 -> 89 | E12: =D12+J$3 -> 90 | F12: =E12+K$3 -> 93 | I12: =v0!K86 -> Yread latancy | J12: =v0!L86 -> 4x4 input cc | K12: =v0!M86 -> 4x4 work cc | L12: =v0!N86 -> 4x4 output cc | M12: =v0!O86 -> 0 | N12: =v0!P86 -> 0 | O12: =v0!Q86 -> 0 | P12: =v0!R86 -> 0
A13: SEL_PK4 | C13: =F12 -> 93 | D13: =C13+I$5 -> 93 | E13: =D13+J$5 -> 93 | F13: =E13+K$5 -> 93 | I13: =v0!K87 -> 0 | J13: =v0!L87 -> 0 | K13: =v0!M87 -> 0 | L13: =v0!N87 -> 0 | M13: =v0!O87 -> 0 | N13: =v0!P87 -> tqitq4x4 input | O13: =v0!Q87 -> tqitq work | P13: =v0!R87 -> tqitq out
A14: PMF_M4_2 | B14: ='264PMF Y c0 round0'!B12 -> 101 | C14: =B14+I$19 -> 103 | D14: =C14+J$19 -> 109 | E14: =D14+K$19 -> 117 | F14: =E14+L$19 -> 119 | I14: =v0!K88 -> UVread latancy | J14: =v0!L88 -> 16x16 input cc | K14: =v0!M88 -> 16x16 work cc | L14: =v0!N88 -> 16x16 output cc | M14: =v0!O88 -> 0 | N14: =v0!P88 -> 0 | O14: =v0!Q88 -> 12 | P14: =v0!R88 -> 1
A15: TQITQ_M4 | C15: =F14 -> 119 | D15: =C15+N$14 -> 119 | E15: =D15+O$14 -> 131 | F15: =E15+P$14 -> 132 | I15: =v0!K89 -> 0 | J15: =v0!L89 -> 0 | K15: =v0!M89 -> 0 | L15: =v0!N89 -> 0 | M15: =v0!O89 -> 0 | N15: =v0!P89 -> 0 | O15: =v0!Q89 -> 0 | P15: =v0!R89 -> 0
A16: INTER_PK4 | C16: =F15 -> 132 | D16: =C16+I$3 -> 133 | E16: =D16+J$3 -> 134 | F16: =E16+K$3 -> 137 | I16: =v0!K90 -> UVread latancy | J16: =v0!L90 -> 8x8 input cc | K16: =v0!M90 -> 8x8 work cc | L16: =v0!N90 -> 8x8 output cc | M16: =v0!O90 -> 0 | N16: =v0!P90 -> 0 | O16: =v0!Q90 -> 0 | P16: =v0!R90 -> 0
A17: SEL_PK4 | C17: =F16 -> 137 | D17: =C17+I$5 -> 137 | E17: =D17+J$5 -> 137 | F17: =E17+K$5 -> 137 | I17: =v0!K91 -> 2 | J17: =v0!L91 -> 26 | K17: =v0!M91 -> -8 | L17: =v0!N91 -> 8 | M17: =v0!O91 -> 0 | N17: =v0!P91 -> 0 | O17: =v0!Q91 -> 0 | P17: =v0!R91 -> 0
A18: PMF_M4_3 | B18: ='264PMF Y c0 round0'!B15 -> 145 | C18: =B18+I$19 -> 147 | D18: =C18+J$19 -> 153 | E18: =D18+K$19 -> 161 | F18: =E18+L$19 -> 163 | I18: =v0!K92 -> UVread latancy | J18: =v0!L92 -> 4x4 input cc | K18: =v0!M92 -> 4x4 work cc | L18: =v0!N92 -> 4x4 output cc | M18: =v0!O92 -> 0 | N18: =v0!P92 -> 0 | O18: =v0!Q92 -> 0 | P18: =v0!R92 -> 0
A19: TQITQ_M4 | C19: =F18 -> 163 | D19: =C19+N$14 -> 163 | E19: =D19+O$14 -> 175 | F19: =E19+P$14 -> 176 | I19: =v0!K93 -> 2 | J19: =v0!L93 -> 6 | K19: =v0!M93 -> 8 | L19: =v0!N93 -> 2 | M19: =v0!O93 -> 0 | N19: =v0!P93 -> 0 | O19: =v0!Q93 -> 0 | P19: =v0!R93 -> 0
A20: INTER_PK4 | C20: =F19 -> 176 | D20: =C20+I$3 -> 177 | E20: =D20+J$3 -> 178 | F20: =E20+K$3 -> 181 | I20: =v0!K94 -> 0 | J20: =v0!L94 -> 0 | K20: =v0!M94 -> 0 | L20: =v0!N94 -> 0 | M20: =v0!O94 -> 0 | N20: =v0!P94 -> 0 | O20: =v0!Q94 -> 0 | P20: =v0!R94 -> 0
A21: SEL_PK4 | C21: =F20 -> 181 | D21: =C21+I$5 -> 181 | E21: =D21+J$5 -> 181 | F21: =E21+K$5 -> 181 | I21: =v0!K95 -> 0 | J21: =v0!L95 -> 0 | K21: =v0!M95 -> 0 | L21: =v0!N95 -> 0 | M21: =v0!O95 -> 0 | N21: =v0!P95 -> 0 | O21: =v0!Q95 -> 0 | P21: =v0!R95 -> 0
A22: PMF_F4_1 | B22: =D6-2 -> 12 | C22: =B22+I$19 -> 14 | D22: =C22+J$19 -> 20 | E22: =D22+K$19 -> 28 | F22: =E22+L$19 -> 30 | I22: =v0!K96 -> 0 | J22: =v0!L96 -> 0 | K22: =v0!M96 -> 0 | L22: =v0!N96 -> 0 | M22: =v0!O96 -> 0 | N22: =v0!P96 -> 0 | O22: =v0!Q96 -> 0 | P22: =v0!R96 -> 0
A23: PMF_F4_2 | B23: =B14-J19 -> 95 | C23: =B23+I$19 -> 97 | D23: =C23+J$19 -> 103 | E23: =D23+K$19 -> 111 | F23: =E23+L$19 -> 113 | I23: =v0!K97 -> 0 | J23: =v0!L97 -> 0 | K23: =v0!M97 -> 0 | L23: =v0!N97 -> 0 | M23: =v0!O97 -> 0 | N23: =v0!P97 -> 0 | O23: =v0!Q97 -> 0 | P23: =v0!R97 -> 0
A24: PMF_F4_3 | B24: =B18-J19 -> 139 | C24: =B24+I$19 -> 141 | D24: =C24+J$19 -> 147 | E24: =D24+K$19 -> 155 | F24: =E24+L$19 -> 157 | I24: =v0!K98 -> 0 | J24: =v0!L98 -> 0 | K24: =v0!M98 -> 0 | L24: =v0!N98 -> 0 | M24: =v0!O98 -> 0 | N24: =v0!P98 -> 0 | O24: =v0!Q98 -> 0 | P24: =v0!R98 -> 0
I25: =v0!K99 -> 0 | J25: =v0!L99 -> 0 | K25: =v0!M99 -> 0 | L25: =v0!N99 -> 0 | M25: =v0!O99 -> 0 | N25: =v0!P99 -> 0 | O25: =v0!Q99 -> 0 | P25: =v0!R99 -> 0
I26: =v0!K100 -> 0 | J26: =v0!L100 -> 0 | K26: =v0!M100 -> 0 | L26: =v0!N100 -> 0 | M26: =v0!O100 -> 0 | N26: =v0!P100 -> 0 | O26: =v0!Q100 -> 0 | P26: =v0!R100 -> 0

Sheet 264PMF UV c1 round0
A1: tile | B1: 264PMF UV c1 round0 | I1: =v0!K75 -> H264 | J1: =v0!L75 -> 0 | K1: =v0!M75 -> 0 | L1: =v0!N75 -> 0 | M1: =v0!O75 -> 0 | N1: =v0!P75 -> 0 | O1: =v0!Q75 -> 0 | P1: =v0!R75 -> 0
A2: x | B2: CYCLE | I2: =v0!K76 -> inter pk in | J2: =v0!L76 -> inter pk work | K2: =v0!M76 -> inter pk out | L2: =v0!N76 -> 0 | M2: =v0!O76 -> 0 | N2: =v0!P76 -> tqitq16x16 input | O2: =v0!Q76 -> tqitq work | P2: =v0!R76 -> tqitq out
A3: y | B3: MODE | I3: =v0!K77 -> 1 | J3: =v0!L77 -> 1 | K3: =v0!M77 -> 3 | L3: =v0!N77 -> 0 | M3: =v0!O77 -> 0 | N3: =v0!P77 -> 0 | O3: =v0!Q77 -> 0 | P3: =v0!R77 -> 0
A4: mode | B4: pipe begin | C4: input begin | D4: input end | E4: output begin | F4: output end | I4: =v0!K78 -> sel pk in | J4: =v0!L78 -> sel pk work | K4: =v0!M78 -> sel pk out | L4: =v0!N78 -> 0 | M4: =v0!O78 -> 0 | N4: =v0!P78 -> tqitq8x8 input | O4: =v0!Q78 -> tqitq work | P4: =v0!R78 -> tqitq out
A5: PMF_M8 | B5: ='264PMF Y c1 round0'!B5 -> 14 | C5: =B5+I17 -> 16 | D5: =C5+J17 -> 34 | E5: =D5+K17+4 -> 30 | I5: =v0!K79 -> 0 | J5: =v0!L79 -> 0 | K5: =v0!M79 -> 0 | L5: =v0!N79 -> 0 | M5: =v0!O79 -> 0 | N5: =v0!P79 -> 0 | O5: =v0!Q79 -> 12 | P5: =v0!R79 -> 0
A6: PMF_F8 | B6: ='264PMF Y c1 round0'!B6 -> 64 | C6: =B6+I17 -> 66 | D6: =C6+J17 -> 84 | E6: =D6+K17 -> 76 | I6: =v0!K80 -> Yread latancy | J6: =v0!L80 -> 32x32 input cc | K6: =v0!M80 -> 32x32 work cc | L6: =v0!N80 -> 32x32 output cc | M6: =v0!O80 -> 0 | N6: =v0!P80 -> tqitq4x4 input | O6: =v0!Q80 -> tqitq work | P6: =v0!R80 -> tqitq out
A7: PMF_8M4_0 | E7: =E5+1 -> 31 | F7: =E7+2 -> 33 | I7: =v0!K81 -> 0 | J7: =v0!L81 -> 0 | K7: =v0!M81 -> 0 | L7: =v0!N81 -> 0 | M7: =v0!O81 -> 0 | N7: =v0!P81 -> 0 | O7: =v0!Q81 -> 12 | P7: =v0!R81 -> 0
A8: PMF_8M4_1 | E8: =F7 -> 33 | F8: =E8+2 -> 35 | I8: =v0!K82 -> Yread latancy | J8: =v0!L82 -> 16x16 input cc | K8: =v0!M82 -> 16x16 work cc | L8: =v0!N82 -> 16x16 output cc | M8: =v0!O82 -> 0 | N8: =v0!P82 -> chroma | O8: =v0!Q82 -> 0 | P8: =v0!R82 -> 0
A9: PMF_8M4_2 | E9: =F8 -> 35 | F9: =E9+2 -> 37 | I9: =v0!K83 -> 2 | J9: =v0!L83 -> 44 | K9: =v0!M83 -> -22 | L9: 24 | M9: =v0!O83 -> 0 | N9: =v0!P83 -> tqitq16x16 input | O9: =v0!Q83 -> tqitq work | P9: =v0!R83 -> tqitq out
A10: PMF_8M4_3 | E10: =F9 -> 37 | F10: =E10+4 -> 41 | I10: =v0!K84 -> Yread latancy | J10: =v0!L84 -> 8x8 input cc | K10: =v0!M84 -> 8x8 work cc | L10: =v0!N84 -> 8x8 output cc | M10: =v0!O84 -> 0 | N10: =v0!P84 -> 0 | O10: =v0!Q84 -> 0 | P10: =v0!R84 -> 0
A11: PMF_8F4_0 | E11: =E6+1 -> 77 | F11: =E11+2 -> 79 | I11: =v0!K85 -> 2 | J11: =v0!L85 -> 13 | K11: =v0!M85 -> 8 | L11: =v0!N85 -> 4 | M11: =v0!O85 -> 0 | N11: =v0!P85 -> tqitq8x8 input | O11: =v0!Q85 -> tqitq work | P11: =v0!R85 -> tqitq out
A12: PMF_8F4_1 | E12: =F11 -> 79 | F12: =E12+2 -> 81 | I12: =v0!K86 -> Yread latancy | J12: =v0!L86 -> 4x4 input cc | K12: =v0!M86 -> 4x4 work cc | L12: =v0!N86 -> 4x4 output cc | M12: =v0!O86 -> 0 | N12: =v0!P86 -> 0 | O12: =v0!Q86 -> 0 | P12: =v0!R86 -> 0
A13: PMF_8F4_2 | E13: =F12 -> 81 | F13: =E13+2 -> 83 | I13: =v0!K87 -> 0 | J13: =v0!L87 -> 0 | K13: =v0!M87 -> 0 | L13: =v0!N87 -> 0 | M13: =v0!O87 -> 0 | N13: =v0!P87 -> tqitq4x4 input | O13: =v0!Q87 -> tqitq work | P13: =v0!R87 -> tqitq out
A14: PMF_8F4_3 | E14: =F13 -> 83 | F14: =E14+4 -> 87 | I14: =v0!K88 -> UVread latancy | J14: =v0!L88 -> 16x16 input cc | K14: =v0!M88 -> 16x16 work cc | L14: =v0!N88 -> 16x16 output cc | M14: =v0!O88 -> 0 | N14: =v0!P88 -> 0 | O14: =v0!Q88 -> 12 | P14: =v0!R88 -> 1
I15: =v0!K89 -> 0 | J15: =v0!L89 -> 0 | K15: =v0!M89 -> 0 | L15: =v0!N89 -> 0 | M15: =v0!O89 -> 0 | N15: =v0!P89 -> 0 | O15: =v0!Q89 -> 0 | P15: =v0!R89 -> 0
I16: =v0!K90 -> UVread latancy | J16: =v0!L90 -> 8x8 input cc | K16: =v0!M90 -> 8x8 work cc | L16: =v0!N90 -> 8x8 output cc | M16: =v0!O90 -> 0 | N16: =v0!P90 -> 0 | O16: =v0!Q90 -> 0 | P16: =v0!R90 -> 0
I17: =v0!K91 -> 2 | J17: 18 | K17: =v0!M91 -> -8 | L17: =v0!N91 -> 8 | M17: =v0!O91 -> 0 | N17: =v0!P91 -> 0 | O17: =v0!Q91 -> 0 | P17: =v0!R91 -> 0
I18: =v0!K92 -> UVread latancy | J18: =v0!L92 -> 4x4 input cc | K18: =v0!M92 -> 4x4 work cc | L18: =v0!N92 -> 4x4 output cc | M18: =v0!O92 -> 0 | N18: =v0!P92 -> 0 | O18: =v0!Q92 -> 0 | P18: =v0!R92 -> 0
I19: =v0!K93 -> 2 | J19: =v0!L93 -> 6 | K19: =v0!M93 -> 8 | L19: =v0!N93 -> 2 | M19: =v0!O93 -> 0 | N19: =v0!P93 -> 0 | O19: =v0!Q93 -> 0 | P19: =v0!R93 -> 0
I20: =v0!K94 -> 0 | J20: =v0!L94 -> 0 | K20: =v0!M94 -> 0 | L20: =v0!N94 -> 0 | M20: =v0!O94 -> 0 | N20: =v0!P94 -> 0 | O20: =v0!Q94 -> 0 | P20: =v0!R94 -> 0
I21: =v0!K95 -> 0 | J21: =v0!L95 -> 0 | K21: =v0!M95 -> 0 | L21: =v0!N95 -> 0 | M21: =v0!O95 -> 0 | N21: =v0!P95 -> 0 | O21: =v0!Q95 -> 0 | P21: =v0!R95 -> 0
I22: =v0!K96 -> 0 | J22: =v0!L96 -> 0 | K22: =v0!M96 -> 0 | L22: =v0!N96 -> 0 | M22: =v0!O96 -> 0 | N22: =v0!P96 -> 0 | O22: =v0!Q96 -> 0 | P22: =v0!R96 -> 0
I23: =v0!K97 -> 0 | J23: =v0!L97 -> 0 | K23: =v0!M97 -> 0 | L23: =v0!N97 -> 0 | M23: =v0!O97 -> 0 | N23: =v0!P97 -> 0 | O23: =v0!Q97 -> 0 | P23: =v0!R97 -> 0
I24: =v0!K98 -> 0 | J24: =v0!L98 -> 0 | K24: =v0!M98 -> 0 | L24: =v0!N98 -> 0 | M24: =v0!O98 -> 0 | N24: =v0!P98 -> 0 | O24: =v0!Q98 -> 0 | P24: =v0!R98 -> 0
I25: =v0!K99 -> 0 | J25: =v0!L99 -> 0 | K25: =v0!M99 -> 0 | L25: =v0!N99 -> 0 | M25: =v0!O99 -> 0 | N25: =v0!P99 -> 0 | O25: =v0!Q99 -> 0 | P25: =v0!R99 -> 0
I26: =v0!K100 -> 0 | J26: =v0!L100 -> 0 | K26: =v0!M100 -> 0 | L26: =v0!N100 -> 0 | M26: =v0!O100 -> 0 | N26: =v0!P100 -> 0 | O26: =v0!Q100 -> 0 | P26: =v0!R100 -> 0

Sheet PMF c0 round0
A1: tile | B1: PMF c0 round0 | H1: =v0!A76 -> inter pk in | I1: =v0!B76 -> inter pk work | J1: =v0!C76 -> inter pk out | L1: =v0!A78 -> sel pk in | M1: =v0!B78 -> sel pk work | N1: =v0!C78 -> sel pk out | P1: =v0!A84 -> Yread latancy | Q1: =v0!B84 -> 8x8 input cc | R1: =v0!C84 -> 8x8 work cc | S1: =v0!D84 -> 8x8 output cc | U1: =v0!G76 -> tqitq8x8 input | V1: =v0!H76 -> tqitq work | W1: =v0!I76 -> tqitq out | Y1: =v0!A82 -> Yread latancy | Z1: =v0!B82 -> 16x16 input cc | AA1: =v0!C82 -> 16x16 work cc | AB1: =v0!D82 -> 16x16 output cc
A2: x | B2: CYCLE | H2: =v0!A77 -> 1 | I2: =v0!B77 -> 1 | J2: =v0!C77 -> 1 | L2: =v0!A79 -> 1 | M2: =v0!B79 -> 1 | N2: =v0!C79 -> 4 | P2: =v0!A85 -> 2 | Q2: =v0!B85 -> 8 | R2: =v0!C85 -> 4 | S2: =v0!D85 -> 4 | U2: =v0!G77 -> 0 | V2: =v0!H77 -> 19 | W2: =v0!I77 -> 0 | Y2: =v0!A83 -> 2 | Z2: =v0!B83 -> 23 | AA2: =v0!C83 -> -8 | AB2: =v0!D83 -> 16
A3: y | B3: MODE
A4: mode | B4: pipe begin | C4: input begin | D4: input end | E4: output begin | F4: output end
A5: PMF_M8_0_a | B5: 0 | C5: =B5+$P$2 -> 2 | D5: =C5+$Q$2 -> 10 | E5: =D5+$R$2 -> 14 | F5: =E5+$S$2 -> 18
A6: PMF_M8_0_b | B6: =B5+8 -> 8 | C6: =B6+$P$2 -> 10 | D6: =C6+$Q$2 -> 18 | E6: =D6+$R$2 -> 22 | F6: =E6+$S$2 -> 26
A7: PMF_M8_0_c | B7: =B6+8 -> 16 | C7: =B7+$P$2 -> 18 | D7: =C7+$Q$2 -> 26 | E7: =D7+$R$2 -> 30 | F7: =E7+$S$2 -> 34
A8: PMF_F8_0 | B8: =B7+8 -> 24 | C8: =B8+$P$2 -> 26 | D8: =C8+$Q$2 -> 34 | E8: =D8+$R$2 -> 38 | F8: =E8+$S$2 -> 42
A9: TQITQ_F8 | C9: =F8 -> 42 | D9: =C9+$U$2 -> 42 | E9: =D9+$V$2 -> 61 | F9: =E9+$W$2 -> 61
A10: INTER_PK8 | C10: =F9 -> 61 | D10: =C10+$H$2 -> 62 | E10: =D10+$I$2 -> 63 | F10: =E10+$J$2 -> 64
A11: SEL_PK8 | C11: =F10 -> 64 | D11: =C11+$L$2 -> 65 | E11: =D11+$M$2 -> 66 | F11: =E11+$N$2 -> 70
A12: PMF_M8_1_c | B12: =D31-2 -> 79 | C12: =B12+$P$2 -> 81 | D12: =C12+$Q$2 -> 89 | E12: =D12+$R$2 -> 93 | F12: =E12+$S$2 -> 97
A13: TQITQ_M8 | C13: =F12 -> 97 | D13: =C13+$U$2 -> 97 | E13: =D13+$V$2 -> 116 | F13: =E13+$W$2 -> 116
A14: INTER_PK8 | C14: =F13 -> 116 | D14: =C14+$H$2 -> 117 | E14: =D14+$I$2 -> 118 | F14: =E14+$J$2 -> 119
A15: SEL_PK8 | C15: =F14 -> 119 | D15: =C15+$L$2 -> 120 | E15: =D15+$M$2 -> 121 | F15: =E15+$N$2 -> 125
A16: PMF_M8_2_c | B16: =F15 -> 125 | C16: =B16+$P$2 -> 127 | D16: =C16+$Q$2 -> 135 | E16: =D16+$R$2 -> 139 | F16: =E16+$S$2 -> 143
A17: TQITQ_M8 | C17: =F16 -> 143 | D17: =C17+$U$2 -> 143 | E17: =D17+$V$2 -> 162 | F17: =E17+$W$2 -> 162
A18: INTER_PK8 | C18: =F17 -> 162 | D18: =C18+$H$2 -> 163 | E18: =D18+$I$2 -> 164 | F18: =E18+$J$2 -> 165
A19: SEL_PK8 | C19: =F18 -> 165 | D19: =C19+$L$2 -> 166 | E19: =D19+$M$2 -> 167 | F19: =E19+$N$2 -> 171
A20: PMF_M8_3_c | B20: =F19 -> 171 | C20: =B20+$P$2 -> 173 | D20: =C20+$Q$2 -> 181 | E20: =D20+$R$2 -> 185 | F20: =E20+$S$2 -> 189
A21: TQITQ_F8 | C21: =F20 -> 189 | D21: =C21+$U$2 -> 189 | E21: =D21+$V$2 -> 208 | F21: =E21+$W$2 -> 208
A22: INTER_PK8 | C22: =F21 -> 208 | D22: =C22+$H$2 -> 209 | E22: =D22+$I$2 -> 210 | F22: =E22+$J$2 -> 211
A23: SEL_PK8 | C23: =F22 -> 211 | D23: =C23+$L$2 -> 212 | E23: =D23+$M$2 -> 213 | F23: =E23+$N$2 -> 217
A24: dummy wait | D24: =F23 -> 217 | E24: =D24+7 -> 224 | F24: =E24+1 -> 225
A25: PMF_M8_1_a | B25: =B8+8 -> 32 | C25: =B25+$P$2 -> 34 | D25: =C25+$Q$2 -> 42 | E25: =D25+$R$2 -> 46 | F25: =E25+$S$2 -> 50
A26: PMF_M8_1_b | B26: =B25+8 -> 40 | C26: =B26+$P$2 -> 42 | D26: =C26+$Q$2 -> 50 | E26: =D26+$R$2 -> 54 | F26: =E26+$S$2 -> 58
A27: PMF_F8_1 | B27: =B26+8 -> 48 | C27: =B27+$P$2 -> 50 | D27: =C27+$Q$2 -> 58 | E27: =D27+$R$2 -> 62 | F27: =E27+$S$2 -> 66
A28: PMF_F8_2 | B28: =D30-2 -> 103 | C28: =B28+$P$2 -> 105 | D28: =C28+$Q$2 -> 113 | E28: =D28+$R$2 -> 117 | F28: =E28+$S$2 -> 121
A29: PMF_M8_2_a | B29: =B12+8 -> 87 | C29: =B29+$P$2 -> 89 | D29: =C29+$Q$2 -> 97 | E29: =D29+$R$2 -> 101 | F29: =E29+$S$2 -> 105
A30: PMF_M8_2_b | B30: =B29+8 -> 95 | C30: =B30+$P$2 -> 97 | D30: =C30+$Q$2 -> 105 | E30: =D30+$R$2 -> 109 | F30: =E30+$S$2 -> 113
A31: PMF_M16_0_c | B31: =D27-2 -> 56 | C31: =B31+$Y$2 -> 58 | D31: =C31+$Z$2 -> 81 | E31: =D31+$AA$2+24 -> 97 | F31: =E31+$AB$2 -> 113
A32: PMF_M8_3_a | B32: =D16-2 -> 133 | C32: =B32+$P$2 -> 135 | D32: =C32+$Q$2 -> 143 | E32: =D32+$R$2 -> 147 | F32: =E32+$S$2 -> 151
A33: PMF_M8_3_b | B33: =B32+8 -> 141 | C33: =B33+$P$2 -> 143 | D33: =C33+$Q$2 -> 151 | E33: =D33+$R$2 -> 155 | F33: =E33+$S$2 -> 159
A34: PMF_F8_3 | B34: =D33-2 -> 149 | C34: =B34+$P$2 -> 151 | D34: =C34+$Q$2 -> 159 | E34: =D34+$R$2 -> 163 | F34: =E34+$S$2 -> 167

Sheet PMF sp c0 round0
A1: ='PMF c0 round0'!A1 -> tile | B1: ='PMF c0 round0'!B1 -> PMF c0 round0
A2: ='PMF c0 round0'!A2 -> x | B2: ='PMF c0 round0'!B2 -> CYCLE
A3: ='PMF c0 round0'!A3 -> y | B3: ='PMF c0 round0'!B3 -> MODE
A4: ='PMF c0 round0'!A4 -> mode | B4: ='PMF c0 round0'!B4 -> pipe begin | C4: ='PMF c0 round0'!C4 -> input begin | D4: ='PMF c0 round0'!D4 -> input end | E4: ='PMF c0 round0'!E4 -> output begin | F4: ='PMF c0 round0'!F4 -> output end
A5: ='PMF c0 round0'!A5 -> PMF_M8_0_a | B5: ='PMF c0 round0'!B5 -> 0 | C5: ='PMF c0 round0'!C5 -> 2 | D5: ='PMF c0 round0'!D5 -> 10 | E5: ='PMF c0 round0'!E5+2 -> 16 | F5: ='PMF c0 round0'!F5+2 -> 20
A6: ='PMF c0 round0'!A6 -> PMF_M8_0_b | B6: ='PMF c0 round0'!B6 -> 8 | C6: ='PMF c0 round0'!C6 -> 10 | D6: ='PMF c0 round0'!D6 -> 18 | E6: ='PMF c0 round0'!E6+2 -> 24 | F6: ='PMF c0 round0'!F6+2 -> 28
A7: ='PMF c0 round0'!A7 -> PMF_M8_0_c | B7: ='PMF c0 round0'!B7 -> 16 | C7: ='PMF c0 round0'!C7 -> 18 | D7: ='PMF c0 round0'!D7 -> 26 | E7: ='PMF c0 round0'!E7+2 -> 32 | F7: ='PMF c0 round0'!F7+2 -> 36
A8: ='PMF c0 round0'!A8 -> PMF_F8_0 | B8: ='PMF c0 round0'!B8 -> 24 | C8: ='PMF c0 round0'!C8 -> 26 | D8: ='PMF c0 round0'!D8 -> 34 | E8: ='PMF c0 round0'!E8+2 -> 40 | F8: ='PMF c0 round0'!F8+2 -> 44
A9: ='PMF c0 round0'!A9 -> TQITQ_F8 | B9: ='PMF c0 round0'!B9 -> 0 | C9: ='PMF c0 round0'!C9 -> 42 | D9: ='PMF c0 round0'!D9 -> 42 | E9: ='PMF c0 round0'!E9 -> 61 | F9: ='PMF c0 round0'!F9 -> 61
A10: ='PMF c0 round0'!A10 -> INTER_PK8 | B10: ='PMF c0 round0'!B10 -> 0 | C10: ='PMF c0 round0'!C10 -> 61 | D10: ='PMF c0 round0'!D10 -> 62 | E10: ='PMF c0 round0'!E10 -> 63 | F10: ='PMF c0 round0'!F10 -> 64
A11: ='PMF c0 round0'!A11 -> SEL_PK8 | B11: ='PMF c0 round0'!B11 -> 0 | C11: ='PMF c0 round0'!C11 -> 64 | D11: ='PMF c0 round0'!D11 -> 65 | E11: ='PMF c0 round0'!E11 -> 66 | F11: ='PMF c0 round0'!F11 -> 70
A12: ='PMF c0 round0'!A12 -> PMF_M8_1_c | B12: ='PMF c0 round0'!B12 -> 79 | C12: ='PMF c0 round0'!C12 -> 81 | D12: ='PMF c0 round0'!D12 -> 89 | E12: ='PMF c0 round0'!E12+2 -> 95 | F12: ='PMF c0 round0'!F12+2 -> 99
A13: ='PMF c0 round0'!A13 -> TQITQ_M8 | B13: ='PMF c0 round0'!B13 -> 0 | C13: ='PMF c0 round0'!C13 -> 97 | D13: ='PMF c0 round0'!D13 -> 97 | E13: ='PMF c0 round0'!E13 -> 116 | F13: ='PMF c0 round0'!F13 -> 116
A14: ='PMF c0 round0'!A14 -> INTER_PK8 | B14: ='PMF c0 round0'!B14 -> 0 | C14: ='PMF c0 round0'!C14 -> 116 | D14: ='PMF c0 round0'!D14 -> 117 | E14: ='PMF c0 round0'!E14 -> 118 | F14: ='PMF c0 round0'!F14 -> 119
A15: ='PMF c0 round0'!A15 -> SEL_PK8 | B15: ='PMF c0 round0'!B15 -> 0 | C15: ='PMF c0 round0'!C15 -> 119 | D15: ='PMF c0 round0'!D15 -> 120 | E15: ='PMF c0 round0'!E15 -> 121 | F15: ='PMF c0 round0'!F15 -> 125
A16: ='PMF c0 round0'!A16 -> PMF_M8_2_c | B16: ='PMF c0 round0'!B16 -> 125 | C16: ='PMF c0 round0'!C16 -> 127 | D16: ='PMF c0 round0'!D16 -> 135 | E16: ='PMF c0 round0'!E16+2 -> 141 | F16: ='PMF c0 round0'!F16+2 -> 145
A17: ='PMF c0 round0'!A17 -> TQITQ_M8 | B17: ='PMF c0 round0'!B17 -> 0 | C17: ='PMF c0 round0'!C17 -> 143 | D17: ='PMF c0 round0'!D17 -> 143 | E17: ='PMF c0 round0'!E17 -> 162 | F17: ='PMF c0 round0'!F17 -> 162
A18: ='PMF c0 round0'!A18 -> INTER_PK8 | B18: ='PMF c0 round0'!B18 -> 0 | C18: ='PMF c0 round0'!C18 -> 162 | D18: ='PMF c0 round0'!D18 -> 163 | E18: ='PMF c0 round0'!E18 -> 164 | F18: ='PMF c0 round0'!F18 -> 165
A19: ='PMF c0 round0'!A19 -> SEL_PK8 | B19: ='PMF c0 round0'!B19 -> 0 | C19: ='PMF c0 round0'!C19 -> 165 | D19: ='PMF c0 round0'!D19 -> 166 | E19: ='PMF c0 round0'!E19 -> 167 | F19: ='PMF c0 round0'!F19 -> 171
A20: ='PMF c0 round0'!A20 -> PMF_M8_3_c | B20: ='PMF c0 round0'!B20 -> 171 | C20: ='PMF c0 round0'!C20 -> 173 | D20: ='PMF c0 round0'!D20 -> 181 | E20: ='PMF c0 round0'!E20+5 -> 190 | F20: ='PMF c0 round0'!F20+5 -> 194
A21: ='PMF c0 round0'!A21 -> TQITQ_F8 | B21: ='PMF c0 round0'!B21 -> 0 | C21: ='PMF c0 round0'!C21 -> 189 | D21: ='PMF c0 round0'!D21 -> 189 | E21: ='PMF c0 round0'!E21 -> 208 | F21: ='PMF c0 round0'!F21 -> 208
A22: ='PMF c0 round0'!A22 -> INTER_PK8 | B22: ='PMF c0 round0'!B22 -> 0 | C22: ='PMF c0 round0'!C22 -> 208 | D22: ='PMF c0 round0'!D22 -> 209 | E22: ='PMF c0 round0'!E22 -> 210 | F22: ='PMF c0 round0'!F22 -> 211
A23: ='PMF c0 round0'!A23 -> SEL_PK8 | B23: ='PMF c0 round0'!B23 -> 0 | C23: ='PMF c0 round0'!C23 -> 211 | D23: ='PMF c0 round0'!D23 -> 212 | E23: ='PMF c0 round0'!E23 -> 213 | F23: ='PMF c0 round0'!F23 -> 217
A24: ='PMF c0 round0'!A24 -> dummy wait | B24: ='PMF c0 round0'!B24 -> 0 | C24: ='PMF c0 round0'!C24 -> 0 | D24: ='PMF c0 round0'!D24 -> 217 | E24: ='PMF c0 round0'!E24 -> 224 | F24: ='PMF c0 round0'!F24 -> 225
A25: ='PMF c0 round0'!A25 -> PMF_M8_1_a | B25: ='PMF c0 round0'!B25 -> 32 | C25: ='PMF c0 round0'!C25 -> 34 | D25: ='PMF c0 round0'!D25 -> 42 | E25: ='PMF c0 round0'!E25+2 -> 48 | F25: ='PMF c0 round0'!F25+2 -> 52
A26: ='PMF c0 round0'!A26 -> PMF_M8_1_b | B26: ='PMF c0 round0'!B26 -> 40 | C26: ='PMF c0 round0'!C26 -> 42 | D26: ='PMF c0 round0'!D26 -> 50 | E26: ='PMF c0 round0'!E26+2 -> 56 | F26: ='PMF c0 round0'!F26+2 -> 60
A27: ='PMF c0 round0'!A27 -> PMF_F8_1 | B27: ='PMF c0 round0'!B27 -> 48 | C27: ='PMF c0 round0'!C27 -> 50 | D27: ='PMF c0 round0'!D27 -> 58 | E27: ='PMF c0 round0'!E27+2 -> 64 | F27: ='PMF c0 round0'!F27+2 -> 68
A28: ='PMF c0 round0'!A28 -> PMF_F8_2 | B28: ='PMF c0 round0'!B28 -> 103 | C28: ='PMF c0 round0'!C28 -> 105 | D28: ='PMF c0 round0'!D28 -> 113 | E28: ='PMF c0 round0'!E28+2 -> 119 | F28: ='PMF c0 round0'!F28+2 -> 123
A29: ='PMF c0 round0'!A29 -> PMF_M8_2_a | B29: ='PMF c0 round0'!B29 -> 87 | C29: ='PMF c0 round0'!C29 -> 89 | D29: ='PMF c0 round0'!D29 -> 97 | E29: ='PMF c0 round0'!E29+2 -> 103 | F29: ='PMF c0 round0'!F29+2 -> 107
A30: ='PMF c0 round0'!A30 -> PMF_M8_2_b | B30: ='PMF c0 round0'!B30 -> 95 | C30: ='PMF c0 round0'!C30 -> 97 | D30: ='PMF c0 round0'!D30 -> 105 | E30: ='PMF c0 round0'!E30+2 -> 111 | F30: ='PMF c0 round0'!F30+2 -> 115
A31: ='PMF c0 round0'!A31 -> PMF_M16_0_c | B31: ='PMF c0 round0'!B31 -> 56 | C31: ='PMF c0 round0'!C31 -> 58 | D31: ='PMF c0 round0'!D31 -> 81 | E31: ='PMF c0 round0'!E31 -> 97 | F31: ='PMF c0 round0'!F31 -> 113
A32: ='PMF c0 round0'!A32 -> PMF_M8_3_a | B32: ='PMF c0 round0'!B32 -> 133 | C32: ='PMF c0 round0'!C32 -> 135 | D32: ='PMF c0 round0'!D32 -> 143 | E32: ='PMF c0 round0'!E32+2 -> 149 | F32: ='PMF c0 round0'!F32+2 -> 153
A33: ='PMF c0 round0'!A33 -> PMF_M8_3_b | B33: ='PMF c0 round0'!B33 -> 141 | C33: ='PMF c0 round0'!C33 -> 143 | D33: ='PMF c0 round0'!D33 -> 151 | E33: ='PMF c0 round0'!E33+2 -> 157 | F33: ='PMF c0 round0'!F33+2 -> 161
A34: ='PMF c0 round0'!A34 -> PMF_F8_3 | B34: ='PMF c0 round0'!B34 -> 149 | C34: ='PMF c0 round0'!C34 -> 151 | D34: ='PMF c0 round0'!D34 -> 159 | E34: ='PMF c0 round0'!E34+2 -> 165 | F34: ='PMF c0 round0'!F34+2 -> 169
A35: ='PMF c0 round0'!A35 -> 0 | B35: ='PMF c0 round0'!B35 -> 0 | C35: ='PMF c0 round0'!C35 -> 0 | D35: ='PMF c0 round0'!D35 -> 0 | E35: ='PMF c0 round0'!E35 -> 0 | F35: ='PMF c0 round0'!F35 -> 0
A36: ='PMF c0 round0'!A36 -> 0 | B36: ='PMF c0 round0'!B36 -> 0 | C36: ='PMF c0 round0'!C36 -> 0 | D36: ='PMF c0 round0'!D36 -> 0 | E36: ='PMF c0 round0'!E36 -> 0 | F36: ='PMF c0 round0'!F36 -> 0
A37: ='PMF c0 round0'!A37 -> 0 | B37: ='PMF c0 round0'!B37 -> 0 | C37: ='PMF c0 round0'!C37 -> 0 | D37: ='PMF c0 round0'!D37 -> 0 | E37: ='PMF c0 round0'!E37 -> 0 | F37: ='PMF c0 round0'!F37 -> 0
A38: ='PMF c0 round0'!A38 -> 0 | B38: ='PMF c0 round0'!B38 -> 0 | C38: ='PMF c0 round0'!C38 -> 0 | D38: ='PMF c0 round0'!D38 -> 0 | E38: ='PMF c0 round0'!E38 -> 0 | F38: ='PMF c0 round0'!F38 -> 0

Sheet PMF sp c0 round1-3
A1: ='PMF c0 round1-3'!A1 -> tile | B1: ='PMF c0 round1-3'!B1 -> PMF C0 Round 1-3 | C1: ='PMF c0 round1-3'!C1 -> 0 | D1: ='PMF c0 round1-3'!D1 -> 0 | E1: ='PMF c0 round1-3'!E1 -> 0 | F1: ='PMF c0 round1-3'!F1 -> 0
A2: ='PMF c0 round1-3'!A2 -> x | B2: ='PMF c0 round1-3'!B2 -> CYCLE | C2: ='PMF c0 round1-3'!C2 -> 0 | D2: ='PMF c0 round1-3'!D2 -> 0 | E2: ='PMF c0 round1-3'!E2 -> 0 | F2: ='PMF c0 round1-3'!F2 -> 0
A3: ='PMF c0 round1-3'!A3 -> y | B3: ='PMF c0 round1-3'!B3 -> MODE | C3: ='PMF c0 round1-3'!C3 -> 0 | D3: ='PMF c0 round1-3'!D3 -> 0 | E3: ='PMF c0 round1-3'!E3 -> 0 | F3: ='PMF c0 round1-3'!F3 -> 0
A4: ='PMF c0 round1-3'!A4 -> mode | B4: ='PMF c0 round1-3'!B4 -> pipe begin | C4: ='PMF c0 round1-3'!C4 -> input begin | D4: ='PMF c0 round1-3'!D4 -> input end | E4: ='PMF c0 round1-3'!E4 -> output begin | F4: ='PMF c0 round1-3'!F4 -> output end
A5: ='PMF c0 round1-3'!A6 -> PMF_M8_0_a | B5: ='PMF c0 round1-3'!B6 -> 202 | C5: ='PMF c0 round1-3'!C6 -> 204 | D5: ='PMF c0 round1-3'!D6 -> 212 | E5: ='PMF c0 round1-3'!E6+2 -> 218 | F5: ='PMF c0 round1-3'!F6+2 -> 222
A6: ='PMF c0 round1-3'!A7 -> PMF_M8_0_b | B6: ='PMF c0 round1-3'!B7 -> 210 | C6: ='PMF c0 round1-3'!C7 -> 212 | D6: ='PMF c0 round1-3'!D7 -> 220 | E6: ='PMF c0 round1-3'!E7+2 -> 226 | F6: ='PMF c0 round1-3'!F7+2 -> 230
A7: ='PMF c0 round1-3'!A8 -> PMF_F8_0 | B7: ='PMF c0 round1-3'!B8 -> 218 | C7: ='PMF c0 round1-3'!C8 -> 220 | D7: ='PMF c0 round1-3'!D8 -> 228 | E7: ='PMF c0 round1-3'!E8+2 -> 234 | F7: ='PMF c0 round1-3'!F8+2 -> 238
A8: ='PMF c0 round1-3'!A9 -> PMF_M8_0_c | B8: ='PMF c0 round1-3'!B9 -> 226 | C8: ='PMF c0 round1-3'!C9 -> 228 | D8: ='PMF c0 round1-3'!D9 -> 236 | E8: ='PMF c0 round1-3'!E9+2 -> 242 | F8: ='PMF c0 round1-3'!F9+2 -> 246
A9: ='PMF c0 round1-3'!A10 -> TQITQ_M8 | B9: ='PMF c0 round1-3'!B10 -> 0 | C9: ='PMF c0 round1-3'!C10 -> 240 | D9: ='PMF c0 round1-3'!D10 -> 240 | E9: ='PMF c0 round1-3'!E10 -> 259 | F9: ='PMF c0 round1-3'!F10 -> 259
A10: ='PMF c0 round1-3'!A11 -> INTER_PK8 | B10: ='PMF c0 round1-3'!B11 -> 0 | C10: ='PMF c0 round1-3'!C11 -> 259 | D10: ='PMF c0 round1-3'!D11 -> 260 | E10: ='PMF c0 round1-3'!E11 -> 261 | F10: ='PMF c0 round1-3'!F11 -> 262
A11: ='PMF c0 round1-3'!A12 -> SEL_PK8 | B11: ='PMF c0 round1-3'!B12 -> 0 | C11: ='PMF c0 round1-3'!C12 -> 262 | D11: ='PMF c0 round1-3'!D12 -> 263 | E11: ='PMF c0 round1-3'!E12 -> 264 | F11: ='PMF c0 round1-3'!F12 -> 268
A12: ='PMF c0 round1-3'!A13 -> PMF_M8_1_c | B12: ='PMF c0 round1-3'!B13 -> 281 | C12: ='PMF c0 round1-3'!C13 -> 283 | D12: ='PMF c0 round1-3'!D13 -> 291 | E12: ='PMF c0 round1-3'!E13+2 -> 297 | F12: ='PMF c0 round1-3'!F13+2 -> 301
A13: ='PMF c0 round1-3'!A14 -> TQITQ_M8 | B13: ='PMF c0 round1-3'!B14 -> 0 | C13: ='PMF c0 round1-3'!C14 -> 295 | D13: ='PMF c0 round1-3'!D14 -> 295 | E13: ='PMF c0 round1-3'!E14 -> 314 | F13: ='PMF c0 round1-3'!F14 -> 314
A14: ='PMF c0 round1-3'!A15 -> INTER_PK8 | B14: ='PMF c0 round1-3'!B15 -> 0 | C14: ='PMF c0 round1-3'!C15 -> 314 | D14: ='PMF c0 round1-3'!D15 -> 315 | E14: ='PMF c0 round1-3'!E15 -> 316 | F14: ='PMF c0 round1-3'!F15 -> 317
A15: ='PMF c0 round1-3'!A16 -> SEL_PK8 | B15: ='PMF c0 round1-3'!B16 -> 0 | C15: ='PMF c0 round1-3'!C16 -> 317 | D15: ='PMF c0 round1-3'!D16 -> 318 | E15: ='PMF c0 round1-3'!E16 -> 319 | F15: ='PMF c0 round1-3'!F16 -> 323
A16: ='PMF c0 round1-3'!A17 -> PMF_M8_2_c | B16: ='PMF c0 round1-3'!B17 -> 323 | C16: ='PMF c0 round1-3'!C17 -> 325 | D16: ='PMF c0 round1-3'!D17 -> 333 | E16: ='PMF c0 round1-3'!E17+1 -> 338 | F16: ='PMF c0 round1-3'!F17+1 -> 342
A17: ='PMF c0 round1-3'!A18 -> TQITQ_M8 | B17: ='PMF c0 round1-3'!B18 -> 0 | C17: ='PMF c0 round1-3'!C18 -> 337 | D17: ='PMF c0 round1-3'!D18 -> 337 | E17: ='PMF c0 round1-3'!E18 -> 356 | F17: ='PMF c0 round1-3'!F18 -> 356
A18: ='PMF c0 round1-3'!A19 -> INTER_PK8 | B18: ='PMF c0 round1-3'!B19 -> 0 | C18: ='PMF c0 round1-3'!C19 -> 356 | D18: ='PMF c0 round1-3'!D19 -> 357 | E18: ='PMF c0 round1-3'!E19 -> 358 | F18: ='PMF c0 round1-3'!F19 -> 359
A19: ='PMF c0 round1-3'!A20 -> SEL_PK8 | B19: ='PMF c0 round1-3'!B20 -> 0 | C19: ='PMF c0 round1-3'!C20 -> 359 | D19: ='PMF c0 round1-3'!D20 -> 360 | E19: ='PMF c0 round1-3'!E20 -> 361 | F19: ='PMF c0 round1-3'!F20 -> 365
A20: ='PMF c0 round1-3'!A21 -> PMF_M8_3_c | B20: ='PMF c0 round1-3'!B21 -> 365 | C20: ='PMF c0 round1-3'!C21 -> 367 | D20: ='PMF c0 round1-3'!D21 -> 375 | E20: ='PMF c0 round1-3'!E21+5 -> 384 | F20: ='PMF c0 round1-3'!F21+5 -> 388
A21: ='PMF c0 round1-3'!A22 -> TQITQ_F8 | B21: ='PMF c0 round1-3'!B22 -> 0 | C21: ='PMF c0 round1-3'!C22 -> 379 | D21: ='PMF c0 round1-3'!D22 -> 379 | E21: ='PMF c0 round1-3'!E22 -> 398 | F21: ='PMF c0 round1-3'!F22 -> 398
A22: ='PMF c0 round1-3'!A23 -> INTER_PK8 | B22: ='PMF c0 round1-3'!B23 -> 0 | C22: ='PMF c0 round1-3'!C23 -> 398 | D22: ='PMF c0 round1-3'!D23 -> 399 | E22: ='PMF c0 round1-3'!E23 -> 400 | F22: ='PMF c0 round1-3'!F23 -> 401
A23: ='PMF c0 round1-3'!A24 -> SEL_PK8 | B23: ='PMF c0 round1-3'!B24 -> 0 | C23: ='PMF c0 round1-3'!C24 -> 401 | D23: ='PMF c0 round1-3'!D24 -> 402 | E23: ='PMF c0 round1-3'!E24 -> 403 | F23: ='PMF c0 round1-3'!F24 -> 407
A24: ='PMF c0 round1-3'!A25 -> PMF_M8_1_a | B24: ='PMF c0 round1-3'!B25 -> 234 | C24: ='PMF c0 round1-3'!C25 -> 236 | D24: ='PMF c0 round1-3'!D25 -> 244 | E24: ='PMF c0 round1-3'!E25+2 -> 250 | F24: ='PMF c0 round1-3'!F25+2 -> 254
A25: ='PMF c0 round1-3'!A26 -> PMF_M8_1_b | B25: ='PMF c0 round1-3'!B26 -> 242 | C25: ='PMF c0 round1-3'!C26 -> 244 | D25: ='PMF c0 round1-3'!D26 -> 252 | E25: ='PMF c0 round1-3'!E26+2 -> 258 | F25: ='PMF c0 round1-3'!F26+2 -> 262
A26: ='PMF c0 round1-3'!A27 -> PMF_F8_1 | B26: ='PMF c0 round1-3'!B27 -> 250 | C26: ='PMF c0 round1-3'!C27 -> 252 | D26: ='PMF c0 round1-3'!D27 -> 260 | E26: ='PMF c0 round1-3'!E27+2 -> 266 | F26: ='PMF c0 round1-3'!F27+2 -> 270
A27: ='PMF c0 round1-3'!A28 -> PMF_F8_2 | B27: ='PMF c0 round1-3'!B28 -> 305 | C27: ='PMF c0 round1-3'!C28 -> 307 | D27: ='PMF c0 round1-3'!D28 -> 315 | E27: ='PMF c0 round1-3'!E28+2 -> 321 | F27: ='PMF c0 round1-3'!F28+2 -> 325
A28: ='PMF c0 round1-3'!A29 -> PMF_M8_2_a | B28: ='PMF c0 round1-3'!B29 -> 289 | C28: ='PMF c0 round1-3'!C29 -> 291 | D28: ='PMF c0 round1-3'!D29 -> 299 | E28: ='PMF c0 round1-3'!E29+2 -> 305 | F28: ='PMF c0 round1-3'!F29+2 -> 309
A29: ='PMF c0 round1-3'!A30 -> PMF_M8_2_b | B29: ='PMF c0 round1-3'!B30 -> 297 | C29: ='PMF c0 round1-3'!C30 -> 299 | D29: ='PMF c0 round1-3'!D30 -> 307 | E29: ='PMF c0 round1-3'!E30+2 -> 313 | F29: ='PMF c0 round1-3'!F30+2 -> 317
A30: ='PMF c0 round1-3'!A31 -> PMF_M16_1_c | B30: ='PMF c0 round1-3'!B31 -> 258 | C30: ='PMF c0 round1-3'!C31 -> 260 | D30: ='PMF c0 round1-3'!D31 -> 283 | E30: ='PMF c0 round1-3'!E31 -> 299 | F30: ='PMF c0 round1-3'!F31 -> 315
A31: ='PMF c0 round1-3'!A32 -> PMF_M8_3_a | B31: ='PMF c0 round1-3'!B32 -> 331 | C31: ='PMF c0 round1-3'!C32 -> 333 | D31: ='PMF c0 round1-3'!D32 -> 341 | E31: ='PMF c0 round1-3'!E32+2 -> 347 | F31: ='PMF c0 round1-3'!F32+2 -> 351
A32: ='PMF c0 round1-3'!A33 -> PMF_M8_3_b | B32: ='PMF c0 round1-3'!B33 -> 339 | C32: ='PMF c0 round1-3'!C33 -> 341 | D32: ='PMF c0 round1-3'!D33 -> 349 | E32: ='PMF c0 round1-3'!E33+2 -> 355 | F32: ='PMF c0 round1-3'!F33+2 -> 359
A33: ='PMF c0 round1-3'!A34 -> PMF_F8_3 | B33: ='PMF c0 round1-3'!B34 -> 347 | C33: ='PMF c0 round1-3'!C34 -> 349 | D33: ='PMF c0 round1-3'!D34 -> 357 | E33: ='PMF c0 round1-3'!E34+2 -> 363 | F33: ='PMF c0 round1-3'!F34+2 -> 367
A34: ='PMF c0 round1-3'!A35 -> 0 | B34: ='PMF c0 round1-3'!B35 -> 0 | C34: ='PMF c0 round1-3'!C35 -> 0 | D34: ='PMF c0 round1-3'!D35 -> 0 | E34: ='PMF c0 round1-3'!E35 -> 0 | F34: ='PMF c0 round1-3'!F35 -> 0
A35: ='PMF c0 round1-3'!A36 -> 0 | B35: ='PMF c0 round1-3'!B36 -> 0 | C35: ='PMF c0 round1-3'!C36 -> 0 | D35: ='PMF c0 round1-3'!D36 -> 0 | E35: ='PMF c0 round1-3'!E36 -> 0 | F35: ='PMF c0 round1-3'!F36 -> 0
A36: ='PMF c0 round1-3'!A37 -> 0 | B36: ='PMF c0 round1-3'!B37 -> 0 | C36: ='PMF c0 round1-3'!C37 -> 0 | D36: ='PMF c0 round1-3'!D37 -> 0 | E36: ='PMF c0 round1-3'!E37 -> 0 | F36: ='PMF c0 round1-3'!F37 -> 0

Sheet PMF c0 round1-3
A1: tile | B1: PMF C0 Round 1-3 | H1: =v0!A76 -> inter pk in | I1: =v0!B76 -> inter pk work | J1: =v0!C76 -> inter pk out | L1: =v0!A78 -> sel pk in | M1: =v0!B78 -> sel pk work | N1: =v0!C78 -> sel pk out | P1: =v0!A84 -> Yread latancy | Q1: =v0!B84 -> 8x8 input cc | R1: =v0!C84 -> 8x8 work cc | S1: =v0!D84 -> 8x8 output cc | U1: =v0!G76 -> tqitq8x8 input | V1: =v0!H76 -> tqitq work | W1: =v0!I76 -> tqitq out | Y1: =v0!A82 -> Yread latancy | Z1: =v0!B82 -> 16x16 input cc | AA1: =v0!C82 -> 16x16 work cc | AB1: =v0!D82 -> 16x16 output cc
A2: x | B2: CYCLE | H2: =v0!A77 -> 1 | I2: =v0!B77 -> 1 | J2: =v0!C77 -> 1 | L2: =v0!A79 -> 1 | M2: =v0!B79 -> 1 | N2: =v0!C79 -> 4 | P2: =v0!A85 -> 2 | Q2: =v0!B85 -> 8 | R2: =v0!C85 -> 4 | S2: =v0!D85 -> 4 | U2: =v0!G77 -> 0 | V2: =v0!H77 -> 19 | W2: =v0!I77 -> 0 | Y2: =v0!A83 -> 2 | Z2: =v0!B83 -> 23 | AA2: =v0!C83 -> -8 | AB2: =v0!D83 -> 16
A3: y | B3: MODE
A4: mode | B4: pipe begin | C4: input begin | D4: input end | E4: output begin | F4: output end
A5: PMF_M16_a | B5: ='PMF c0 round0'!D20-2 -> 179 | C5: =B5+$Y$2 -> 181 | D5: =C5+$Z$2 -> 204 | E5: =D5+$AA$2 -> 196 | F5: =E5+$AB$2 -> 212
A6: PMF_M8_0_a | B6: =D5-2 -> 202 | C6: =B6+$P$2 -> 204 | D6: =C6+$Q$2 -> 212 | E6: =D6+$R$2 -> 216 | F6: =E6+$S$2 -> 220
A7: PMF_M8_0_b | B7: =B6+8 -> 210 | C7: =B7+$P$2 -> 212 | D7: =C7+$Q$2 -> 220 | E7: =D7+$R$2 -> 224 | F7: =E7+$S$2 -> 228
A8: PMF_F8_0 | B8: =B7+8 -> 218 | C8: =B8+$P$2 -> 220 | D8: =C8+$Q$2 -> 228 | E8: =D8+$R$2 -> 232 | F8: =E8+$S$2 -> 236
A9: PMF_M8_0_c | B9: =D8-2 -> 226 | C9: =B9+$P$2 -> 228 | D9: =C9+$Q$2 -> 236 | E9: =D9+$R$2 -> 240 | F9: =E9+$S$2 -> 244
