Workbook

Sheet v0
B1: 块个数 | C1: 单块运行cycle | D1: 流水延迟 | E1: CB CR 块 | F1: 420 | G1: 422 | H1: 模式
A2: 8x8 | B2: 64 | C2: 8 | D2: 6 | E2: 64*2 | F2: 4x4 | G2: 4x8 | H2: FME+ MMVPx1
A3: 16x16 | B3: 16 | C3: 24 | D3: 6 | E3: 16*2 | F3: 8x8 | G3: 8x16 | H3: FME+ MMVPx2
A4: 32x32 | B4: 4 | C4: 78 | D4: 6 | E4: 8*2 | F4: 16x16 | G4: 16x32 | H4: FME+ MMVPx2
A5: 64x64 | B5: 1 | C5: 284 | D5: 6 | E5: 2 | F5: 32x32 | G5: 32x64 | H5: FME+ MMVPx1
A7: 性能需求420：64x64 | B7: 3200
A8: 插值性能估计
A9: Y | B9: 块个数 | C9: 单块运行cycle | D9: 模式个数 | E9: 总计 | G9: Y | H9: y size | I9: 块个数 | J9: 单块运行cycle | K9: 模式个数 | L9: 小计 | M9: 总计 | O9: Y | P9: y size | Q9: 块个数 | R9: 单块运行cycle | S9: 模式个数 | T9: 小计 | U9: 总计
A10: 8x8 | B10: 64 | C10: 8 | D10: 2 | E10: =B10*C10*D10 -> 1024 | G10: 16pixel | H10: 8x8 1F1M | I10: 64 | J10: 8 | K10: 2 | L10: 1024 | M10: 2440 | O10: 16pixel | P10: 8x8 1F3M | Q10: 64 | R10: 8 | S10: 4 | T10: =Q10*R10*S10 -> 2048 | U10: 2784
A11: 16x16 | B11: 16 | C11: 23 | D11: 3 | E11: =B11*C11*D11 -> 1104 | H11: 16x16 1F2M | I11: 16 | J11: 23 | K11: 3 | L11: 1104 | P11: 16x16 2M | Q11: 16 | R11: 23 | S11: 2 | T11: =Q11*R11*S11 -> 736
A12: 32x32 | B12: 4 | C12: 78 | D12: 3 | E12: =B12*C12*D12 -> 936 | H12: 32x32 1F | I12: 4 | J12: 78 | K12: 1 | L12: 312 | O12: 16pixel | P12: 16x16 1F1M | Q12: 16 | R12: 23 | S12: 2 | T12: =Q12*R12*S12 -> 736 | U12: 2608
A13: 64x64(切成4个32x32) | B13: 4 | C13: 78 | D13: 2 | E13: =B13*C13*D13 -> 624 | G13: 8pixel | H13: 32x32 2M | I13: 4 | J13: 156 | K13: 2 | L13: 1248 | M13: 2496 | P13: 32x32 1F3M | Q13: 4 | R13: 78 | S13: 4 | T13: =Q13*R13*S13 -> 1248
E14: 3688 | H14: 64x64 1F1M(切成4个32x32) | I14: 4 | J14: 156 | K14: 2 | L14: 1248 | P14: 64x64 1F1M(切成4个32x32) | Q14: 4 | R14: 78 | S14: 2 | T14: =Q14*R14*S14 -> 624
A16: U(420) | B16: 块个数 | C16: 单块运行cycle(8 pixel) | D16: 模式个数 | G16: UV | H16: uv size | I16: 块个数 | J16: 单块运行cycle | K16: 模式个数 | L16: 小计 | M16: 总计 （U+V） | O16: Y | P16: y size | Q16: 块个数 | R16: 单块运行cycle | S16: 模式个数 | T16: 小计 | U16: 总计
A17: 4x4 (Y8x8) | B17: 64 | C17: 4 | D17: 4 | E17: =B17*C17*D17 -> 1024 | G17: 8pixel | H17: 4x4 | I17: 64 | J17: 4 | K17: 2 | L17: 512 | M17: 2384 | O17: 16pixel | P17: 8x8 1F1M | Q17: 64 | R17: 8 | S17: 2 | T17: =Q17*R17*S17 -> 1024 | U17: 2496
A18: 8x8 (Y16x16) | B18: 16 | C18: 11 | D18: 4 | E18: =B18*C18*D18 -> 704 | H18: 8x8 | I18: 16 | J18: 11 | K18: 3 | L18: 528 | P18: 16x16 1F3M | Q18: 16 | R18: 23 | S18: 4 | T18: =Q18*R18*S18 -> 1472
A19: 16x16 (Y32x32) | B19: 4 | C19: 38 | D19: 4 | E19: =B19*C19*D19 -> 608 | H19: 16x16 F | I19: 4 | J19: 38 | K19: 1 | L19: 152 | T19: =Q19*R19*S19 -> 0
A20: 32x32 (Y64x64) | B20: 1 | C20: 140 | D20: 2 | E20: =B20*C20*D20 -> 280 | G20: 4pixel | H20: 16x16 M | I20: 4 | J20: 76 | K20: 2 | L20: 608 | M20: 2336 | O20: 16pixel | P20: 32x32 1F3M | Q20: 4 | R20: 78 | S20: 4 | T20: =Q20*R20*S20 -> 1248 | U20: 2496
E21: 1800 | H21: 32x32(4x32x8) | I21: 1 | J21: 280 | K21: 2 | L21: 560 | P21: 64x64 1F3M(切成4个32x32) | Q21: 4 | R21: 78 | S21: 4 | T21: =Q21*R21*S21 -> 1248
A23: 块输出到TQITQ 时间
A24: Y | B24: 块个数 | C24: 单块输出时间 | D24: 模式个数 | E24: 总计 | G24: TQITQ输入通道 | H24: Y 耗时 | I24: UV 耗时 | J24: MRG总耗时 | K24: Intra 耗时 | L24: TQITQ 输入耗时 | O24: UV | P24: uv size | Q24: 块个数 | R24: 单块运行cycle | S24: 模式个数 | T24: 小计 | U24: 总计 （U420）
A25: 8x8 | B25: 64 | C25: 4 | D25: 2 | E25: =B25*C25*D25 -> 512 | G25: 8x8 | H25: 512 | I25: 256 | J25: 768 | K25: 768 | L25: 768 | M25: MRG & intra 独立 | O25: 16pixel | P25: 4x4 1F3M | Q25: 64 | R25: 4 | S25: 4 | T25: =Q25*R25*S25 -> 1024 | U25: =T25+T26 -> 1376
A26: 16x16 | B26: 16 | C26: 16 | D26: 2 | E26: =B26*C26*D26 -> 512 | G26: 16x16 | H26: 512 | I26: 256 | J26: 768 | K26: 768 | L26: 1536 | M26: MRG & intra 共享 | P26: 8x8 2M | Q26: 16 | R26: 11 | S26: 2 | T26: =Q26*R26*S26 -> 352
A27: 32x32 | B27: 4 | C27: 64 | D27: 2 | E27: =B27*C27*D27 -> 512 | G27: 32x32 | H27: 1024 | I27: 256 | J27: 1280 | K27: 512 | L27: 1792 | O27: 16pixel | P27: 8x8 1F1M | Q27: 16 | R27: 11 | S27: 2 | T27: =Q27*R27*S27 -> 352 | U27: =T27+T28+T29 -> 1240
A28: 64x64(切成4个32x32) | B28: 4 | C28: 64 | D28: 2 | E28: =B28*C28*D28 -> 512 | G28: 4x4 | H28: 0 | I28: 512 | J28: 512 | K28: 0 | L28: 512 | M28: 待定 | P28: 16x16 1F3M | Q28: 4 | R28: 38 | S28: 4 | T28: =Q28*R28*S28 -> 608
E29: 2048 | P29: 32x32 1F1M(切成4个32x32) | Q29: 1 | R29: 140 | S29: 2 | T29: =Q29*R29*S29 -> 280
A31: U(420) | B31: 块个数 | C31: 单块输出时间 | D31: 模式个数
A32: 4x4 (Y8x8) | B32: 64 | C32: 2 | D32: 2 | E32: =B32*C32*D32 -> 256
A33: 8x8 (Y16x16) | B33: 16 | C33: 4 | D33: 2 | E33: =B33*C33*D33 -> 128
A34: 16x16 (Y32x32) | B34: 4 | C34: 16 | D34: 2 | E34: =B34*C34*D34 -> 128
A35: 32x32 (Y64x64) | B35: 1 | C35: 64 | D35: 2 | E35: =B35*C35*D35 -> 128
E36: 640
A38: PMF output to TQITQ 占用时间
A39: 通道4 | B39: 块数 | C39: 输出时间 | D39: 模式个数 | E39: 时间
A40: uv4x4 | B40: 128 | C40: 1 | D40: 4 | E40: =B40*C40*D40 -> 512
A41: y8x8(切成4个4x4) | B41: 256 | C41: 1 | D41: 4 | E41: =B41*C41*D41 -> 1024
A42: 总计 | E42: =SUM(E40:E41) -> 1536
A44: 通道8
A45: Y8x8 | B45: 64 | C45: 4 | D45: 4 | E45: =B45*C45*D45 -> 1024
A46: UV8x8 | B46: 32 | C46: 4 | D46: 2 | E46: =B46*C46*D46 -> 256
...

Sheet 264PMF Y c0 round0
A1: tile | B1: 264PMF c0 round0 | I1: =v0!K61 -> H264 | J1: =v0!L61 -> 0 | K1: =v0!M61 -> 0 | L1: =v0!N61 -> 0 | M1: =v0!O61 -> 0 | N1: =v0!P61 -> 0 | O1: =v0!Q61 -> 0 | P1: =v0!R61 -> 0
A2: x | B2: CYCLE | I2: =v0!K62 -> inter pk in | J2: =v0!L62 -> inter pk work | K2: =v0!M62 -> inter pk out | L2: =v0!N62 -> 0 | M2: =v0!O62 -> 0 | N2: =v0!P62 -> tqitq16x16 input | O2: =v0!Q62 -> tqitq work | P2: =v0!R62 -> tqitq out
A3: y | B3: MODE | I3: =v0!K63 -> 1 | J3: =v0!L63 -> 1 | K3: =v0!M63 -> 1 | L3: =v0!N63 -> 0 | M3: =v0!O63 -> 0 | N3: =v0!P63 -> 0 | O3: =v0!Q63 -> 29 | P3: =v0!R63 -> 1
A4: mode | B4: pipe begin | C4: input begin | D4: input end | E4: output begin | F4: output end | I4: =v0!K64 -> sel pk in | J4: =v0!L64 -> sel pk work | K4: =v0!M64 -> sel pk out | L4: =v0!N64 -> 0 | M4: =v0!O64 -> 0 | N4: =v0!P64 -> tqitq8x8 input | O4: =v0!Q64 -> tqitq work | P4: =v0!R64 -> tqitq out
A5: PMF_M8_0 | B5: 0 | C5: =B5+I$11 -> 2 | D5: =C5+J$11 -> 9 | E5: =D5+K$11 -> 15 | F5: =E5+L$11 -> 19 | I5: =v0!K65 -> 1 | J5: =v0!L65 -> 1 | K5: =v0!M65 -> 1 | L5: =v0!N65 -> 0 | M5: =v0!O65 -> 0 | N5: =v0!P65 -> 0 | O5: =v0!Q65 -> 18 | P5: =v0!R65 -> 1
A6: PMF_F8_0 | B6: =D5-2 -> 7 | C6: =B6+I$11 -> 9 | D6: =C6+J$11 -> 16 | E6: =D6+K$11 -> 22 | F6: =E6+L$11 -> 26 | I6: =v0!K66 -> Yread latancy | J6: =v0!L66 -> 32x32 input cc | K6: =v0!M66 -> 32x32 work cc | L6: =v0!N66 -> 32x32 output cc | M6: =v0!O66 -> 0 | N6: =v0!P66 -> tqitq4x4 input | O6: =v0!Q66 -> tqitq work | P6: =v0!R66 -> tqitq out
A7: TQITQ_F8 | C7: =F6 -> 26 | D7: =C7+N$5 -> 26 | E7: =D7+O$5 -> 44 | F7: =E7+P$5 -> 45 | I7: =v0!K67 -> 0 | J7: =v0!L67 -> 0 | K7: =v0!M67 -> 0 | L7: =v0!N67 -> 0 | M7: =v0!O67 -> 0 | O7: =v0!Q67 -> 11 | P7: =v0!R67 -> 1
A8: INTER_PK8 | C8: =F7 -> 45 | D8: =C8+I$3 -> 46 | E8: =D8+J$3 -> 47 | F8: =E8+K$3 -> 48 | I8: =v0!K68 -> Yread latancy | J8: =v0!L68 -> 16x16 input cc | K8: =v0!M68 -> 16x16 work cc | L8: =v0!N68 -> 16x16 output cc | M8: =v0!O68 -> 0 | N8: =v0!P68 -> chroma | O8: =v0!Q68 -> 0 | P8: =v0!R68 -> 0
A9: SEL_PK8 | C9: =F8 -> 48 | D9: =C9+I$5 -> 49 | E9: =D9+J$5 -> 50 | F9: =E9+K$5 -> 51 | I9: =v0!K69 -> 2 | J9: =v0!L69 -> 22 | K9: =v0!M69 -> 0 | L9: 24 | M9: =v0!O69 -> 0 | N9: =v0!P69 -> tqitq16x16 input | O9: =v0!Q69 -> tqitq work | P9: =v0!R69 -> tqitq out
A10: PMF_M8_1 | B10: =F9 -> 51 | C10: =B10+I$11 -> 53 | D10: =C10+J$11 -> 60 | E10: =D10+K$11 -> 66 | F10: =E10+L$11 -> 70 | I10: =v0!K70 -> Yread latancy | J10: =v0!L70 -> 8x8 input cc | K10: =v0!M70 -> 8x8 work cc | L10: =v0!N70 -> 8x8 output cc | M10: =v0!O70 -> 0 | N10: =v0!P70 -> 0 | O10: =v0!Q70 -> 0 | P10: =v0!R70 -> 0
A11: TQITQ_M8 | C11: =F10 -> 70 | D11: =C11+N$5 -> 70 | E11: =D11+O$5 -> 88 | F11: =E11+P$5 -> 89 | I11: =v0!K71 -> 2 | J11: =v0!L71 -> 7 | K11: =v0!M71 -> 6 | L11: =v0!N71 -> 4 | M11: =v0!O71 -> 0 | N11: =v0!P71 -> tqitq8x8 input | O11: =v0!Q71 -> tqitq work | P11: =v0!R71 -> tqitq out
A12: INTER_PK8 | C12: =F11 -> 89 | D12: =C12+I$3 -> 90 | E12: =D12+J$3 -> 91 | F12: =E12+K$3 -> 92 | I12: =v0!K72 -> Yread latancy | J12: =v0!L72 -> 4x4 input cc | K12: =v0!M72 -> 4x4 work cc | L12: =v0!N72 -> 4x4 output cc | M12: =v0!O72 -> 0 | N12: =v0!P72 -> 0 | O12: =v0!Q72 -> 0 | P12: =v0!R72 -> 0
A13: SEL_PK8 | C13: =F12 -> 92 | D13: =C13+I$5 -> 93 | E13: =D13+J$5 -> 94 | F13: =E13+K$5 -> 95 | I13: =v0!K73 -> 0 | J13: =v0!L73 -> 0 | K13: =v0!M73 -> 0 | L13: =v0!N73 -> 0 | M13: =v0!O73 -> 0 | N13: =v0!P73 -> tqitq4x4 input | O13: =v0!Q73 -> tqitq work | P13: =v0!R73 -> tqitq out
A14: PMF_M8_2 | B14: =F13 -> 95 | C14: =B14+I$11 -> 97 | D14: =C14+J$11 -> 104 | E14: =D14+K$11 -> 110 | F14: =E14+L$11 -> 114 | I14: =v0!K74 -> UVread latancy | J14: =v0!L74 -> 16x16 input cc | K14: =v0!M74 -> 16x16 work cc | L14: =v0!N74 -> 16x16 output cc | M14: =v0!O74 -> 0 | N14: =v0!P74 -> 0 | O14: =v0!Q74 -> 12 | P14: =v0!R74 -> 1
A15: TQITQ_M8 | C15: =F14 -> 114 | D15: =C15+N$5 -> 114 | E15: =D15+O$5 -> 132 | F15: =E15+P$5 -> 133 | I15: =v0!K75 -> 0 | J15: =v0!L75 -> 0 | K15: =v0!M75 -> 0 | L15: =v0!N75 -> 0 | M15: =v0!O75 -> 0 | N15: =v0!P75 -> 0 | O15: =v0!Q75 -> 0 | P15: =v0!R75 -> 0
A16: INTER_PK8 | C16: =F15 -> 133 | D16: =C16+I$3 -> 134 | E16: =D16+J$3 -> 135 | F16: =E16+K$3 -> 136 | I16: =v0!K76 -> UVread latancy | J16: =v0!L76 -> 8x8 input cc | K16: =v0!M76 -> 8x8 work cc | L16: =v0!N76 -> 8x8 output cc | M16: =v0!O76 -> 0 | N16: =v0!P76 -> 0 | O16: =v0!Q76 -> 0 | P16: =v0!R76 -> 0
A17: SEL_PK8 | C17: =F16 -> 136 | D17: =C17+I$5 -> 137 | E17: =D17+J$5 -> 138 | F17: =E17+K$5 -> 139 | I17: =v0!K77 -> 2 | J17: =v0!L77 -> 16 | K17: =v0!M77 -> 6 | L17: =v0!N77 -> 8 | M17: =v0!O77 -> 0 | N17: =v0!P77 -> 0 | O17: =v0!Q77 -> 0 | P17: =v0!R77 -> 0
A18: PMF_M8_3 | B18: =F17 -> 139 | C18: =B18+I$11 -> 141 | D18: =C18+J$11 -> 148 | E18: =D18+K$11 -> 154 | F18: =E18+L$11 -> 158 | I18: =v0!K78 -> UVread latancy | J18: =v0!L78 -> 4x4 input cc | K18: =v0!M78 -> 4x4 work cc | L18: =v0!N78 -> 4x4 output cc | M18: =v0!O78 -> 0 | N18: =v0!P78 -> 0 | O18: =v0!Q78 -> 0 | P18: =v0!R78 -> 0
A19: TQITQ_M8 | C19: =F18 -> 158 | D19: =C19+N$5 -> 158 | E19: =D19+O$5 -> 176 | F19: =E19+P$5 -> 177 | I19: =v0!K79 -> 2 | J19: =v0!L79 -> 6 | K19: =v0!M79 -> 8 | L19: =v0!N79 -> 2 | M19: =v0!O79 -> 0 | N19: =v0!P79 -> 0 | O19: =v0!Q79 -> 0 | P19: =v0!R79 -> 0
A20: INTER_PK8 | C20: =F19 -> 177 | D20: =C20+I$3 -> 178 | E20: =D20+J$3 -> 179 | F20: =E20+K$3 -> 180 | I20: =v0!K80 -> 0 | J20: =v0!L80 -> 0 | K20: =v0!M80 -> 0 | L20: =v0!N80 -> 0 | M20: =v0!O80 -> 0 | N20: =v0!P80 -> 0 | O20: =v0!Q80 -> 0 | P20: =v0!R80 -> 0
A21: SEL_PK8 | C21: =F20 -> 180 | D21: =C21+I$5 -> 181 | E21: =D21+J$5 -> 182 | F21: =E21+K$5 -> 183 | I21: =v0!K81 -> 0 | J21: =v0!L81 -> 0 | K21: =v0!M81 -> 0 | L21: =v0!N81 -> 0 | M21: =v0!O81 -> 0 | N21: =v0!P81 -> 0 | O21: =v0!Q81 -> 0 | P21: =v0!R81 -> 0
A22: PMF_F8_1 | B22: =B10-J$11 -> 44 | C22: =B22+I$11 -> 46 | D22: =C22+J$11 -> 53 | E22: =D22+K$11 -> 59 | F22: =E22+L$11 -> 63 | I22: =v0!K82 -> 0 | J22: =v0!L82 -> 0 | K22: =v0!M82 -> 0 | L22: =v0!N82 -> 0 | M22: =v0!O82 -> 0 | N22: =v0!P82 -> 0 | O22: =v0!Q82 -> 0 | P22: =v0!R82 -> 0
A23: PMF_F8_2 | B23: =B14-J$11 -> 88 | C23: =B23+I$11 -> 90 | D23: =C23+J$11 -> 97 | E23: =D23+K$11 -> 103 | F23: =E23+L$11 -> 107 | I23: =v0!K83 -> 0 | J23: =v0!L83 -> 0 | K23: =v0!M83 -> 0 | L23: =v0!N83 -> 0 | M23: =v0!O83 -> 0 | N23: =v0!P83 -> 0 | O23: =v0!Q83 -> 0 | P23: =v0!R83 -> 0
A24: PMF_F8_3 | B24: =B18-J$11 -> 132 | C24: =B24+I$11 -> 134 | D24: =C24+J$11 -> 141 | E24: =D24+K$11 -> 147 | F24: =E24+L$11 -> 151 | I24: =v0!K84 -> 0 | J24: =v0!L84 -> 0 | K24: =v0!M84 -> 0 | L24: =v0!N84 -> 0 | M24: =v0!O84 -> 0 | N24: =v0!P84 -> 0 | O24: =v0!Q84 -> 0 | P24: =v0!R84 -> 0
A25: PMF_8M4_0 | E25: =E5+1 -> 16 | F25: =F5+1 -> 20 | I25: =v0!K85 -> 0 | J25: =v0!L85 -> 0 | K25: =v0!M85 -> 0 | L25: =v0!N85 -> 0 | M25: =v0!O85 -> 0 | N25: =v0!P85 -> 0 | O25: =v0!Q85 -> 0 | P25: =v0!R85 -> 0
A26: PMF_8F4_0 | E26: =E6+1 -> 23 | F26: =F6+1 -> 27 | I26: =v0!K86 -> 0 | J26: =v0!L86 -> 0 | K26: =v0!M86 -> 0 | L26: =v0!N86 -> 0 | M26: =v0!O86 -> 0 | N26: =v0!P86 -> 0 | O26: =v0!Q86 -> 0 | P26: =v0!R86 -> 0
A27: PMF_8M4_1 | E27: =E10+1 -> 67 | F27: =F10+1 -> 71
A28: PMF_8F4_1 | E28: =E22+1 -> 60 | F28: =F22+1 -> 64
A29: PMF_8M4_2 | E29: =E14+1 -> 111 | F29: =F14+1 -> 115
A30: PMF_8F4_2 | E30: =E23+1 -> 104 | F30: =F23+1 -> 108
A31: PMF_8M4_3 | E31: =E18+1 -> 155 | F31: =F18+1 -> 159
A32: PMF_8F4_3 | E32: =E24+1 -> 148 | F32: =F24+1 -> 152

Sheet 264PMF Y c1 round0
A1: tile | B1: 264PMF c1 round0 | I1: =v0!K61 -> H264 | J1: =v0!L61 -> 0 | K1: =v0!M61 -> 0 | L1: =v0!N61 -> 0 | M1: =v0!O61 -> 0 | N1: =v0!P61 -> 0 | O1: =v0!Q61 -> 0 | P1: =v0!R61 -> 0
A2: x | B2: CYCLE | I2: =v0!K62 -> inter pk in | J2: =v0!L62 -> inter pk work | K2: =v0!M62 -> inter pk out | L2: =v0!N62 -> 0 | M2: =v0!O62 -> 0 | N2: =v0!P62 -> tqitq16x16 input | O2: =v0!Q62 -> tqitq work | P2: =v0!R62 -> tqitq out
A3: y | B3: MODE | I3: =v0!K63 -> 1 | J3: =v0!L63 -> 1 | K3: =v0!M63 -> 1 | L3: =v0!N63 -> 0 | M3: =v0!O63 -> 0 | N3: =v0!P63 -> 0 | O3: =v0!Q63 -> 29 | P3: =v0!R63 -> 1
A4: mode | B4: pipe begin | C4: input begin | D4: input end | E4: output begin | F4: output end | I4: =v0!K64 -> sel pk in | J4: =v0!L64 -> sel pk work | K4: =v0!M64 -> sel pk out | L4: =v0!N64 -> 0 | M4: =v0!O64 -> 0 | N4: =v0!P64 -> tqitq8x8 input | O4: =v0!Q64 -> tqitq work | P4: =v0!R64 -> tqitq out
A5: PMF_M16 | B5: 4 | C5: =B5+I9 -> 6 | D5: =C5+J9 -> 28 | E5: =D5+K9+2 -> 30 | I5: =v0!K65 -> 1 | J5: =v0!L65 -> 1 | K5: =v0!M65 -> 1 | L5: =v0!N65 -> 0 | M5: =v0!O65 -> 0 | N5: =v0!P65 -> 0 | O5: =v0!Q65 -> 18 | P5: =v0!R65 -> 1
A6: PMF_F16 | B6: =D5-2+20 -> 46 | C6: =B6+I9 -> 48 | D6: =C6+J9 -> 70 | E6: =D6+K9 -> 70 | I6: =v0!K66 -> Yread latancy | J6: =v0!L66 -> 32x32 input cc | K6: =v0!M66 -> 32x32 work cc | L6: =v0!N66 -> 32x32 output cc | M6: =v0!O66 -> 0 | N6: =v0!P66 -> tqitq4x4 input | O6: =v0!Q66 -> tqitq work | P6: =v0!R66 -> tqitq out
A7: PMF_16M8_0 | E7: =E5 -> 30 | F7: =E7+L$11 -> 34 | I7: =v0!K67 -> 0 | J7: =v0!L67 -> 0 | K7: =v0!M67 -> 0 | L7: =v0!N67 -> 0 | M7: =v0!O67 -> 0 | N7: =v0!P67 -> 0 | O7: =v0!Q67 -> 11 | P7: =v0!R67 -> 1
A8: PMF_16M8_1 | E8: =F7 -> 34 | F8: =E8+L$11 -> 38 | I8: =v0!K68 -> Yread latancy | J8: =v0!L68 -> 16x16 input cc | K8: =v0!M68 -> 16x16 work cc | L8: =v0!N68 -> 16x16 output cc | M8: =v0!O68 -> 0 | N8: =v0!P68 -> chroma | O8: =v0!Q68 -> 0 | P8: =v0!R68 -> 0
A9: PMF_16M8_2 | E9: =F8 -> 38 | F9: =E9+L$11 -> 42 | I9: =v0!K69 -> 2 | J9: =v0!L69 -> 22 | K9: =v0!M69 -> 0 | L9: =v0!N69 -> 20 | M9: =v0!O69 -> 0 | N9: =v0!P69 -> tqitq16x16 input | O9: =v0!Q69 -> tqitq work | P9: =v0!R69 -> tqitq out
A10: PMF_16M8_3 | E10: =F9 -> 42 | F10: =E10+L$11+4 -> 50 | I10: =v0!K70 -> Yread latancy | J10: =v0!L70 -> 8x8 input cc | K10: =v0!M70 -> 8x8 work cc | L10: =v0!N70 -> 8x8 output cc | M10: =v0!O70 -> 0 | N10: =v0!P70 -> 0 | O10: =v0!Q70 -> 0 | P10: =v0!R70 -> 0
A11: PMF_16F8_0 | E11: =E6 -> 70 | F11: =E11+L$11 -> 74 | I11: =v0!K71 -> 2 | J11: =v0!L71 -> 7 | K11: =v0!M71 -> 6 | L11: =v0!N71 -> 4 | M11: =v0!O71 -> 0 | N11: =v0!P71 -> tqitq8x8 input | O11: =v0!Q71 -> tqitq work | P11: =v0!R71 -> tqitq out
A12: PMF_16F8_1 | E12: =F11 -> 74 | F12: =E12+L$11 -> 78 | I12: =v0!K72 -> Yread latancy | J12: =v0!L72 -> 4x4 input cc | K12: =v0!M72 -> 4x4 work cc | L12: =v0!N72 -> 4x4 output cc | M12: =v0!O72 -> 0 | N12: =v0!P72 -> 0 | O12: =v0!Q72 -> 0 | P12: =v0!R72 -> 0
A13: PMF_16F8_2 | E13: =F12 -> 78 | F13: =E13+L$11 -> 82 | I13: =v0!K73 -> 0 | J13: =v0!L73 -> 0 | K13: =v0!M73 -> 0 | L13: =v0!N73 -> 0 | M13: =v0!O73 -> 0 | N13: =v0!P73 -> tqitq4x4 input | O13: =v0!Q73 -> tqitq work | P13: =v0!R73 -> tqitq out
A14: PMF_16F8_3 | E14: =F13 -> 82 | F14: =E14+L$11+4 -> 90 | I14: =v0!K74 -> UVread latancy | J14: =v0!L74 -> 16x16 input cc | K14: =v0!M74 -> 16x16 work cc | L14: =v0!N74 -> 16x16 output cc | M14: =v0!O74 -> 0 | N14: =v0!P74 -> 0 | O14: =v0!Q74 -> 12 | P14: =v0!R74 -> 1
A15: PMF_16M4_0 | E15: =E7+1 -> 31 | F15: =F7+1 -> 35 | I15: =v0!K75 -> 0 | J15: =v0!L75 -> 0 | K15: =v0!M75 -> 0 | L15: =v0!N75 -> 0 | M15: =v0!O75 -> 0 | N15: =v0!P75 -> 0 | O15: =v0!Q75 -> 0 | P15: =v0!R75 -> 0
A16: PMF_16M4_1 | E16: =E8+1 -> 35 | F16: =F8+1 -> 39 | I16: =v0!K76 -> UVread latancy | J16: =v0!L76 -> 8x8 input cc | K16: =v0!M76 -> 8x8 work cc | L16: =v0!N76 -> 8x8 output cc | M16: =v0!O76 -> 0 | N16: =v0!P76 -> 0 | O16: =v0!Q76 -> 0 | P16: =v0!R76 -> 0
A17: PMF_16M4_2 | E17: =E9+1 -> 39 | F17: =F9+1 -> 43 | I17: =v0!K77 -> 2 | J17: =v0!L77 -> 16 | K17: =v0!M77 -> 6 | L17: =v0!N77 -> 8 | M17: =v0!O77 -> 0 | N17: =v0!P77 -> 0 | O17: =v0!Q77 -> 0 | P17: =v0!R77 -> 0
A18: PMF_16M4_3 | E18: =E10+1 -> 43 | F18: =F10+1 -> 51 | I18: =v0!K78 -> UVread latancy | J18: =v0!L78 -> 4x4 input cc | K18: =v0!M78 -> 4x4 work cc | L18: =v0!N78 -> 4x4 output cc | M18: =v0!O78 -> 0 | N18: =v0!P78 -> 0 | O18: =v0!Q78 -> 0 | P18: =v0!R78 -> 0
A19: PMF_16F4_0 | E19: =E11+1 -> 71 | F19: =F11+1 -> 75 | I19: =v0!K79 -> 2 | J19: =v0!L79 -> 6 | K19: =v0!M79 -> 8 | L19: =v0!N79 -> 2 | M19: =v0!O79 -> 0 | N19: =v0!P79 -> 0 | O19: =v0!Q79 -> 0 | P19: =v0!R79 -> 0
A20: PMF_16F4_1 | E20: =E12+1 -> 75 | F20: =F12+1 -> 79 | I20: =v0!K80 -> 0 | J20: =v0!L80 -> 0 | K20: =v0!M80 -> 0 | L20: =v0!N80 -> 0 | M20: =v0!O80 -> 0 | N20: =v0!P80 -> 0 | O20: =v0!Q80 -> 0 | P20: =v0!R80 -> 0
A21: PMF_16F4_2 | E21: =E13+1 -> 79 | F21: =F13+1 -> 83 | I21: =v0!K81 -> 0 | J21: =v0!L81 -> 0 | K21: =v0!M81 -> 0 | L21: =v0!N81 -> 0 | M21: =v0!O81 -> 0 | N21: =v0!P81 -> 0 | O21: =v0!Q81 -> 0 | P21: =v0!R81 -> 0
A22: PMF_16F4_3 | E22: =E14+1 -> 83 | F22: =F14+1 -> 91 | I22: =v0!K82 -> 0 | J22: =v0!L82 -> 0 | K22: =v0!M82 -> 0 | L22: =v0!N82 -> 0 | M22: =v0!O82 -> 0 | N22: =v0!P82 -> 0 | O22: =v0!Q82 -> 0 | P22: =v0!R82 -> 0
I23: =v0!K83 -> 0 | J23: =v0!L83 -> 0 | K23: =v0!M83 -> 0 | L23: =v0!N83 -> 0 | M23: =v0!O83 -> 0 | N23: =v0!P83 -> 0 | O23: =v0!Q83 -> 0 | P23: =v0!R83 -> 0
I24: =v0!K84 -> 0 | J24: =v0!L84 -> 0 | K24: =v0!M84 -> 0 | L24: =v0!N84 -> 0 | M24: =v0!O84 -> 0 | N24: =v0!P84 -> 0 | O24: =v0!Q84 -> 0 | P24: =v0!R84 -> 0
I25: =v0!K85 -> 0 | J25: =v0!L85 -> 0 | K25: =v0!M85 -> 0 | L25: =v0!N85 -> 0 | M25: =v0!O85 -> 0 | N25: =v0!P85 -> 0 | O25: =v0!Q85 -> 0 | P25: =v0!R85 -> 0
I26: =v0!K86 -> 0 | J26: =v0!L86 -> 0 | K26: =v0!M86 -> 0 | L26: =v0!N86 -> 0 | M26: =v0!O86 -> 0 | N26: =v0!P86 -> 0 | O26: =v0!Q86 -> 0 | P26: =v0!R86 -> 0

Sheet 264PMF UV c0 round0
A1: tile | B1: 264PMF UV c0 round0 | I1: =v0!K61 -> H264 | J1: =v0!L61 -> 0 | K1: =v0!M61 -> 0 | L1: =v0!N61 -> 0 | M1: =v0!O61 -> 0 | N1: =v0!P61 -> 0 | O1: =v0!Q61 -> 0 | P1: =v0!R61 -> 0
A2: x | B2: CYCLE | I2: =v0!K62 -> inter pk in | J2: =v0!L62 -> inter pk work | K2: =v0!M62 -> inter pk out | L2: =v0!N62 -> 0 | M2: =v0!O62 -> 0 | N2: =v0!P62 -> tqitq16x16 input | O2: =v0!Q62 -> tqitq work | P2: =v0!R62 -> tqitq out
A3: y | B3: MODE | I3: =v0!K63 -> 1 | J3: =v0!L63 -> 1 | K3: =v0!M63 -> 1 | L3: =v0!N63 -> 0 | M3: =v0!O63 -> 0 | N3: =v0!P63 -> 0 | O3: =v0!Q63 -> 29 | P3: =v0!R63 -> 1
A4: mode | B4: pipe begin | C4: input begin | D4: input end | E4: output begin | F4: output end | I4: =v0!K64 -> sel pk in | J4: =v0!L64 -> sel pk work | K4: =v0!M64 -> sel pk out | L4: =v0!N64 -> 0 | M4: =v0!O64 -> 0 | N4: =v0!P64 -> tqitq8x8 input | O4: =v0!Q64 -> tqitq work | P4: =v0!R64 -> tqitq out
A5: PMF_M4_0 | B5: 0 | C5: =B5+I$19 -> 2 | D5: =C5+J$19 -> 8 | E5: =D5+K$19 -> 16 | F5: =E5+L$19 -> 18 | I5: =v0!K65 -> 1 | J5: =v0!L65 -> 1 | K5: =v0!M65 -> 1 | L5: =v0!N65 -> 0 | M5: =v0!O65 -> 0 | N5: =v0!P65 -> 0 | O5: =v0!Q65 -> 18 | P5: =v0!R65 -> 1
A6: PMF_F4_0 | B6: =D5-2 -> 6 | C6: =B6+I$19 -> 8 | D6: =C6+J$19 -> 14 | E6: =D6+K$19 -> 22 | F6: =E6+L$19 -> 24 | I6: =v0!K66 -> Yread latancy | J6: =v0!L66 -> 32x32 input cc | K6: =v0!M66 -> 32x32 work cc | L6: =v0!N66 -> 32x32 output cc | M6: =v0!O66 -> 0 | N6: =v0!P66 -> tqitq4x4 input | O6: =v0!Q66 -> tqitq work | P6: =v0!R66 -> tqitq out
A7: TQITQ_F4 | C7: =F6 -> 24 | D7: =C7+N$14 -> 24 | E7: =D7+O$14 -> 36 | F7: =E7+P$14 -> 37 | I7: =v0!K67 -> 0 | J7: =v0!L67 -> 0 | K7: =v0!M67 -> 0 | L7: =v0!N67 -> 0 | M7: =v0!O67 -> 0 | N7: 0 | O7: =v0!Q67 -> 11 | P7: =v0!R67 -> 1
A8: INTER_PK4 | C8: =F7 -> 37 | D8: =C8+I$3 -> 38 | E8: =D8+J$3 -> 39 | F8: =E8+K$3 -> 40 | I8: =v0!K68 -> Yread latancy | J8: =v0!L68 -> 16x16 input cc | K8: =v0!M68 -> 16x16 work cc | L8: =v0!N68 -> 16x16 output cc | M8: =v0!O68 -> 0 | N8: =v0!P68 -> chroma | O8: =v0!Q68 -> 0 | P8: =v0!R68 -> 0
A9: SEL_PK4 | C9: =F8 -> 40 | D9: =C9+I$5 -> 41 | E9: =D9+J$5 -> 42 | F9: =E9+K$5 -> 43 | I9: =v0!K69 -> 2 | J9: =v0!L69 -> 22 | K9: =v0!M69 -> 0 | L9: 24 | M9: =v0!O69 -> 0 | N9: =v0!P69 -> tqitq16x16 input | O9: =v0!Q69 -> tqitq work | P9: =v0!R69 -> tqitq out
A10: PMF_M4_1 | B10: ='264PMF Y c0 round0'!B10 -> 51 | C10: =B10+I$19 -> 53 | D10: =C10+J$19 -> 59 | E10: =D10+K$19 -> 67 | F10: =E10+L$19 -> 69 | I10: =v0!K70 -> Yread latancy | J10: =v0!L70 -> 8x8 input cc | K10: =v0!M70 -> 8x8 work cc | L10: =v0!N70 -> 8x8 output cc | M10: =v0!O70 -> 0 | N10: =v0!P70 -> 0 | O10: =v0!Q70 -> 0 | P10: =v0!R70 -> 0
A11: TQITQ_M4 | C11: =F10 -> 69 | D11: =C11+N$14 -> 69 | E11: =D11+O$14 -> 81 | F11: =E11+P$14 -> 82 | I11: =v0!K71 -> 2 | J11: =v0!L71 -> 7 | K11: =v0!M71 -> 6 | L11: =v0!N71 -> 4 | M11: =v0!O71 -> 0 | N11: =v0!P71 -> tqitq8x8 input | O11: =v0!Q71 -> tqitq work | P11: =v0!R71 -> tqitq out
A12: INTER_PK4 | C12: =F11 -> 82 | D12: =C12+I$3 -> 83 | E12: =D12+J$3 -> 84 | F12: =E12+K$3 -> 85 | I12: =v0!K72 -> Yread latancy | J12: =v0!L72 -> 4x4 input cc | K12: =v0!M72 -> 4x4 work cc | L12: =v0!N72 -> 4x4 output cc | M12: =v0!O72 -> 0 | N12: =v0!P72 -> 0 | O12: =v0!Q72 -> 0 | P12: =v0!R72 -> 0
A13: SEL_PK4 | C13: =F12 -> 85 | D13: =C13+I$5 -> 86 | E13: =D13+J$5 -> 87 | F13: =E13+K$5 -> 88 | I13: =v0!K73 -> 0 | J13: =v0!L73 -> 0 | K13: =v0!M73 -> 0 | L13: =v0!N73 -> 0 | M13: =v0!O73 -> 0 | N13: =v0!P73 -> tqitq4x4 input | O13: =v0!Q73 -> tqitq work | P13: =v0!R73 -> tqitq out
A14: PMF_M4_2 | B14: ='264PMF Y c0 round0'!B14 -> 95 | C14: =B14+I$19 -> 97 | D14: =C14+J$19 -> 103 | E14: =D14+K$19 -> 111 | F14: =E14+L$19 -> 113 | I14: =v0!K74 -> UVread latancy | J14: =v0!L74 -> 16x16 input cc | K14: =v0!M74 -> 16x16 work cc | L14: =v0!N74 -> 16x16 output cc | M14: =v0!O74 -> 0 | N14: =v0!P74 -> 0 | O14: =v0!Q74 -> 12 | P14: =v0!R74 -> 1
A15: TQITQ_M4 | C15: =F14 -> 113 | D15: =C15+N$14 -> 113 | E15: =D15+O$14 -> 125 | F15: =E15+P$14 -> 126 | I15: =v0!K75 -> 0 | J15: =v0!L75 -> 0 | K15: =v0!M75 -> 0 | L15: =v0!N75 -> 0 | M15: =v0!O75 -> 0 | N15: =v0!P75 -> 0 | O15: =v0!Q75 -> 0 | P15: =v0!R75 -> 0
A16: INTER_PK4 | C16: =F15 -> 126 | D16: =C16+I$3 -> 127 | E16: =D16+J$3 -> 128 | F16: =E16+K$3 -> 129 | I16: =v0!K76 -> UVread latancy | J16: =v0!L76 -> 8x8 input cc | K16: =v0!M76 -> 8x8 work cc | L16: =v0!N76 -> 8x8 output cc | M16: =v0!O76 -> 0 | N16: =v0!P76 -> 0 | O16: =v0!Q76 -> 0 | P16: =v0!R76 -> 0
A17: SEL_PK4 | C17: =F16 -> 129 | D17: =C17+I$5 -> 130 | E17: =D17+J$5 -> 131 | F17: =E17+K$5 -> 132 | I17: =v0!K77 -> 2 | J17: =v0!L77 -> 16 | K17: =v0!M77 -> 6 | L17: =v0!N77 -> 8 | M17: =v0!O77 -> 0 | N17: =v0!P77 -> 0 | O17: =v0!Q77 -> 0 | P17: =v0!R77 -> 0
A18: PMF_M4_3 | B18: ='264PMF Y c0 round0'!B18 -> 139 | C18: =B18+I$19 -> 141 | D18: =C18+J$19 -> 147 | E18: =D18+K$19 -> 155 | F18: =E18+L$19 -> 157 | I18: =v0!K78 -> UVread latancy | J18: =v0!L78 -> 4x4 input cc | K18: =v0!M78 -> 4x4 work cc | L18: =v0!N78 -> 4x4 output cc | M18: =v0!O78 -> 0 | N18: =v0!P78 -> 0 | O18: =v0!Q78 -> 0 | P18: =v0!R78 -> 0
A19: TQITQ_M4 | C19: =F18 -> 157 | D19: =C19+N$14 -> 157 | E19: =D19+O$14 -> 169 | F19: =E19+P$14 -> 170 | I19: =v0!K79 -> 2 | J19: =v0!L79 -> 6 | K19: =v0!M79 -> 8 | L19: =v0!N79 -> 2 | M19: =v0!O79 -> 0 | N19: =v0!P79 -> 0 | O19: =v0!Q79 -> 0 | P19: =v0!R79 -> 0
A20: INTER_PK4 | C20: =F19 -> 170 | D20: =C20+I$3 -> 171 | E20: =D20+J$3 -> 172 | F20: =E20+K$3 -> 173 | I20: =v0!K80 -> 0 | J20: =v0!L80 -> 0 | K20: =v0!M80 -> 0 | L20: =v0!N80 -> 0 | M20: =v0!O80 -> 0 | N20: =v0!P80 -> 0 | O20: =v0!Q80 -> 0 | P20: =v0!R80 -> 0
A21: SEL_PK4 | C21: =F20 -> 173 | D21: =C21+I$5 -> 174 | E21: =D21+J$5 -> 175 | F21: =E21+K$5 -> 176 | I21: =v0!K81 -> 0 | J21: =v0!L81 -> 0 | K21: =v0!M81 -> 0 | L21: =v0!N81 -> 0 | M21: =v0!O81 -> 0 | N21: =v0!P81 -> 0 | O21: =v0!Q81 -> 0 | P21: =v0!R81 -> 0
A22: PMF_F4_1 | B22: =D6-2 -> 12 | C22: =B22+I$19 -> 14 | D22: =C22+J$19 -> 20 | E22: =D22+K$19 -> 28 | F22: =E22+L$19 -> 30 | I22: =v0!K82 -> 0 | J22: =v0!L82 -> 0 | K22: =v0!M82 -> 0 | L22: =v0!N82 -> 0 | M22: =v0!O82 -> 0 | N22: =v0!P82 -> 0 | O22: =v0!Q82 -> 0 | P22: =v0!R82 -> 0
A23: PMF_F4_2 | B23: =B14-J19 -> 89 | C23: =B23+I$19 -> 91 | D23: =C23+J$19 -> 97 | E23: =D23+K$19 -> 105 | F23: =E23+L$19 -> 107 | I23: =v0!K83 -> 0 | J23: =v0!L83 -> 0 | K23: =v0!M83 -> 0 | L23: =v0!N83 -> 0 | M23: =v0!O83 -> 0 | N23: =v0!P83 -> 0 | O23: =v0!Q83 -> 0 | P23: =v0!R83 -> 0
A24: PMF_F4_3 | B24: =B18-J19 -> 133 | C24: =B24+I$19 -> 135 | D24: =C24+J$19 -> 141 | E24: =D24+K$19 -> 149 | F24: =E24+L$19 -> 151 | I24: =v0!K84 -> 0 | J24: =v0!L84 -> 0 | K24: =v0!M84 -> 0 | L24: =v0!N84 -> 0 | M24: =v0!O84 -> 0 | N24: =v0!P84 -> 0 | O24: =v0!Q84 -> 0 | P24: =v0!R84 -> 0
I25: =v0!K85 -> 0 | J25: =v0!L85 -> 0 | K25: =v0!M85 -> 0 | L25: =v0!N85 -> 0 | M25: =v0!O85 -> 0 | N25: =v0!P85 -> 0 | O25: =v0!Q85 -> 0 | P25: =v0!R85 -> 0
I26: =v0!K86 -> 0 | J26: =v0!L86 -> 0 | K26: =v0!M86 -> 0 | L26: =v0!N86 -> 0 | M26: =v0!O86 -> 0 | N26: =v0!P86 -> 0 | O26: =v0!Q86 -> 0 | P26: =v0!R86 -> 0

Sheet 264PMF UV c1 round0
A1: tile | B1: 264PMF UV c1 round0 | I1: =v0!K61 -> H264 | J1: =v0!L61 -> 0 | K1: =v0!M61 -> 0 | L1: =v0!N61 -> 0 | M1: =v0!O61 -> 0 | N1: =v0!P61 -> 0 | O1: =v0!Q61 -> 0 | P1: =v0!R61 -> 0
A2: x | B2: CYCLE | I2: =v0!K62 -> inter pk in | J2: =v0!L62 -> inter pk work | K2: =v0!M62 -> inter pk out | L2: =v0!N62 -> 0 | M2: =v0!O62 -> 0 | N2: =v0!P62 -> tqitq16x16 input | O2: =v0!Q62 -> tqitq work | P2: =v0!R62 -> tqitq out
A3: y | B3: MODE | I3: =v0!K63 -> 1 | J3: =v0!L63 -> 1 | K3: =v0!M63 -> 1 | L3: =v0!N63 -> 0 | M3: =v0!O63 -> 0 | N3: =v0!P63 -> 0 | O3: =v0!Q63 -> 29 | P3: =v0!R63 -> 1
A4: mode | B4: pipe begin | C4: input begin | D4: input end | E4: output begin | F4: output end | I4: =v0!K64 -> sel pk in | J4: =v0!L64 -> sel pk work | K4: =v0!M64 -> sel pk out | L4: =v0!N64 -> 0 | M4: =v0!O64 -> 0 | N4: =v0!P64 -> tqitq8x8 input | O4: =v0!Q64 -> tqitq work | P4: =v0!R64 -> tqitq out
A5: PMF_M8 | B5: 0 | C5: =B5+I17 -> 2 | D5: =C5+J17 -> 20 | E5: =D5+K17+4 -> 30 | I5: =v0!K65 -> 1 | J5: =v0!L65 -> 1 | K5: =v0!M65 -> 1 | L5: =v0!N65 -> 0 | M5: =v0!O65 -> 0 | N5: =v0!P65 -> 0 | O5: =v0!Q65 -> 18 | P5: =v0!R65 -> 1
A6: PMF_F8 | B6: =D5-2 -> 18 | C6: =B6+I17 -> 20 | D6: =C6+J17 -> 38 | E6: =D6+K17 -> 44 | I6: =v0!K66 -> Yread latancy | J6: =v0!L66 -> 32x32 input cc | K6: =v0!M66 -> 32x32 work cc | L6: =v0!N66 -> 32x32 output cc | M6: =v0!O66 -> 0 | N6: =v0!P66 -> tqitq4x4 input | O6: =v0!Q66 -> tqitq work | P6: =v0!R66 -> tqitq out
A7: PMF_8M4_0 | E7: =E5+1 -> 31 | F7: =E7+2 -> 33 | I7: =v0!K67 -> 0 | J7: =v0!L67 -> 0 | K7: =v0!M67 -> 0 | L7: =v0!N67 -> 0 | M7: =v0!O67 -> 0 | N7: =v0!P67 -> 0 | O7: =v0!Q67 -> 11 | P7: =v0!R67 -> 1
A8: PMF_8M4_1 | E8: =F7 -> 33 | F8: =E8+2 -> 35 | I8: =v0!K68 -> Yread latancy | J8: =v0!L68 -> 16x16 input cc | K8: =v0!M68 -> 16x16 work cc | L8: =v0!N68 -> 16x16 output cc | M8: =v0!O68 -> 0 | N8: =v0!P68 -> chroma | O8: =v0!Q68 -> 0 | P8: =v0!R68 -> 0
A9: PMF_8M4_2 | E9: =F8 -> 35 | F9: =E9+2 -> 37 | I9: =v0!K69 -> 2 | J9: =v0!L69 -> 22 | K9: =v0!M69 -> 0 | L9: 24 | M9: =v0!O69 -> 0 | N9: =v0!P69 -> tqitq16x16 input | O9: =v0!Q69 -> tqitq work | P9: =v0!R69 -> tqitq out
A10: PMF_8M4_3 | E10: =F9 -> 37 | F10: =E10+4 -> 41 | I10: =v0!K70 -> Yread latancy | J10: =v0!L70 -> 8x8 input cc | K10: =v0!M70 -> 8x8 work cc | L10: =v0!N70 -> 8x8 output cc | M10: =v0!O70 -> 0 | N10: =v0!P70 -> 0 | O10: =v0!Q70 -> 0 | P10: =v0!R70 -> 0
A11: PMF_8F4_0 | E11: =E6+1 -> 45 | F11: =E11+2 -> 47 | I11: =v0!K71 -> 2 | J11: =v0!L71 -> 7 | K11: =v0!M71 -> 6 | L11: =v0!N71 -> 4 | M11: =v0!O71 -> 0 | N11: =v0!P71 -> tqitq8x8 input | O11: =v0!Q71 -> tqitq work | P11: =v0!R71 -> tqitq out
A12: PMF_8F4_1 | E12: =F11 -> 47 | F12: =E12+2 -> 49 | I12: =v0!K72 -> Yread latancy | J12: =v0!L72 -> 4x4 input cc | K12: =v0!M72 -> 4x4 work cc | L12: =v0!N72 -> 4x4 output cc | M12: =v0!O72 -> 0 | N12: =v0!P72 -> 0 | O12: =v0!Q72 -> 0 | P12: =v0!R72 -> 0
A13: PMF_8F4_2 | E13: =F12 -> 49 | F13: =E13+2 -> 51 | I13: =v0!K73 -> 0 | J13: =v0!L73 -> 0 | K13: =v0!M73 -> 0 | L13: =v0!N73 -> 0 | M13: =v0!O73 -> 0 | N13: =v0!P73 -> tqitq4x4 input | O13: =v0!Q73 -> tqitq work | P13: =v0!R73 -> tqitq out
A14: PMF_8F4_3 | E14: =F13 -> 51 | F14: =E14+4 -> 55 | I14: =v0!K74 -> UVread latancy | J14: =v0!L74 -> 16x16 input cc | K14: =v0!M74 -> 16x16 work cc | L14: =v0!N74 -> 16x16 output cc | M14: =v0!O74 -> 0 | N14: =v0!P74 -> 0 | O14: =v0!Q74 -> 12 | P14: =v0!R74 -> 1
I15: =v0!K75 -> 0 | J15: =v0!L75 -> 0 | K15: =v0!M75 -> 0 | L15: =v0!N75 -> 0 | M15: =v0!O75 -> 0 | N15: =v0!P75 -> 0 | O15: =v0!Q75 -> 0 | P15: =v0!R75 -> 0
I16: =v0!K76 -> UVread latancy | J16: =v0!L76 -> 8x8 input cc | K16: =v0!M76 -> 8x8 work cc | L16: =v0!N76 -> 8x8 output cc | M16: =v0!O76 -> 0 | N16: =v0!P76 -> 0 | O16: =v0!Q76 -> 0 | P16: =v0!R76 -> 0
I17: =v0!K77 -> 2 | J17: 18 | K17: =v0!M77 -> 6 | L17: =v0!N77 -> 8 | M17: =v0!O77 -> 0 | N17: =v0!P77 -> 0 | O17: =v0!Q77 -> 0 | P17: =v0!R77 -> 0
I18: =v0!K78 -> UVread latancy | J18: =v0!L78 -> 4x4 input cc | K18: =v0!M78 -> 4x4 work cc | L18: =v0!N78 -> 4x4 output cc | M18: =v0!O78 -> 0 | N18: =v0!P78 -> 0 | O18: =v0!Q78 -> 0 | P18: =v0!R78 -> 0
I19: =v0!K79 -> 2 | J19: =v0!L79 -> 6 | K19: =v0!M79 -> 8 | L19: =v0!N79 -> 2 | M19: =v0!O79 -> 0 | N19: =v0!P79 -> 0 | O19: =v0!Q79 -> 0 | P19: =v0!R79 -> 0
I20: =v0!K80 -> 0 | J20: =v0!L80 -> 0 | K20: =v0!M80 -> 0 | L20: =v0!N80 -> 0 | M20: =v0!O80 -> 0 | N20: =v0!P80 -> 0 | O20: =v0!Q80 -> 0 | P20: =v0!R80 -> 0
I21: =v0!K81 -> 0 | J21: =v0!L81 -> 0 | K21: =v0!M81 -> 0 | L21: =v0!N81 -> 0 | M21: =v0!O81 -> 0 | N21: =v0!P81 -> 0 | O21: =v0!Q81 -> 0 | P21: =v0!R81 -> 0
I22: =v0!K82 -> 0 | J22: =v0!L82 -> 0 | K22: =v0!M82 -> 0 | L22: =v0!N82 -> 0 | M22: =v0!O82 -> 0 | N22: =v0!P82 -> 0 | O22: =v0!Q82 -> 0 | P22: =v0!R82 -> 0
I23: =v0!K83 -> 0 | J23: =v0!L83 -> 0 | K23: =v0!M83 -> 0 | L23: =v0!N83 -> 0 | M23: =v0!O83 -> 0 | N23: =v0!P83 -> 0 | O23: =v0!Q83 -> 0 | P23: =v0!R83 -> 0
I24: =v0!K84 -> 0 | J24: =v0!L84 -> 0 | K24: =v0!M84 -> 0 | L24: =v0!N84 -> 0 | M24: =v0!O84 -> 0 | N24: =v0!P84 -> 0 | O24: =v0!Q84 -> 0 | P24: =v0!R84 -> 0
I25: =v0!K85 -> 0 | J25: =v0!L85 -> 0 | K25: =v0!M85 -> 0 | L25: =v0!N85 -> 0 | M25: =v0!O85 -> 0 | N25: =v0!P85 -> 0 | O25: =v0!Q85 -> 0 | P25: =v0!R85 -> 0
I26: =v0!K86 -> 0 | J26: =v0!L86 -> 0 | K26: =v0!M86 -> 0 | L26: =v0!N86 -> 0 | M26: =v0!O86 -> 0 | N26: =v0!P86 -> 0 | O26: =v0!Q86 -> 0 | P26: =v0!R86 -> 0

Sheet PMF c0 round0
A1: tile | B1: PMF c0 round0 | H1: =v0!A62 -> inter pk in | I1: =v0!B62 -> inter pk work | J1: =v0!C62 -> inter pk out | L1: =v0!A64 -> sel pk in | M1: =v0!B64 -> sel pk work | N1: =v0!C64 -> sel pk out | P1: =v0!A70 -> Yread latancy | Q1: =v0!B70 -> 8x8 input cc | R1: =v0!C70 -> 8x8 work cc | S1: =v0!D70 -> 8x8 output cc | U1: =v0!G62 -> tqitq8x8 input | V1: =v0!H62 -> tqitq work | W1: =v0!I62 -> tqitq out | Y1: =v0!A68 -> Yread latancy | Z1: =v0!B68 -> 16x16 input cc | AA1: =v0!C68 -> 16x16 work cc | AB1: =v0!D68 -> 16x16 output cc
A2: x | B2: CYCLE | H2: =v0!A63 -> 1 | I2: =v0!B63 -> 1 | J2: =v0!C63 -> 1 | L2: =v0!A65 -> 1 | M2: =v0!B65 -> 1 | N2: =v0!C65 -> 1 | P2: =v0!A71 -> 2 | Q2: =v0!B71 -> 8 | R2: =v0!C71 -> 4 | S2: =v0!D71 -> 4 | U2: =v0!G63 -> 4 | V2: =v0!H63 -> 23 | W2: =v0!I63 -> 1 | Y2: =v0!A69 -> 2 | Z2: =v0!B69 -> 23 | AA2: =v0!C69 -> -8 | AB2: =v0!D69 -> 16
A3: y | B3: MODE
A4: mode | B4: pipe begin | C4: input begin | D4: input end | E4: output begin | F4: output end
A5: PMF_M8_0_a | B5: 0 | C5: =B5+$P$2 -> 2 | D5: =C5+$Q$2 -> 10 | E5: =D5+$R$2 -> 14 | F5: =E5+$S$2 -> 18
A6: PMF_M8_0_b | B6: =B5+8 -> 8 | C6: =B6+$P$2 -> 10 | D6: =C6+$Q$2 -> 18 | E6: =D6+$R$2 -> 22 | F6: =E6+$S$2 -> 26
A7: PMF_M8_0_c | B7: =B6+8 -> 16 | C7: =B7+$P$2 -> 18 | D7: =C7+$Q$2 -> 26 | E7: =D7+$R$2 -> 30 | F7: =E7+$S$2 -> 34
A8: PMF_F8_0 | B8: =B7+8 -> 24 | C8: =B8+$P$2 -> 26 | D8: =C8+$Q$2 -> 34 | E8: =D8+$R$2 -> 38 | F8: =E8+$S$2 -> 42
A9: TQITQ_F8 | C9: =E8 -> 38 | D9: =C9+$U$2 -> 42 | E9: =D9+$V$2 -> 65 | F9: =E9+$W$2 -> 66
A10: INTER_PK8 | C10: =F9 -> 66 | D10: =C10+$H$2 -> 67 | E10: =D10+$I$2 -> 68 | F10: =E10+$J$2 -> 69
A11: SEL_PK8 | C11: =F10 -> 69 | D11: =C11+$L$2 -> 70 | E11: =D11+$M$2 -> 71 | F11: =E11+$N$2 -> 72
A12: PMF_M8_1_c | B12: =D31-2 -> 79 | C12: =B12+$P$2 -> 81 | D12: =C12+$Q$2 -> 89 | E12: =D12+$R$2 -> 93 | F12: =E12+$S$2 -> 97
A13: TQITQ_M8 | C13: =E12 -> 93 | D13: =C13+$U$2 -> 97 | E13: =D13+$V$2 -> 120 | F13: =E13+$W$2 -> 121
A14: INTER_PK8 | C14: =F13 -> 121 | D14: =C14+$H$2 -> 122 | E14: =D14+$I$2 -> 123 | F14: =E14+$J$2 -> 124
A15: SEL_PK8 | C15: =F14 -> 124 | D15: =C15+$L$2 -> 125 | E15: =D15+$M$2 -> 126 | F15: =E15+$N$2 -> 127
A16: PMF_M8_2_c | B16: =F15 -> 127 | C16: =B16+$P$2 -> 129 | D16: =C16+$Q$2 -> 137 | E16: =D16+$R$2 -> 141 | F16: =E16+$S$2 -> 145
A17: TQITQ_M8 | C17: =E16 -> 141 | D17: =C17+$U$2 -> 145 | E17: =D17+$V$2 -> 168 | F17: =E17+$W$2 -> 169
A18: INTER_PK8 | C18: =F17 -> 169 | D18: =C18+$H$2 -> 170 | E18: =D18+$I$2 -> 171 | F18: =E18+$J$2 -> 172
A19: SEL_PK8 | C19: =F18 -> 172 | D19: =C19+$L$2 -> 173 | E19: =D19+$M$2 -> 174 | F19: =E19+$N$2 -> 175
A20: PMF_M8_3_c | B20: =F19 -> 175 | C20: =B20+$P$2 -> 177 | D20: =C20+$Q$2 -> 185 | E20: =D20+$R$2 -> 189 | F20: =E20+$S$2 -> 193
A21: TQITQ_F8 | C21: =E20 -> 189 | D21: =C21+$U$2 -> 193 | E21: =D21+$V$2 -> 216 | F21: =E21+$W$2 -> 217
A22: INTER_PK8 | C22: =F21 -> 217 | D22: =C22+$H$2 -> 218 | E22: =D22+$I$2 -> 219 | F22: =E22+$J$2 -> 220
A23: SEL_PK8 | C23: =F22 -> 220 | D23: =C23+$L$2 -> 221 | E23: =D23+$M$2 -> 222 | F23: =E23+$N$2 -> 223
A24: dummy wait | D24: =F23 -> 223 | E24: =D24+7 -> 230 | F24: =E24+1 -> 231
A25: PMF_M8_1_a | B25: =B8+8 -> 32 | C25: =B25+$P$2 -> 34 | D25: =C25+$Q$2 -> 42 | E25: =D25+$R$2 -> 46 | F25: =E25+$S$2 -> 50
A26: PMF_M8_1_b | B26: =B25+8 -> 40 | C26: =B26+$P$2 -> 42 | D26: =C26+$Q$2 -> 50 | E26: =D26+$R$2 -> 54 | F26: =E26+$S$2 -> 58
A27: PMF_F8_1 | B27: =B26+8 -> 48 | C27: =B27+$P$2 -> 50 | D27: =C27+$Q$2 -> 58 | E27: =D27+$R$2 -> 62 | F27: =E27+$S$2 -> 66
A28: PMF_F8_2 | B28: =D30-2 -> 103 | C28: =B28+$P$2 -> 105 | D28: =C28+$Q$2 -> 113 | E28: =D28+$R$2 -> 117 | F28: =E28+$S$2 -> 121
A29: PMF_M8_2_a | B29: =B12+8 -> 87 | C29: =B29+$P$2 -> 89 | D29: =C29+$Q$2 -> 97 | E29: =D29+$R$2 -> 101 | F29: =E29+$S$2 -> 105
A30: PMF_M8_2_b | B30: =B29+8 -> 95 | C30: =B30+$P$2 -> 97 | D30: =C30+$Q$2 -> 105 | E30: =D30+$R$2 -> 109 | F30: =E30+$S$2 -> 113
A31: PMF_F16_0 | B31: =D27-2 -> 56 | C31: =B31+$Y$2 -> 58 | D31: =C31+$Z$2 -> 81 | E31: =D31+$AA$2+24 -> 97 | F31: =E31+$AB$2 -> 113
A32: PMF_M8_3_a | B32: =D16-2 -> 135 | C32: =B32+$P$2 -> 137 | D32: =C32+$Q$2 -> 145 | E32: =D32+$R$2 -> 149 | F32: =E32+$S$2 -> 153
A33: PMF_M8_3_b | B33: =B32+8 -> 143 | C33: =B33+$P$2 -> 145 | D33: =C33+$Q$2 -> 153 | E33: =D33+$R$2 -> 157 | F33: =E33+$S$2 -> 161
A34: PMF_F8_3 | B34: =D33-2 -> 151 | C34: =B34+$P$2 -> 153 | D34: =C34+$Q$2 -> 161 | E34: =D34+$R$2 -> 165 | F34: =E34+$S$2 -> 169

Sheet PMF sp c0 round0
A1: ='PMF c0 round0'!A1 -> tile | B1: ='PMF c0 round0'!B1 -> PMF c0 round0
A2: ='PMF c0 round0'!A2 -> x | B2: ='PMF c0 round0'!B2 -> CYCLE
A3: ='PMF c0 round0'!A3 -> y | B3: ='PMF c0 round0'!B3 -> MODE
A4: ='PMF c0 round0'!A4 -> mode | B4: ='PMF c0 round0'!B4 -> pipe begin | C4: ='PMF c0 round0'!C4 -> input begin | D4: ='PMF c0 round0'!D4 -> input end | E4: ='PMF c0 round0'!E4 -> output begin | F4: ='PMF c0 round0'!F4 -> output end
A5: ='PMF c0 round0'!A5 -> PMF_M8_0_a | B5: ='PMF c0 round0'!B5 -> 0 | C5: ='PMF c0 round0'!C5 -> 2 | D5: ='PMF c0 round0'!D5 -> 10 | E5: ='PMF c0 round0'!E5+2 -> 16 | F5: ='PMF c0 round0'!F5+2 -> 20
A6: ='PMF c0 round0'!A6 -> PMF_M8_0_b | B6: ='PMF c0 round0'!B6 -> 8 | C6: ='PMF c0 round0'!C6 -> 10 | D6: ='PMF c0 round0'!D6 -> 18 | E6: ='PMF c0 round0'!E6+2 -> 24 | F6: ='PMF c0 round0'!F6+2 -> 28
A7: ='PMF c0 round0'!A7 -> PMF_M8_0_c | B7: ='PMF c0 round0'!B7 -> 16 | C7: ='PMF c0 round0'!C7 -> 18 | D7: ='PMF c0 round0'!D7 -> 26 | E7: ='PMF c0 round0'!E7+2 -> 32 | F7: ='PMF c0 round0'!F7+2 -> 36
A8: ='PMF c0 round0'!A8 -> PMF_F8_0 | B8: ='PMF c0 round0'!B8 -> 24 | C8: ='PMF c0 round0'!C8 -> 26 | D8: ='PMF c0 round0'!D8 -> 34 | E8: ='PMF c0 round0'!E8+2 -> 40 | F8: ='PMF c0 round0'!F8+2 -> 44
A9: ='PMF c0 round0'!A9 -> TQITQ_F8 | B9: ='PMF c0 round0'!B9 -> 0 | C9: ='PMF c0 round0'!C9 -> 38 | D9: ='PMF c0 round0'!D9 -> 42 | E9: ='PMF c0 round0'!E9 -> 65 | F9: ='PMF c0 round0'!F9 -> 66
A10: ='PMF c0 round0'!A10 -> INTER_PK8 | B10: ='PMF c0 round0'!B10 -> 0 | C10: ='PMF c0 round0'!C10 -> 66 | D10: ='PMF c0 round0'!D10 -> 67 | E10: ='PMF c0 round0'!E10 -> 68 | F10: ='PMF c0 round0'!F10 -> 69
A11: ='PMF c0 round0'!A11 -> SEL_PK8 | B11: ='PMF c0 round0'!B11 -> 0 | C11: ='PMF c0 round0'!C11 -> 69 | D11: ='PMF c0 round0'!D11 -> 70 | E11: ='PMF c0 round0'!E11 -> 71 | F11: ='PMF c0 round0'!F11 -> 72
A12: ='PMF c0 round0'!A12 -> PMF_M8_1_c | B12: ='PMF c0 round0'!B12 -> 79 | C12: ='PMF c0 round0'!C12 -> 81 | D12: ='PMF c0 round0'!D12 -> 89 | E12: ='PMF c0 round0'!E12+2 -> 95 | F12: ='PMF c0 round0'!F12+2 -> 99
A13: ='PMF c0 round0'!A13 -> TQITQ_M8 | B13: ='PMF c0 round0'!B13 -> 0 | C13: ='PMF c0 round0'!C13 -> 93 | D13: ='PMF c0 round0'!D13 -> 97 | E13: ='PMF c0 round0'!E13 -> 120 | F13: ='PMF c0 round0'!F13 -> 121
A14: ='PMF c0 round0'!A14 -> INTER_PK8 | B14: ='PMF c0 round0'!B14 -> 0 | C14: ='PMF c0 round0'!C14 -> 121 | D14: ='PMF c0 round0'!D14 -> 122 | E14: ='PMF c0 round0'!E14 -> 123 | F14: ='PMF c0 round0'!F14 -> 124
A15: ='PMF c0 round0'!A15 -> SEL_PK8 | B15: ='PMF c0 round0'!B15 -> 0 | C15: ='PMF c0 round0'!C15 -> 124 | D15: ='PMF c0 round0'!D15 -> 125 | E15: ='PMF c0 round0'!E15 -> 126 | F15: ='PMF c0 round0'!F15 -> 127
A16: ='PMF c0 round0'!A16 -> PMF_M8_2_c | B16: ='PMF c0 round0'!B16 -> 127 | C16: ='PMF c0 round0'!C16 -> 129 | D16: ='PMF c0 round0'!D16 -> 137 | E16: ='PMF c0 round0'!E16+2 -> 143 | F16: ='PMF c0 round0'!F16+2 -> 147
A17: ='PMF c0 round0'!A17 -> TQITQ_M8 | B17: ='PMF c0 round0'!B17 -> 0 | C17: ='PMF c0 round0'!C17 -> 141 | D17: ='PMF c0 round0'!D17 -> 145 | E17: ='PMF c0 round0'!E17 -> 168 | F17: ='PMF c0 round0'!F17 -> 169
A18: ='PMF c0 round0'!A18 -> INTER_PK8 | B18: ='PMF c0 round0'!B18 -> 0 | C18: ='PMF c0 round0'!C18 -> 169 | D18: ='PMF c0 round0'!D18 -> 170 | E18: ='PMF c0 round0'!E18 -> 171 | F18: ='PMF c0 round0'!F18 -> 172
A19: ='PMF c0 round0'!A19 -> SEL_PK8 | B19: ='PMF c0 round0'!B19 -> 0 | C19: ='PMF c0 round0'!C19 -> 172 | D19: ='PMF c0 round0'!D19 -> 173 | E19: ='PMF c0 round0'!E19 -> 174 | F19: ='PMF c0 round0'!F19 -> 175
A20: ='PMF c0 round0'!A20 -> PMF_M8_3_c | B20: ='PMF c0 round0'!B20 -> 175 | C20: ='PMF c0 round0'!C20 -> 177 | D20: ='PMF c0 round0'!D20 -> 185 | E20: ='PMF c0 round0'!E20+5 -> 194 | F20: ='PMF c0 round0'!F20+5 -> 198
A21: ='PMF c0 round0'!A21 -> TQITQ_F8 | B21: ='PMF c0 round0'!B21 -> 0 | C21: ='PMF c0 round0'!C21 -> 189 | D21: ='PMF c0 round0'!D21 -> 193 | E21: ='PMF c0 round0'!E21 -> 216 | F21: ='PMF c0 round0'!F21 -> 217
A22: ='PMF c0 round0'!A22 -> INTER_PK8 | B22: ='PMF c0 round0'!B22 -> 0 | C22: ='PMF c0 round0'!C22 -> 217 | D22: ='PMF c0 round0'!D22 -> 218 | E22: ='PMF c0 round0'!E22 -> 219 | F22: ='PMF c0 round0'!F22 -> 220
A23: ='PMF c0 round0'!A23 -> SEL_PK8 | B23: ='PMF c0 round0'!B23 -> 0 | C23: ='PMF c0 round0'!C23 -> 220 | D23: ='PMF c0 round0'!D23 -> 221 | E23: ='PMF c0 round0'!E23 -> 222 | F23: ='PMF c0 round0'!F23 -> 223
A24: ='PMF c0 round0'!A24 -> dummy wait | B24: ='PMF c0 round0'!B24 -> 0 | C24: ='PMF c0 round0'!C24 -> 0 | D24: ='PMF c0 round0'!D24 -> 223 | E24: ='PMF c0 round0'!E24 -> 230 | F24: ='PMF c0 round0'!F24 -> 231
A25: ='PMF c0 round0'!A25 -> PMF_M8_1_a | B25: ='PMF c0 round0'!B25 -> 32 | C25: ='PMF c0 round0'!C25 -> 34 | D25: ='PMF c0 round0'!D25 -> 42 | E25: ='PMF c0 round0'!E25+2 -> 48 | F25: ='PMF c0 round0'!F25+2 -> 52
A26: ='PMF c0 round0'!A26 -> PMF_M8_1_b | B26: ='PMF c0 round0'!B26 -> 40 | C26: ='PMF c0 round0'!C26 -> 42 | D26: ='PMF c0 round0'!D26 -> 50 | E26: ='PMF c0 round0'!E26+2 -> 56 | F26: ='PMF c0 round0'!F26+2 -> 60
A27: ='PMF c0 round0'!A27 -> PMF_F8_1 | B27: ='PMF c0 round0'!B27 -> 48 | C27: ='PMF c0 round0'!C27 -> 50 | D27: ='PMF c0 round0'!D27 -> 58 | E27: ='PMF c0 round0'!E27+2 -> 64 | F27: ='PMF c0 round0'!F27+2 -> 68
A28: ='PMF c0 round0'!A28 -> PMF_F8_2 | B28: ='PMF c0 round0'!B28 -> 103 | C28: ='PMF c0 round0'!C28 -> 105 | D28: ='PMF c0 round0'!D28 -> 113 | E28: ='PMF c0 round0'!E28+2 -> 119 | F28: ='PMF c0 round0'!F28+2 -> 123
A29: ='PMF c0 round0'!A29 -> PMF_M8_2_a | B29: ='PMF c0 round0'!B29 -> 87 | C29: ='PMF c0 round0'!C29 -> 89 | D29: ='PMF c0 round0'!D29 -> 97 | E29: ='PMF c0 round0'!E29+2 -> 103 | F29: ='PMF c0 round0'!F29+2 -> 107
A30: ='PMF c0 round0'!A30 -> PMF_M8_2_b | B30: ='PMF c0 round0'!B30 -> 95 | C30: ='PMF c0 round0'!C30 -> 97 | D30: ='PMF c0 round0'!D30 -> 105 | E30: ='PMF c0 round0'!E30+2 -> 111 | F30: ='PMF c0 round0'!F30+2 -> 115
A31: ='PMF c0 round0'!A31 -> PMF_F16_0 | B31: ='PMF c0 round0'!B31 -> 56 | C31: ='PMF c0 round0'!C31 -> 58 | D31: ='PMF c0 round0'!D31 -> 81 | E31: ='PMF c0 round0'!E31 -> 97 | F31: ='PMF c0 round0'!F31 -> 113
A32: ='PMF c0 round0'!A32 -> PMF_M8_3_a | B32: ='PMF c0 round0'!B32 -> 135 | C32: ='PMF c0 round0'!C32 -> 137 | D32: ='PMF c0 round0'!D32 -> 145 | E32: ='PMF c0 round0'!E32+2 -> 151 | F32: ='PMF c0 round0'!F32+2 -> 155
A33: ='PMF c0 round0'!A33 -> PMF_M8_3_b | B33: ='PMF c0 round0'!B33 -> 143 | C33: ='PMF c0 round0'!C33 -> 145 | D33: ='PMF c0 round0'!D33 -> 153 | E33: ='PMF c0 round0'!E33+2 -> 159 | F33: ='PMF c0 round0'!F33+2 -> 163
A34: ='PMF c0 round0'!A34 -> PMF_F8_3 | B34: ='PMF c0 round0'!B34 -> 151 | C34: ='PMF c0 round0'!C34 -> 153 | D34: ='PMF c0 round0'!D34 -> 161 | E34: ='PMF c0 round0'!E34+2 -> 167 | F34: ='PMF c0 round0'!F34+2 -> 171
A35: ='PMF c0 round0'!A35 -> 0 | B35: ='PMF c0 round0'!B35 -> 0 | C35: ='PMF c0 round0'!C35 -> 0 | D35: ='PMF c0 round0'!D35 -> 0 | E35: ='PMF c0 round0'!E35 -> 0 | F35: ='PMF c0 round0'!F35 -> 0
A36: ='PMF c0 round0'!A36 -> 0 | B36: ='PMF c0 round0'!B36 -> 0 | C36: ='PMF c0 round0'!C36 -> 0 | D36: ='PMF c0 round0'!D36 -> 0 | E36: ='PMF c0 round0'!E36 -> 0 | F36: ='PMF c0 round0'!F36 -> 0
A37: ='PMF c0 round0'!A37 -> 0 | B37: ='PMF c0 round0'!B37 -> 0 | C37: ='PMF c0 round0'!C37 -> 0 | D37: ='PMF c0 round0'!D37 -> 0 | E37: ='PMF c0 round0'!E37 -> 0 | F37: ='PMF c0 round0'!F37 -> 0
A38: ='PMF c0 round0'!A38 -> 0 | B38: ='PMF c0 round0'!B38 -> 0 | C38: ='PMF c0 round0'!C38 -> 0 | D38: ='PMF c0 round0'!D38 -> 0 | E38: ='PMF c0 round0'!E38 -> 0 | F38: ='PMF c0 round0'!F38 -> 0

Sheet PMF sp c0 round1-3
A1: ='PMF c0 round1-3'!A1 -> tile | B1: ='PMF c0 round1-3'!B1 -> PMF C0 Round 1-3 | C1: ='PMF c0 round1-3'!C1 -> 0 | D1: ='PMF c0 round1-3'!D1 -> 0 | E1: ='PMF c0 round1-3'!E1 -> 0 | F1: ='PMF c0 round1-3'!F1 -> 0
A2: ='PMF c0 round1-3'!A2 -> x | B2: ='PMF c0 round1-3'!B2 -> CYCLE | C2: ='PMF c0 round1-3'!C2 -> 0 | D2: ='PMF c0 round1-3'!D2 -> 0 | E2: ='PMF c0 round1-3'!E2 -> 0 | F2: ='PMF c0 round1-3'!F2 -> 0
A3: ='PMF c0 round1-3'!A3 -> y | B3: ='PMF c0 round1-3'!B3 -> MODE | C3: ='PMF c0 round1-3'!C3 -> 0 | D3: ='PMF c0 round1-3'!D3 -> 0 | E3: ='PMF c0 round1-3'!E3 -> 0 | F3: ='PMF c0 round1-3'!F3 -> 0
A4: ='PMF c0 round1-3'!A4 -> mode | B4: ='PMF c0 round1-3'!B4 -> pipe begin | C4: ='PMF c0 round1-3'!C4 -> input begin | D4: ='PMF c0 round1-3'!D4 -> input end | E4: ='PMF c0 round1-3'!E4 -> output begin | F4: ='PMF c0 round1-3'!F4 -> output end
A5: ='PMF c0 round1-3'!A6 -> PMF_M8_0_a | B5: ='PMF c0 round1-3'!B6 -> 206 | C5: ='PMF c0 round1-3'!C6 -> 208 | D5: ='PMF c0 round1-3'!D6 -> 216 | E5: ='PMF c0 round1-3'!E6+2 -> 222 | F5: ='PMF c0 round1-3'!F6+2 -> 226
A6: ='PMF c0 round1-3'!A7 -> PMF_M8_0_b | B6: ='PMF c0 round1-3'!B7 -> 214 | C6: ='PMF c0 round1-3'!C7 -> 216 | D6: ='PMF c0 round1-3'!D7 -> 224 | E6: ='PMF c0 round1-3'!E7+2 -> 230 | F6: ='PMF c0 round1-3'!F7+2 -> 234
A7: ='PMF c0 round1-3'!A8 -> PMF_F8_0 | B7: ='PMF c0 round1-3'!B8 -> 222 | C7: ='PMF c0 round1-3'!C8 -> 224 | D7: ='PMF c0 round1-3'!D8 -> 232 | E7: ='PMF c0 round1-3'!E8+2 -> 238 | F7: ='PMF c0 round1-3'!F8+2 -> 242
A8: ='PMF c0 round1-3'!A9 -> PMF_M8_0_c | B8: ='PMF c0 round1-3'!B9 -> 230 | C8: ='PMF c0 round1-3'!C9 -> 232 | D8: ='PMF c0 round1-3'!D9 -> 240 | E8: ='PMF c0 round1-3'!E9+2 -> 246 | F8: ='PMF c0 round1-3'!F9+2 -> 250
A9: ='PMF c0 round1-3'!A10 -> TQITQ_M8 | B9: ='PMF c0 round1-3'!B10 -> 0 | C9: ='PMF c0 round1-3'!C10 -> 244 | D9: ='PMF c0 round1-3'!D10 -> 248 | E9: ='PMF c0 round1-3'!E10 -> 271 | F9: ='PMF c0 round1-3'!F10 -> 272
A10: ='PMF c0 round1-3'!A11 -> INTER_PK8 | B10: ='PMF c0 round1-3'!B11 -> 0 | C10: ='PMF c0 round1-3'!C11 -> 272 | D10: ='PMF c0 round1-3'!D11 -> 273 | E10: ='PMF c0 round1-3'!E11 -> 274 | F10: ='PMF c0 round1-3'!F11 -> 275
A11: ='PMF c0 round1-3'!A12 -> SEL_PK8 | B11: ='PMF c0 round1-3'!B12 -> 0 | C11: ='PMF c0 round1-3'!C12 -> 275 | D11: ='PMF c0 round1-3'!D12 -> 276 | E11: ='PMF c0 round1-3'!E12 -> 277 | F11: ='PMF c0 round1-3'!F12 -> 278
A12: ='PMF c0 round1-3'!A13 -> PMF_M8_1_c | B12: ='PMF c0 round1-3'!B13 -> 285 | C12: ='PMF c0 round1-3'!C13 -> 287 | D12: ='PMF c0 round1-3'!D13 -> 295 | E12: ='PMF c0 round1-3'!E13+2 -> 301 | F12: ='PMF c0 round1-3'!F13+2 -> 305
A13: ='PMF c0 round1-3'!A14 -> TQITQ_M8 | B13: ='PMF c0 round1-3'!B14 -> 0 | C13: ='PMF c0 round1-3'!C14 -> 299 | D13: ='PMF c0 round1-3'!D14 -> 303 | E13: ='PMF c0 round1-3'!E14 -> 326 | F13: ='PMF c0 round1-3'!F14 -> 327
A14: ='PMF c0 round1-3'!A15 -> INTER_PK8 | B14: ='PMF c0 round1-3'!B15 -> 0 | C14: ='PMF c0 round1-3'!C15 -> 327 | D14: ='PMF c0 round1-3'!D15 -> 328 | E14: ='PMF c0 round1-3'!E15 -> 329 | F14: ='PMF c0 round1-3'!F15 -> 330
A15: ='PMF c0 round1-3'!A16 -> SEL_PK8 | B15: ='PMF c0 round1-3'!B16 -> 0 | C15: ='PMF c0 round1-3'!C16 -> 330 | D15: ='PMF c0 round1-3'!D16 -> 331 | E15: ='PMF c0 round1-3'!E16 -> 332 | F15: ='PMF c0 round1-3'!F16 -> 333
A16: ='PMF c0 round1-3'!A17 -> PMF_M8_2_c | B16: ='PMF c0 round1-3'!B17 -> 333 | C16: ='PMF c0 round1-3'!C17 -> 335 | D16: ='PMF c0 round1-3'!D17 -> 343 | E16: ='PMF c0 round1-3'!E17+1 -> 348 | F16: ='PMF c0 round1-3'!F17+1 -> 352
A17: ='PMF c0 round1-3'!A18 -> TQITQ_M8 | B17: ='PMF c0 round1-3'!B18 -> 0 | C17: ='PMF c0 round1-3'!C18 -> 347 | D17: ='PMF c0 round1-3'!D18 -> 351 | E17: ='PMF c0 round1-3'!E18 -> 374 | F17: ='PMF c0 round1-3'!F18 -> 375
A18: ='PMF c0 round1-3'!A19 -> INTER_PK8 | B18: ='PMF c0 round1-3'!B19 -> 0 | C18: ='PMF c0 round1-3'!C19 -> 375 | D18: ='PMF c0 round1-3'!D19 -> 376 | E18: ='PMF c0 round1-3'!E19 -> 377 | F18: ='PMF c0 round1-3'!F19 -> 378
A19: ='PMF c0 round1-3'!A20 -> SEL_PK8 | B19: ='PMF c0 round1-3'!B20 -> 0 | C19: ='PMF c0 round1-3'!C20 -> 378 | D19: ='PMF c0 round1-3'!D20 -> 379 | E19: ='PMF c0 round1-3'!E20 -> 380 | F19: ='PMF c0 round1-3'!F20 -> 381
A20: ='PMF c0 round1-3'!A21 -> PMF_M8_3_c | B20: ='PMF c0 round1-3'!B21 -> 381 | C20: ='PMF c0 round1-3'!C21 -> 383 | D20: ='PMF c0 round1-3'!D21 -> 391 | E20: ='PMF c0 round1-3'!E21+5 -> 400 | F20: ='PMF c0 round1-3'!F21+5 -> 404
A21: ='PMF c0 round1-3'!A22 -> TQITQ_F8 | B21: ='PMF c0 round1-3'!B22 -> 0 | C21: ='PMF c0 round1-3'!C22 -> 395 | D21: ='PMF c0 round1-3'!D22 -> 399 | E21: ='PMF c0 round1-3'!E22 -> 422 | F21: ='PMF c0 round1-3'!F22 -> 423
A22: ='PMF c0 round1-3'!A23 -> INTER_PK8 | B22: ='PMF c0 round1-3'!B23 -> 0 | C22: ='PMF c0 round1-3'!C23 -> 423 | D22: ='PMF c0 round1-3'!D23 -> 424 | E22: ='PMF c0 round1-3'!E23 -> 425 | F22: ='PMF c0 round1-3'!F23 -> 426
A23: ='PMF c0 round1-3'!A24 -> SEL_PK8 | B23: ='PMF c0 round1-3'!B24 -> 0 | C23: ='PMF c0 round1-3'!C24 -> 426 | D23: ='PMF c0 round1-3'!D24 -> 427 | E23: ='PMF c0 round1-3'!E24 -> 428 | F23: ='PMF c0 round1-3'!F24 -> 429
A24: ='PMF c0 round1-3'!A25 -> PMF_M8_1_a | B24: ='PMF c0 round1-3'!B25 -> 238 | C24: ='PMF c0 round1-3'!C25 -> 240 | D24: ='PMF c0 round1-3'!D25 -> 248 | E24: ='PMF c0 round1-3'!E25+2 -> 254 | F24: ='PMF c0 round1-3'!F25+2 -> 258
A25: ='PMF c0 round1-3'!A26 -> PMF_M8_1_b | B25: ='PMF c0 round1-3'!B26 -> 246 | C25: ='PMF c0 round1-3'!C26 -> 248 | D25: ='PMF c0 round1-3'!D26 -> 256 | E25: ='PMF c0 round1-3'!E26+2 -> 262 | F25: ='PMF c0 round1-3'!F26+2 -> 266
A26: ='PMF c0 round1-3'!A27 -> PMF_F8_1 | B26: ='PMF c0 round1-3'!B27 -> 254 | C26: ='PMF c0 round1-3'!C27 -> 256 | D26: ='PMF c0 round1-3'!D27 -> 264 | E26: ='PMF c0 round1-3'!E27+2 -> 270 | F26: ='PMF c0 round1-3'!F27+2 -> 274
A27: ='PMF c0 round1-3'!A28 -> PMF_F8_2 | B27: ='PMF c0 round1-3'!B28 -> 309 | C27: ='PMF c0 round1-3'!C28 -> 311 | D27: ='PMF c0 round1-3'!D28 -> 319 | E27: ='PMF c0 round1-3'!E28+2 -> 325 | F27: ='PMF c0 round1-3'!F28+2 -> 329
A28: ='PMF c0 round1-3'!A29 -> PMF_M8_2_a | B28: ='PMF c0 round1-3'!B29 -> 293 | C28: ='PMF c0 round1-3'!C29 -> 295 | D28: ='PMF c0 round1-3'!D29 -> 303 | E28: ='PMF c0 round1-3'!E29+2 -> 309 | F28: ='PMF c0 round1-3'!F29+2 -> 313
A29: ='PMF c0 round1-3'!A30 -> PMF_M8_2_b | B29: ='PMF c0 round1-3'!B30 -> 301 | C29: ='PMF c0 round1-3'!C30 -> 303 | D29: ='PMF c0 round1-3'!D30 -> 311 | E29: ='PMF c0 round1-3'!E30+2 -> 317 | F29: ='PMF c0 round1-3'!F30+2 -> 321
A30: ='PMF c0 round1-3'!A31 -> PMF_F16_1 | B30: ='PMF c0 round1-3'!B31 -> 262 | C30: ='PMF c0 round1-3'!C31 -> 264 | D30: ='PMF c0 round1-3'!D31 -> 287 | E30: ='PMF c0 round1-3'!E31 -> 303 | F30: ='PMF c0 round1-3'!F31 -> 319
A31: ='PMF c0 round1-3'!A32 -> PMF_M8_3_a | B31: ='PMF c0 round1-3'!B32 -> 341 | C31: ='PMF c0 round1-3'!C32 -> 343 | D31: ='PMF c0 round1-3'!D32 -> 351 | E31: ='PMF c0 round1-3'!E32+2 -> 357 | F31: ='PMF c0 round1-3'!F32+2 -> 361
A32: ='PMF c0 round1-3'!A33 -> PMF_M8_3_b | B32: ='PMF c0 round1-3'!B33 -> 349 | C32: ='PMF c0 round1-3'!C33 -> 351 | D32: ='PMF c0 round1-3'!D33 -> 359 | E32: ='PMF c0 round1-3'!E33+2 -> 365 | F32: ='PMF c0 round1-3'!F33+2 -> 369
A33: ='PMF c0 round1-3'!A34 -> PMF_F8_3 | B33: ='PMF c0 round1-3'!B34 -> 357 | C33: ='PMF c0 round1-3'!C34 -> 359 | D33: ='PMF c0 round1-3'!D34 -> 367 | E33: ='PMF c0 round1-3'!E34+2 -> 373 | F33: ='PMF c0 round1-3'!F34+2 -> 377
A34: ='PMF c0 round1-3'!A35 -> 0 | B34: ='PMF c0 round1-3'!B35 -> 0 | C34: ='PMF c0 round1-3'!C35 -> 0 | D34: ='PMF c0 round1-3'!D35 -> 0 | E34: ='PMF c0 round1-3'!E35 -> 0 | F34: ='PMF c0 round1-3'!F35 -> 0
A35: ='PMF c0 round1-3'!A36 -> 0 | B35: ='PMF c0 round1-3'!B36 -> 0 | C35: ='PMF c0 round1-3'!C36 -> 0 | D35: ='PMF c0 round1-3'!D36 -> 0 | E35: ='PMF c0 round1-3'!E36 -> 0 | F35: ='PMF c0 round1-3'!F36 -> 0
A36: ='PMF c0 round1-3'!A37 -> 0 | B36: ='PMF c0 round1-3'!B37 -> 0 | C36: ='PMF c0 round1-3'!C37 -> 0 | D36: ='PMF c0 round1-3'!D37 -> 0 | E36: ='PMF c0 round1-3'!E37 -> 0 | F36: ='PMF c0 round1-3'!F37 -> 0

Sheet PMF c0 round1-3
A1: tile | B1: PMF C0 Round 1-3 | H1: =v0!A62 -> inter pk in | I1: =v0!B62 -> inter pk work | J1: =v0!C62 -> inter pk out | L1: =v0!A64 -> sel pk in | M1: =v0!B64 -> sel pk work | N1: =v0!C64 -> sel pk out | P1: =v0!A70 -> Yread latancy | Q1: =v0!B70 -> 8x8 input cc | R1: =v0!C70 -> 8x8 work cc | S1: =v0!D70 -> 8x8 output cc | U1: =v0!G62 -> tqitq8x8 input | V1: =v0!H62 -> tqitq work | W1: =v0!I62 -> tqitq out | Y1: =v0!A68 -> Yread latancy | Z1: =v0!B68 -> 16x16 input cc | AA1: =v0!C68 -> 16x16 work cc | AB1: =v0!D68 -> 16x16 output cc
A2: x | B2: CYCLE | H2: =v0!A63 -> 1 | I2: =v0!B63 -> 1 | J2: =v0!C63 -> 1 | L2: =v0!A65 -> 1 | M2: =v0!B65 -> 1 | N2: =v0!C65 -> 1 | P2: =v0!A71 -> 2 | Q2: =v0!B71 -> 8 | R2: =v0!C71 -> 4 | S2: =v0!D71 -> 4 | U2: =v0!G63 -> 4 | V2: =v0!H63 -> 23 | W2: =v0!I63 -> 1 | Y2: =v0!A69 -> 2 | Z2: =v0!B69 -> 23 | AA2: =v0!C69 -> -8 | AB2: =v0!D69 -> 16
A3: y | B3: MODE
A4: mode | B4: pipe begin | C4: input begin | D4: input end | E4: output begin | F4: output end
A5: PMF_M16_a | B5: ='PMF c0 round0'!D20-2 -> 183 | C5: =B5+$Y$2 -> 185 | D5: =C5+$Z$2 -> 208 | E5: =D5+$AA$2 -> 200 | F5: =E5+$AB$2 -> 216
A6: PMF_M8_0_a | B6: =D5-2 -> 206 | C6: =B6+$P$2 -> 208 | D6: =C6+$Q$2 -> 216 | E6: =D6+$R$2 -> 220 | F6: =E6+$S$2 -> 224
A7: PMF_M8_0_b | B7: =B6+8 -> 214 | C7: =B7+$P$2 -> 216 | D7: =C7+$Q$2 -> 224 | E7: =D7+$R$2 -> 228 | F7: =E7+$S$2 -> 232
A8: PMF_F8_0 | B8: =B7+8 -> 222 | C8: =B8+$P$2 -> 224 | D8: =C8+$Q$2 -> 232 | E8: =D8+$R$2 -> 236 | F8: =E8+$S$2 -> 240
A9: PMF_M8_0_c | B9: =D8-2 -> 230 | C9: =B9+$P$2 -> 232 | D9: =C9+$Q$2 -> 240 | E9: =D9+$R$2 -> 244 | F9: =E9+$S$2 -> 248
A10: TQITQ_M8 | C10: =E9 -> 244 | D10: =C10+$U$2 -> 248 | E10: =D10+$V$2 -> 271 | F10: =E10+$W$2 -> 272
A11: INTER_PK8 | C11: =F10 -> 272 | D11: =C11+$H$2 -> 273 | E11: =D11+$I$2 -> 274 | F11: =E11+$J$2 -> 275
A12: SEL_PK8 | C12: =F11 -> 275 | D12: =C12+$L$2 -> 276 | E12: =D12+$M$2 -> 277 | F12: =E12+$N$2 -> 278
A13: PMF_M8_1_c | B13: =D31-2 -> 285 | C13: =B13+$P$2 -> 287 | D13: =C13+$Q$2 -> 295 | E13: =D13+$R$2 -> 299 | F13: =E13+$S$2 -> 303
A14: TQITQ_M8 | C14: =E13 -> 299 | D14: =C14+$U$2 -> 303 | E14: =D14+$V$2 -> 326 | F14: =E14+$W$2 -> 327
A15: INTER_PK8 | C15: =F14 -> 327 | D15: =C15+$H$2 -> 328 | E15: =D15+$I$2 -> 329 | F15: =E15+$J$2 -> 330
A16: SEL_PK8 | C16: =F15 -> 330 | D16: =C16+$L$2 -> 331 | E16: =D16+$M$2 -> 332 | F16: =E16+$N$2 -> 333
A17: PMF_M8_2_c | B17: =F16 -> 333 | C17: =B17+$P$2 -> 335 | D17: =C17+$Q$2 -> 343 | E17: =D17+$R$2 -> 347 | F17: =E17+$S$2 -> 351
A18: TQITQ_M8 | C18: =E17 -> 347 | D18: =C18+$U$2 -> 351 | E18: =D18+$V$2 -> 374 | F18: =E18+$W$2 -> 375
A19: INTER_PK8 | C19: =F18 -> 375 | D19: =C19+$H$2 -> 376 | E19: =D19+$I$2 -> 377 | F19: =E19+$J$2 -> 378
A20: SEL_PK8 | C20: =F19 -> 378 | D20: =C20+$L$2 -> 379 | E20: =D20+$M$2 -> 380 | F20: =E20+$N$2 -> 381
A21: PMF_M8_3_c | B21: =F20 -> 381 | C21: =B21+$P$2 -> 383 | D21: =C21+$Q$2 -> 391 | E21: =D21+$R$2 -> 395 | F21: =E21+$S$2 -> 399
A22: TQITQ_F8 | C22: =E21 -> 395 | D22: =C22+$U$2 -> 399 | E22: =D22+$V$2 -> 422 | F22: =E22+$W$2 -> 423
A23: INTER_PK8 | C23: =F22 -> 423 | D23: =C23+$H$2 -> 424 | E23: =D23+$I$2 -> 425 | F23: =E23+$J$2 -> 426
A24: SEL_PK8 | C24: =F23 -> 426 | D24: =C24+$L$2 -> 427 | E24: =D24+$M$2 -> 428 | F24: =E24+$N$2 -> 429
A25: PMF_M8_1_a | B25: =D9-2 -> 238 | C25: =B25+$P$2 -> 240 | D25: =C25+$Q$2 -> 248 | E25: =D25+$R$2 -> 252 | F25: =E25+$S$2 -> 256
A26: PMF_M8_1_b | B26: =B25+8 -> 246 | C26: =B26+$P$2 -> 248 | D26: =C26+$Q$2 -> 256 | E26: =D26+$R$2 -> 260 | F26: =E26+$S$2 -> 264
A27: PMF_F8_1 | B27: =B26+8 -> 254 | C27: =B27+$P$2 -> 256 | D27: =C27+$Q$2 -> 264 | E27: =D27+$R$2 -> 268 | F27: =E27+$S$2 -> 272
A28: PMF_F8_2 | B28: =D30-2 -> 309 | C28: =B28+$P$2 -> 311 | D28: =C28+$Q$2 -> 319 | E28: =D28+$R$2 -> 323 | F28: =E28+$S$2 -> 327
A29: PMF_M8_2_a | B29: =B13+8 -> 293 | C29: =B29+$P$2 -> 295 | D29: =C29+$Q$2 -> 303 | E29: =D29+$R$2 -> 307 | F29: =E29+$S$2 -> 311
A30: PMF_M8_2_b | B30: =B29+8 -> 301 | C30: =B30+$P$2 -> 303 | D30: =C30+$Q$2 -> 311 | E30: =D30+$R$2 -> 315 | F30: =E30+$S$2 -> 319
A31: PMF_F16_1 | B31: =D27-2 -> 262 | C31: =B31+$Y$2 -> 264 | D31: =C31+$Z$2 -> 287 | E31: =D31+$AA$2+24 -> 303 | F31: =E31+$AB$2 -> 319
A32: PMF_M8_3_a | B32: =D17-2 -> 341 | C32: =B32+$P$2 -> 343 | D32: =C32+$Q$2 -> 351 | E32: =D32+$R$2 -> 355 | F32: =E32+$S$2 -> 359
A33: PMF_M8_3_b | B33: =B32+8 -> 349 | C33: =B33+$P$2 -> 351 | D33: =C33+$Q$2 -> 359 | E33: =D33+$R$2 -> 363 | F33: =E33+$S$2 -> 367
A34: PMF_F8_3 | B34: =D33-2 -> 357 | C34: =B34+$P$2 -> 359 | D34: =C34+$Q$2 -> 367 | E34: =D34+$R$2 -> 371 | F34: =E34+$S$2 -> 375

Sheet PMF c1 round0
A1: tile | B1: PMF c1 round0-3 | P1: =v0!A66 -> Yread latancy | Q1: =v0!B66 -> 32x32 input cc | R1: =v0!C66 -> 32x32 work cc | S1: =v0!D66 -> 32x32 output cc | Y1: =v0!A68 -> Yread latancy | Z1: =v0!B68 -> 16x16 input cc | AA1: =v0!C68 -> 16x16 work cc | AB1: =v0!D68 -> 16x16 output cc
A2: x | B2: CYCLE | P2: =v0!A67 -> 2 | Q2: =v0!B67 -> 78 | R2: =v0!C67 -> -24 | S2: =v0!D67 -> 64 | Y2: =v0!A69 -> 2 | Z2: =v0!B69 -> 23 | AA2: =v0!C69 -> -8 | AB2: =v0!D69 -> 16
A3: y | B3: MODE
A4: mode | B4: pipe begin | C4: input begin | D4: input end | E4: output begin | F4: output end
A5: PMF_M16_0_a | B5: 0 | C5: =B5+$Y$2 -> 2 | D5: =C5+$Z$2 -> 25 | E5: =D5+$AA$2 -> 17 | F5: =E5+$AB$2 -> 33
A6: PMF_M16_0_b | B6: =D5-2 -> 23 | C6: =B6+$Y$2 -> 25 | D6: =C6+$Z$2 -> 48 | E6: =D6+$AA$2 -> 40 | F6: =E6+$AB$2 -> 56
A7: PMF_M16_0_c | B7: =D6-2 -> 46 | C7: =B7+$Y$2 -> 48 | D7: =C7+$Z$2 -> 71 | E7: =D7+$AA$2+18 -> 81 | F7: =E7+$AB$2 -> 97
A8: PMF_M32_0_a | B8: =D7-2 -> 69 | C8: =B8+$P$2 -> 71 | D8: =C8+$Q$2 -> 149 | E8: =D8+$R$2 -> 125 | F8: =E8+$S$2 -> 189
A9: PMF_M32_0_b | B9: =D8-2 -> 147 | C9: =B9+$P$2 -> 149 | D9: =C9+$Q$2 -> 227 | E9: =D9+$R$2 -> 203 | F9: =E9+$S$2 -> 267

Sheet PMF c1 round1-3
A1: tile | B1: PMF c1 round1-3 | P1: =v0!A66 -> Yread latancy | Q1: =v0!B66 -> 32x32 input cc | R1: =v0!C66 -> 32x32 work cc | S1: =v0!D66 -> 32x32 output cc | Y1: =v0!A68 -> Yread latancy | Z1: =v0!B68 -> 16x16 input cc | AA1: =v0!C68 -> 16x16 work cc | AB1: =v0!D68 -> 16x16 output cc
A2: x | B2: CYCLE | P2: =v0!A67 -> 2 | Q2: =v0!B67 -> 78 | R2: =v0!C67 -> -24 | S2: =v0!D67 -> 64 | Y2: =v0!A69 -> 2 | Z2: =v0!B69 -> 23 | AA2: =v0!C69 -> -8 | AB2: =v0!D69 -> 16
A3: y | B3: MODE
A4: mode | B4: pipe begin | C4: input begin | D4: input end | E4: output begin | F4: output end
A5: PMF_M16_1_b | B5: 225 | C5: =B5+$Y$2 -> 227 | D5: =C5+$Z$2 -> 250 | E5: =D5+$AA$2 -> 242 | F5: =E5+$AB$2 -> 258
A6: PMF_M16_1_c | B6: =D5-2 -> 248 | C6: =B6+$Y$2 -> 250 | D6: =C6+$Z$2 -> 273 | E6: =D6+$AA$2+18 -> 283 | F6: =E6+$AB$2 -> 299
A7: PMF_M32_0_c | B7: =D6-2 -> 271 | C7: =B7+$P$2 -> 273 | D7: =C7+$Q$2 -> 351 | E7: =D7+$R$2+75 -> 402 | F7: =E7+64 -> 466
A8: PMF_F32_0 | B8: =D7-2 -> 349 | C8: =B8+$P$2 -> 351 | D8: =C8+$Q$2 -> 429 | E8: =D8+$R$2+61 -> 466 | F8: =E8+$S$2 -> 530
A9: PMF_M16_2_b | B9: =D8-2 -> 427 | C9: =B9+$Y$2 -> 429 | D9: =C9+$Z$2 -> 452 | E9: =D9+$AA$2 -> 444 | F9: =E9+$AB$2 -> 460
A10: PMF_M16_2_c | B10: =D9-2 -> 450 | C10: =B10+$Y$2 -> 452 | D10: =C10+$Z$2 -> 475 | E10: =D10+$AA$2+18 -> 485 | F10: =E10+$AB$2 -> 501
A11: PMF_64M32_0 | B11: =D10-1 -> 474 | C11: =B11+$P$2 -> 476 | D11: =C11+$Q$2 -> 554 | E11: =D11+$R$2 -> 530 | F11: =E11+$S$2 -> 594
A12: PMF_64M32_1 | B12: =D11-2 -> 552 | C12: =B12+$P$2 -> 554 | D12: =C12+$Q$2 -> 632 | E12: =D12+$R$2 -> 608 | F12: =E12+$S$2 -> 672
A13: PMF_M16_3_b | B13: =D12-2 -> 630 | C13: =B13+$Y$2 -> 632 | D13: =C13+$Z$2 -> 655 | E13: =D13+$AA$2 -> 647 | F13: =E13+$AB$2 -> 663
A14: PMF_M16_3_c | B14: =D13-2 -> 653 | C14: =B14+$Y$2 -> 655 | D14: =C14+$Z$2 -> 678 | E14: =D14+$AA$2 -> 670 | F14: =E14+$AB$2 -> 686
A15: PMF_F16_2 | E15: =F10 -> 501 | F15: =E15+16 -> 517
A16: PMF_F16_3 | E16: =F14 -> 686 | F16: =E16+16 -> 702

Sheet PMF UV c0 round0
A1: tile | B1: PMF UV c0 round0 | H1: =v0!A62 -> inter pk in | I1: =v0!B62 -> inter pk work | J1: =v0!C62 -> inter pk out | L1: =v0!A64 -> sel pk in | M1: =v0!B64 -> sel pk work | N1: =v0!C64 -> sel pk out | P1: =v0!A78 -> UVread latancy | Q1: =v0!B78 -> 4x4 input cc | R1: =v0!C78 -> 4x4 work cc | S1: =v0!D78 -> 4x4 output cc | U1: =v0!G64 -> tqitq4x4 input | V1: =v0!H64 -> tqitq work | W1: =v0!I64 -> tqitq out | Y1: =v0!A76 -> UVread latancy | Z1: =v0!B76 -> 8x8 input cc | AA1: =v0!C76 -> 8x8 work cc | AB1: =v0!D76 -> 8x8 output cc
A2: x | B2: CYCLE | H2: =v0!A63 -> 1 | I2: =v0!B63 -> 1 | J2: =v0!C63 -> 1 | L2: =v0!A65 -> 1 | M2: =v0!B65 -> 1 | N2: =v0!C65 -> 1 | P2: =v0!A79 -> 2 | Q2: =v0!B79 -> 8 | R2: =v0!C79 -> 2 | S2: =v0!D79 -> 2 | U2: =v0!G65 -> 1 | V2: =v0!H65 -> 14 | W2: =v0!I65 -> 1 | Y2: =v0!A77 -> 2 | Z2: =v0!B77 -> 22 | AA2: =v0!C77 -> 0 | AB2: =v0!D77 -> 8
A3: y | B3: MODE
A4: mode | B4: pipe begin | C4: input begin | D4: input end | E4: output begin | F4: output end
A5: PMF_M4_0_a | B5: 0 | C5: =B5+$P$2 -> 2 | D5: =C5+$Q$2 -> 10 | E5: =D5+$R$2 -> 12 | F5: =E5+$S$2 -> 14
